Workbook

Sheet Rúbrica Resultados Globales
A2: A) | B2: Definiciones a nivel micro (rúbrica)
C4: Nivel de logro
C5: Óptimo | D5: Satisfactorio | E5: Base | F5: Por Mejorar | G5: No observado
C6: (4 puntos) | D6: (3 puntos) | E6: (2 puntos) | F6: (1 punto) | G6: (0 punto)
C7: El desempeño descrito se logra completamente | D7: El desempeño descrito se logra, sin embargo, presenta algunas imprecisiones. | E7: El desempeño descrito se logra de forma mínima | F7: El desempeño descrito se presenta de forma errónea y/o no se ajusta a lo solicitado | G7: El desempeño descrito no es observado dada la ausencia de acciones o productos
A9: B) | B9: Definiciones a nivel macro (EPI)
B10: El presente documento tiene por objetivo especificar los criterios que dan origen a las definiciones del indicador global de EPI. Entendemos que la EPI es una evaluación formativa, donde existe una diversidad de instrumentos y exigencias asociadas a ellos que responde a la especificidad de cada disciplina. Sin embargo, desde el nivel central el foco se sitúa fundamentalmente en detectar las necesidades de apoyo necesarias que requeriría el estudiantado para continuar su ciclo de profundización, y, en otro casos, para detectar los niveles de autonomía que presentan los/las estudiantes para transitar al ciclo de profundización. En este contexto, los términos utilizados la columna “Justificación” de la siguiente tabla, como; “buen nivel”, “apropiado”,” mínimo”, deben entenderse en el contexto específico y situado de cada evaluación.
C15: Categorías
C16: Óptimo | D16: Satisfactorio | E16: Base | F16: Por Mejorar
B17: Porcentajes | C17: 100%-85% | D17: 84% - 65% | E17: 64% - 50% | F17: 0% - 49%
B18: Definiciones | C18: Los resultados obtenidos por el/la estudiante en la Evaluación de Perfil Intermedio evidencian que ha logrado los aprendizajes clave del Ciclo Básico de formación que le permiten continuar con su trayectoria formativa en el Ciclo de Profundización y/ Especialización, con autonomía, avanzando en el desarrollo de los desempeños evidenciados. | D18: Los resultados obtenidos por el/la estudiante en la Evaluación de Perfil Intermedio evidencian que ha logrado los aprendizajes clave del Ciclo Básico de formación que le permiten continuar con su trayectoria formativa en el Ciclo de Profundización y/o Especialización, con autonomía. Sin embargo, se evidencian aspectos específicos y acotados en que es necesario fortalecer los desempeños. | E18: Los resultados obtenidos por el/la estudiante en la Evaluación de Perfil Intermedio evidencian que el logro de los aprendizajes clave del Ciclo Básico de formación se cumplen de manera mínimay requieren ser fortalecidos durante el Ciclo de Profundización y/o Especialización, para apoyar la continuidad de la trayectoria formativa. | F18: Los resultados obtenidos por el/la estudiante en la Evaluación de Perfil Intermedio evidencian que no se han logrado los aprendizajes clave del Ciclo Básico de formación , requiriendo de acciones de apoyo en el Ciclo de Profundización y/o Especialización que favorezcan el desarrollo de los desempeños evaluados y aseguren la continuidad de la trayectoria formativa. | H18: El/la estudiante en la Evaluación de Perfil Intermedio no presenta respuestas, lo que no permite evidenciar el logro de los aprendizajes clave del Ciclo Básico de formación.
C19: El/la estudiante avanza con autonomía al Ciclo de Profundización y/o Especialización. Cuenta con desempeños relevantes para la continuidad de su trayectoria formativa | E19: El/la estudiante avanza al Ciclo de Profundización y/o Especialización con apoyos adicionales para desarrollar los aprendizajes prioritarios que permiten dar continuidad a su trayectoria formativa
C20: Acciones de fortalecimiento de las trayectorias formativas
B21: Justificación | C21: Dado el carácter formativo de esta evaluación, se define este nivel a partir del 85% ya que a partir de este porcentaje se evidencia con claridad un buen nivel de conocimientos teórico-disciplinares de los contenidos, así como un muy buen manejo metodológico/práctico de estos, sin necesitar apoyos especificos. | D21: Dado el carácter formativo de esta evaluación, se define este nivel a partir del 65% y no del 70% en función del criterio de la autonomía para poder continuar hacia el ciclo de profundización, siendo el 65% un nivel de solidez suficiente para aquello, demostrando un conocimiento apropiado de los conocimientos teórico-disciplinares y un manejo apropiado metodológico/práctico de estos. Esto también obedece a la diversidad de EPIs existentes y a los distintos niveles de exigencia de los distintos instrumentos. | E21: Dado el carácter formativo de la evaluación, se define este nivel a partir del 50% ya que el/la estudiante demuestra un conocimiento/manejo básico de los contenidos/habilidades esenciales, sin embargo el nivel de profundidad de este manejo es superficial/parcial/insuficiente. logrando solo a mitad del puntaje. El nivel de profundidad de los aprendizajes logrados y la consecuente necesidad de apoyos predominan para definir los porcentajes de logro de este nivel. | F21: Dado el carácter formativo de la evaluación, se define este nivel como porcentajes de logro menores al 50%, ya que el/la estudiante no alcanza un mínimo de conocimiento ni manejo de contenidos y habilidades esperadas, evidenciando la necesidad de apoyos para poder transitar al ciclo de profundización.

Sheet Rúbrica situación evaluativa 

Sheet Resultados Individuales
A1: DATOS DE ESTUDIANTES DE LA COHORTE | K1: Actividad problema 1 No observado-No contesta: 0 puntos Insuficiente : 1 punto Regular : 2 puntos Bueno : 3 puntos Excelente: 4 puntos | N1: Actividad Problema 2 No observado-No contesta: 0 puntos Insuficiente : 1 punto Regular : 2 puntos Bueno : 3 puntos Excelente: 4 puntos | R1: Resultado General por estudiante
A3: RUT ESTUDIANTE | B3: DV | D3: PRIMER APELLIDO (Apellido paterno) | E3: SEGUNDO APELLIDO (Apellido materno) | F3: NOMBRES | G3: ESTADO DE HABILITACIÓN PARA RENDIR | H3: ESTATUS DE RENDICIÓN | I3: FECHA DE RENDICIÓN | J3: JUSTIFICACIÓN DE NO RENDICIÓN | K3: Señale tres aspectos que distinguen a las arqueologías post-procesuales de la arqueología procesual. Refiérase brevemente a cada uno | L3: ¿De qué manera el Funcionalismo impactó a la teoría y la práctica arqueológica? | M3: Señale tres corrientes teóricas que influyeron en el planteamiento de críticas a la arqueología procesual y al desarrollo de las arqueologías post-procesuales. | N3: 1a) ¿Qué pasos debiera desarrollar un equipo arqueológico en terreno para la identificación superficial y subsuperficial de los sitios? | O3: 1b) Una vez detectados diversos sitios, ¿cómo debiera tomarse la decisión sobre en qué áreas realizar excavaciones ampliadas? | P3: 1c) ¿Qué procedimientos deben realizarse obligatoriamente a fin de registrar la información contextual de la excavación? | Q3: 2) Desde la excavación de uno de estos sitios fueron recuperados líticos, cerámica, conchas, huesos, carbón y madera. Mencione dos métodos para el fechado del contexto recuperado y la forma en la cual dicho método funciona. | R3: PUNTAJE TOTAL ESTUDIANTE | S3: PORCENTAJE DE LOGRO | T3: CATEGORÍA RESULTADO GLOBAL ESTUDIANTE
A4: 16936249 | B4: 1 | C4: CAROLINA ANDREA JARA LILLO | D4: JARA | E4: LILLO | F4: CAROLINA ANDREA | H4: Rendida | K4: 4 | L4: 0 | M4: 2 | N4: 4 | O4: 4 | P4: 4 | Q4: 4 | R4: =SUM(K4:Q4) -> 22 | S4: =R4/32 -> 0.6875 | T4: =IF(H4="Rendida ",IF('Resultados Individuales'!S4<49.5%,"Por Mejorar",IF('Resultados Individuales'!S4<64.5%,"Base",IF('Resultados Individuales'!S4<84.5%,"Satisfactorio","Óptimo"))),"No rendida o no válida") -> Satisfactorio
A5: 19407652 | B5: 5 | C5: JOSEFINA EUGENIA KAISER MIRANDA | D5: KAISER | E5: MIRANDA | F5: JOSEFINA EUGENIA | H5: Rendida | K5: 2 | L5: 2 | M5: 1 | N5: 1 | O5: 3 | P5: 3 | Q5: 3 | R5: =SUM(K5:Q5) -> 15 | S5: =R5/32 -> 0.46875 | T5: =IF(H5="Rendida ",IF('Resultados Individuales'!S5<49.5%,"Por Mejorar",IF('Resultados Individuales'!S5<64.5%,"Base",IF('Resultados Individuales'!S5<84.5%,"Satisfactorio","Óptimo"))),"No rendida o no válida") -> Por Mejorar
A6: 19517771 | B6: 6 | C6: SEBASTIÁN CRISTÓBAL SANTANDER CÁCERES | D6: SANTANDER | E6: CÁCERES | F6: SEBASTIÁN CRISTÓBAL | H6: Rendida | K6: 4 | L6: 4 | M6: 4 | N6: 4 | O6: 4 | P6: 4 | Q6: 4 | R6: =SUM(K6:Q6) -> 28 | S6: =R6/32 -> 0.875 | T6: =IF(H6="Rendida ",IF('Resultados Individuales'!S6<49.5%,"Por Mejorar",IF('Resultados Individuales'!S6<64.5%,"Base",IF('Resultados Individuales'!S6<84.5%,"Satisfactorio","Óptimo"))),"No rendida o no válida") -> Óptimo
A7: 19602125 | B7: 6 | C7: CATALINA ANDREA HERRERA HERNÁNDEZ | D7: HERRERA | E7: HERNÁNDEZ | F7: CATALINA ANDREA | H7: Rendida | K7: 3 | L7: 2 | M7: 1 | N7: 3 | O7: 2 | P7: 3 | Q7: 1 | R7: =SUM(K7:Q7) -> 15 | S7: =R7/32 -> 0.46875 | T7: =IF(H7="Rendida ",IF('Resultados Individuales'!S7<49.5%,"Por Mejorar",IF('Resultados Individuales'!S7<64.5%,"Base",IF('Resultados Individuales'!S7<84.5%,"Satisfactorio","Óptimo"))),"No rendida o no válida") -> Por Mejorar
A8: 20552682 | B8: K | C8: JOCABED JAZMÍN GONZÁLEZ GUAJARDO | D8: GONZÁLEZ | E8: GUAJARDO | F8: JOCABED JAZMÍN | H8: Rendida | K8: 2 | L8: 2 | M8: 1 | N8: 2 | O8: 2 | P8: 2 | Q8: 2 | R8: =SUM(K8:Q8) -> 13 | S8: =R8/32 -> 0.40625 | T8: =IF(H8="Rendida ",IF('Resultados Individuales'!S8<49.5%,"Por Mejorar",IF('Resultados Individuales'!S8<64.5%,"Base",IF('Resultados Individuales'!S8<84.5%,"Satisfactorio","Óptimo"))),"No rendida o no válida") -> Por Mejorar
A9: 20731256 | B9: 8 | C9: NATALIA MONSERRAT MARTÍNEZ OYARZO | D9: MARTÍNEZ | E9: OYARZO | F9: NATALIA MONSERRAT | H9: No rendida | J9: No justifica | R9: =SUM(K9:Q9) -> 0 | S9: =R9/32 -> 0 | T9: =IF(H9="Rendida ",IF('Resultados Individuales'!S9<49.5%,"Por Mejorar",IF('Resultados Individuales'!S9<64.5%,"Base",IF('Resultados Individuales'!S9<84.5%,"Satisfactorio","Óptimo"))),"No rendida o no válida") -> No rendida o no válida
A10: 20830310 | B10: 4 | C10: BARBARA IRENE PAVEZ LATORRE | D10: PAVEZ | E10: LATORRE | F10: BARBARA IRENE | H10: Rendida | K10: 1 | L10: 0 | M10: 0 | N10: 1 | O10: 1 | P10: 1 | Q10: 1 | R10: =SUM(K10:Q10) -> 5 | S10: =R10/32 -> 0.15625 | T10: =IF(H10="Rendida ",IF('Resultados Individuales'!S10<49.5%,"Por Mejorar",IF('Resultados Individuales'!S10<64.5%,"Base",IF('Resultados Individuales'!S10<84.5%,"Satisfactorio","Óptimo"))),"No rendida o no válida") -> Por Mejorar
A11: 20870582 | B11: 2 | C11: MELANY ALEJANDRA RODRÍGUEZ RIVERA | D11: RODRÍGUEZ | E11: RIVERA | F11: MELANY ALEJANDRA | H11: Rendida | K11: 2 | L11: 3 | M11: 1 | N11: 2 | O11: 2 | P11: 3 | Q11: 2 | R11: =SUM(K11:Q11) -> 15 | S11: =R11/32 -> 0.46875 | T11: =IF(H11="Rendida ",IF('Resultados Individuales'!S11<49.5%,"Por Mejorar",IF('Resultados Individuales'!S11<64.5%,"Base",IF('Resultados Individuales'!S11<84.5%,"Satisfactorio","Óptimo"))),"No rendida o no válida") -> Por Mejorar
A12: 20915008 | B12: 5 | C12: CAROLINA BELÉN ARIAS GUERRERO | D12: ARIAS | E12: GUERRERO | F12: CAROLINA BELÉN | H12: Rendida | K12: 2 | L12: 2 | M12: 1 | N12: 3 | O12: 2 | P12: 3 | Q12: 1 | R12: =SUM(K12:Q12) -> 14 | S12: =R12/32 -> 0.4375 | T12: =IF(H12="Rendida ",IF('Resultados Individuales'!S12<49.5%,"Por Mejorar",IF('Resultados Individuales'!S12<64.5%,"Base",IF('Resultados Individuales'!S12<84.5%,"Satisfactorio","Óptimo"))),"No rendida o no válida") -> Por Mejorar
A13: 20958183 | B13: 3 | C13: PAULINA IGNACIA HENRÍQUEZ BRIONES | D13: HENRÍQUEZ | E13: BRIONES | F13: PAULINA IGNACIA | H13: Rendida | K13: 1 | L13: 1 | M13: 0 | N13: 0 | O13: 0 | P13: 0 | Q13: 1 | R13: =SUM(K13:Q13) -> 3 | S13: =R13/32 -> 0.09375 | T13: =IF(H13="Rendida ",IF('Resultados Individuales'!S13<49.5%,"Por Mejorar",IF('Resultados Individuales'!S13<64.5%,"Base",IF('Resultados Individuales'!S13<84.5%,"Satisfactorio","Óptimo"))),"No rendida o no válida") -> Por Mejorar
A14: 20987063 | B14: 0 | C14: VICENTE JAVIER DONOSO GUTIÉRREZ | D14: DONOSO | E14: GUTIÉRREZ | F14: VICENTE JAVIER | H14: Rendida | K14: 3 | L14: 3 | M14: 3 | N14: 3 | O14: 3 | P14: 2 | Q14: 3 | R14: =SUM(K14:Q14) -> 20 | S14: =R14/32 -> 0.625 | T14: =IF(H14="Rendida ",IF('Resultados Individuales'!S14<49.5%,"Por Mejorar",IF('Resultados Individuales'!S14<64.5%,"Base",IF('Resultados Individuales'!S14<84.5%,"Satisfactorio","Óptimo"))),"No rendida o no válida") -> Base
A15: 21125860 | B15: 8 | C15: JERÓNIMO MANUEL URZÚA KOCH | D15: URZÚA | E15: KOCH | F15: JERÓNIMO MANUEL | H15: Rendida | K15: 1 | L15: 3 | M15: 1 | N15: 2 | O15: 1 | P15: 1 | Q15: 2 | R15: =SUM(K15:Q15) -> 11 | S15: =R15/32 -> 0.34375 | T15: =IF(H15="Rendida ",IF('Resultados Individuales'!S15<49.5%,"Por Mejorar",IF('Resultados Individuales'!S15<64.5%,"Base",IF('Resultados Individuales'!S15<84.5%,"Satisfactorio","Óptimo"))),"No rendida o no válida") -> Por Mejorar
A16: 21390241 | B16: 5 | C16: NATALIA VALENTINA MORENO BASAURE | D16: MORENO | E16: BASAURE | F16: NATALIA VALENTINA | H16: Rendida | K16: 0 | L16: 3 | M16: 0 | N16: 2 | O16: 2 | P16: 3 | Q16: 3 | R16: =SUM(K16:Q16) -> 13 | S16: =R16/32 -> 0.40625 | T16: =IF(H16="Rendida ",IF('Resultados Individuales'!S16<49.5%,"Por Mejorar",IF('Resultados Individuales'!S16<64.5%,"Base",IF('Resultados Individuales'!S16<84.5%,"Satisfactorio","Óptimo"))),"No rendida o no válida") -> Por Mejorar
A17: 21485902 | B17: 5 | C17: ISABELLA FIORENZA ANTONIA SCIARAFFIA VARELA | D17: SCIARAFFIA | E17: VARELA | F17: ISABELLA FIORENZA ANTONIA | H17: Rendida | K17: 1 | L17: 1 | M17: 1 | N17: 1 | O17: 1 | P17: 1 | Q17: 1 | R17: =SUM(K17:Q17) -> 7 | S17: =R17/32 -> 0.21875 | T17: =IF(H17="Rendida ",IF('Resultados Individuales'!S17<49.5%,"Por Mejorar",IF('Resultados Individuales'!S17<64.5%,"Base",IF('Resultados Individuales'!S17<84.5%,"Satisfactorio","Óptimo"))),"No rendida o no válida") -> Por Mejorar
A18: 21489747 | B18: 4 | C18: CRISTIAN FRANCISCO SÁNCHEZ UMANZOR | D18: SÁNCHEZ | E18: UMANZOR | F18: CRISTIAN FRANCISCO | H18: Rendida | K18: 1 | L18: 2 | M18: 1 | N18: 2 | O18: 1 | P18: 1 | Q18: 2 | R18: =SUM(K18:Q18) -> 10 | S18: =R18/32 -> 0.3125 | T18: =IF(H18="Rendida ",IF('Resultados Individuales'!S18<49.5%,"Por Mejorar",IF('Resultados Individuales'!S18<64.5%,"Base",IF('Resultados Individuales'!S18<84.5%,"Satisfactorio","Óptimo"))),"No rendida o no válida") -> Por Mejorar
A19: 21509472 | B19: 3 | C19: DEBORA ROSALIA CANTOS POLIT | D19: CANTOS | E19: POLIT | F19: DEBORA ROSALIA | H19: Rendida | K19: 2 | L19: 0 | M19: 0 | N19: 1 | O19: 1 | P19: 1 | Q19: 2 | R19: =SUM(K19:Q19) -> 7 | S19: =R19/32 -> 0.21875 | T19: =IF(H19="Rendida ",IF('Resultados Individuales'!S19<49.5%,"Por Mejorar",IF('Resultados Individuales'!S19<64.5%,"Base",IF('Resultados Individuales'!S19<84.5%,"Satisfactorio","Óptimo"))),"No rendida o no válida") -> Por Mejorar
A20: 21512977 | B20: 2 | C20: ISMAEL HERNÁN ANDRÉS ESCOBAR DURÁN | D20: ESCOBAR | E20: DURÁN | F20: ISMAEL HERNÁN ANDRÉS | H20: Rendida | K20: 1 | L20: 1 | M20: 1 | N20: 1 | O20: 1 | P20: 1 | Q20: 3 | R20: =SUM(K20:Q20) -> 9 | S20: =R20/32 -> 0.28125 | T20: =IF(H20="Rendida ",IF('Resultados Individuales'!S20<49.5%,"Por Mejorar",IF('Resultados Individuales'!S20<64.5%,"Base",IF('Resultados Individuales'!S20<84.5%,"Satisfactorio","Óptimo"))),"No rendida o no válida") -> Por Mejorar
A21: 21534063 | B21: 5 | C21: HÉCTOR MAXIMILIANO SOTO ESCOBAR | D21: SOTO | E21: ESCOBAR | F21: HÉCTOR MAXIMILIANO | H21: Rendida | K21: 1 | L21: 1 | M21: 1 | N21: 2 | O21: 1 | P21: 3 | Q21: 3 | R21: =SUM(K21:Q21) -> 12 | S21: =R21/32 -> 0.375 | T21: =IF(H21="Rendida ",IF('Resultados Individuales'!S21<49.5%,"Por Mejorar",IF('Resultados Individuales'!S21<64.5%,"Base",IF('Resultados Individuales'!S21<84.5%,"Satisfactorio","Óptimo"))),"No rendida o no válida") -> Por Mejorar
A22: 21562971 | B22: 6 | C22: BENJAMÍN ENRIQUE VARELA SEPÚLVEDA | D22: VARELA | E22: SEPÚLVEDA | F22: BENJAMÍN ENRIQUE | H22: Rendida | K22: 1 | L22: 1 | M22: 1 | N22: 1 | O22: 2 | P22: 1 | Q22: 2 | R22: =SUM(K22:Q22) -> 9 | S22: =R22/32 -> 0.28125 | T22: =IF(H22="Rendida ",IF('Resultados Individuales'!S22<49.5%,"Por Mejorar",IF('Resultados Individuales'!S22<64.5%,"Base",IF('Resultados Individuales'!S22<84.5%,"Satisfactorio","Óptimo"))),"No rendida o no válida") -> Por Mejorar
A23: 21563342 | B23: K | C23: ISIDORA VALENTINA VERGARA LEIGHTON | D23: VERGARA | E23: LEIGHTON | F23: ISIDORA VALENTINA | H23: Rendida | K23: 1 | L23: 2 | M23: 1 | N23: 1 | O23: 2 | P23: 0 | Q23: 2 | R23: =SUM(K23:Q23) -> 9 | S23: =R23/32 -> 0.28125 | T23: =IF(H23="Rendida ",IF('Resultados Individuales'!S23<49.5%,"Por Mejorar",IF('Resultados Individuales'!S23<64.5%,"Base",IF('Resultados Individuales'!S23<84.5%,"Satisfactorio","Óptimo"))),"No rendida o no válida") -> Por Mejorar
A24: 21566470 | B24: 8 | C24: ISIDORA VALENTINA HERRERA HERNANDEZ | D24: HERRERA | E24: HERNANDEZ | F24: ISIDORA VALENTINA | H24: Rendida | K24: 1 | L24: 2 | M24: 0 | N24: 1 | O24: 1 | P24: 1 | Q24: 2 | R24: =SUM(K24:Q24) -> 8 | S24: =R24/32 -> 0.25 | T24: =IF(H24="Rendida ",IF('Resultados Individuales'!S24<49.5%,"Por Mejorar",IF('Resultados Individuales'!S24<64.5%,"Base",IF('Resultados Individuales'!S24<84.5%,"Satisfactorio","Óptimo"))),"No rendida o no válida") -> Por Mejorar
A25: 21574356 | B25: K | C25: MARTÍN ANDRÉS PEREZ PIZARRO | D25: PEREZ | E25: PIZARRO | F25: MARTÍN ANDRÉS | H25: Rendida | K25: 3 | L25: 2 | M25: 2 | N25: 2 | O25: 2 | P25: 1 | Q25: 2 | R25: =SUM(K25:Q25) -> 14 | S25: =R25/32 -> 0.4375 | T25: =IF(H25="Rendida ",IF('Resultados Individuales'!S25<49.5%,"Por Mejorar",IF('Resultados Individuales'!S25<64.5%,"Base",IF('Resultados Individuales'!S25<84.5%,"Satisfactorio","Óptimo"))),"No rendida o no válida") -> Por Mejorar
A26: 21614212 | B26: 8 | C26: ISAÍAS ISAAC PINO CARRASCO | D26: PINO | E26: CARRASCO | F26: ISAÍAS ISAAC | H26: Rendida | K26: 2 | L26: 2 | M26: 0 | N26: 2 | O26: 1 | P26: 1 | Q26: 2 | R26: =SUM(K26:Q26) -> 10 | S26: =R26/32 -> 0.3125 | T26: =IF(H26="Rendida ",IF('Resultados Individuales'!S26<49.5%,"Por Mejorar",IF('Resultados Individuales'!S26<64.5%,"Base",IF('Resultados Individuales'!S26<84.5%,"Satisfactorio","Óptimo"))),"No rendida o no válida") -> Por Mejorar
A27: 21620729 | B27: 7 | C27: BENJAHMIN MATÍAS ANTU VÁSQUEZ GUZMÁN | D27: VÁSQUEZ | E27: GUZMÁN | F27: BENJAHMIN MATÍAS ANTU | H27: Rendida | K27: 2 | L27: 3 | M27: 2 | N27: 2 | O27: 1 | P27: 0 | Q27: 3 | R27: =SUM(K27:Q27) -> 13 | S27: =R27/32 -> 0.40625 | T27: =IF(H27="Rendida ",IF('Resultados Individuales'!S27<49.5%,"Por Mejorar",IF('Resultados Individuales'!S27<64.5%,"Base",IF('Resultados Individuales'!S27<84.5%,"Satisfactorio","Óptimo"))),"No rendida o no válida") -> Por Mejorar
A28: 21668681 | B28: 0 | C28: ISIDORA CATALINA BARRIOS VALENCIA | D28: BARRIOS | E28: VALENCIA | F28: ISIDORA CATALINA | H28: Rendida | K28: 4 | L28: 3 | M28: 3 | N28: 4 | O28: 4 | P28: 4 | Q28: 4 | R28: =SUM(K28:Q28) -> 26 | S28: =R28/32 -> 0.8125 | T28: =IF(H28="Rendida ",IF('Resultados Individuales'!S28<49.5%,"Por Mejorar",IF('Resultados Individuales'!S28<64.5%,"Base",IF('Resultados Individuales'!S28<84.5%,"Satisfactorio","Óptimo"))),"No rendida o no válida") -> Satisfactorio
A29: 21693332 | B29: K | C29: YANITZA POLETTE MARTÍNEZ ANDRADE | D29: MARTÍNEZ | E29: ANDRADE | F29: YANITZA POLETTE | H29: Rendida | K29: 2 | L29: 2 | M29: 0 | N29: 3 | O29: 2 | P29: 4 | Q29: 4 | R29: =SUM(K29:Q29) -> 17 | S29: =R29/32 -> 0.53125 | T29: =IF(H29="Rendida ",IF('Resultados Individuales'!S29<49.5%,"Por Mejorar",IF('Resultados Individuales'!S29<64.5%,"Base",IF('Resultados Individuales'!S29<84.5%,"Satisfactorio","Óptimo"))),"No rendida o no válida") -> Base
A30: 21695062 | B30: 3 | C30: LUIS ALBERTO DELGADO GONSALES | D30: DELGADO | E30: GONSALES | F30: LUIS ALBERTO | H30: Rendida | K30: 3 | L30: 1 | M30: 1 | N30: 3 | O30: 1 | P30: 2 | Q30: 3 | R30: =SUM(K30:Q30) -> 14 | S30: =R30/32 -> 0.4375 | T30: =IF(H30="Rendida ",IF('Resultados Individuales'!S30<49.5%,"Por Mejorar",IF('Resultados Individuales'!S30<64.5%,"Base",IF('Resultados Individuales'!S30<84.5%,"Satisfactorio","Óptimo"))),"No rendida o no válida") -> Por Mejorar
A31: 21700932 | B31: 4 | C31: CAMILA ANTONIA SILVA LÓPEZ | D31: SILVA | E31: LÓPEZ | F31: CAMILA ANTONIA | H31: Rendida | K31: 1 | L31: 1 | M31: 1 | N31: 3 | O31: 3 | P31: 2 | Q31: 1 | R31: =SUM(K31:Q31) -> 12 | S31: =R31/32 -> 0.375 | T31: =IF(H31="Rendida ",IF('Resultados Individuales'!S31<49.5%,"Por Mejorar",IF('Resultados Individuales'!S31<64.5%,"Base",IF('Resultados Individuales'!S31<84.5%,"Satisfactorio","Óptimo"))),"No rendida o no válida") -> Por Mejorar
A32: 21760136 | B32: 3 | C32: JULIÁN ANDRÉS FLORES ROMÁN | D32: FLORES | E32: ROMÁN | F32: JULIÁN ANDRÉS | H32: Rendida | K32: 1 | L32: 1 | M32: 0 | N32: 2 | O32: 1 | P32: 0 | Q32: 1 | R32: =SUM(K32:Q32) -> 6 | S32: =R32/32 -> 0.1875 | T32: =IF(H32="Rendida ",IF('Resultados Individuales'!S32<49.5%,"Por Mejorar",IF('Resultados Individuales'!S32<64.5%,"Base",IF('Resultados Individuales'!S32<84.5%,"Satisfactorio","Óptimo"))),"No rendida o no válida") -> Por Mejorar
A33: 21763717 | B33: 1 | C33: MARTINA IGNACIA ARAYA ARAYA | D33: ARAYA | E33: ARAYA | F33: MARTINA IGNACIA | H33: Rendida | K33: 3 | L33: 4 | M33: 4 | N33: 4 | O33: 3 | P33: 2 | Q33: 2 | R33: =SUM(K33:Q33) -> 22 | S33: =R33/32 -> 0.6875 | T33: =IF(H33="Rendida ",IF('Resultados Individuales'!S33<49.5%,"Por Mejorar",IF('Resultados Individuales'!S33<64.5%,"Base",IF('Resultados Individuales'!S33<84.5%,"Satisfactorio","Óptimo"))),"No rendida o no válida") -> Satisfactorio
A34: 21785952 | B34: 2 | C34: CAMILA IGNACIA MUÑOZ GIGOUX | D34: MUÑOZ | E34: GIGOUX | F34: CAMILA IGNACIA | H34: Rendida | K34: 1 | L34: 1 | M34: 1 | N34: 3 | O34: 1 | P34: 2 | Q34: 1 | R34: =SUM(K34:Q34) -> 10 | S34: =R34/32 -> 0.3125 | T34: =IF(H34="Rendida ",IF('Resultados Individuales'!S34<49.5%,"Por Mejorar",IF('Resultados Individuales'!S34<64.5%,"Base",IF('Resultados Individuales'!S34<84.5%,"Satisfactorio","Óptimo"))),"No rendida o no válida") -> Por Mejorar
A35: 21825263 | B35: K | C35: CARLA SOLANGE MOLINA RODRÍGUEZ | D35: MOLINA | E35: RODRÍGUEZ | F35: CARLA SOLANGE | H35: Rendida | K35: 2 | L35: 3 | M35: 1 | N35: 1 | O35: 2 | P35: 1 | Q35: 2 | R35: =SUM(K35:Q35) -> 12 | S35: =R35/32 -> 0.375 | T35: =IF(H35="Rendida ",IF('Resultados Individuales'!S35<49.5%,"Por Mejorar",IF('Resultados Individuales'!S35<64.5%,"Base",IF('Resultados Individuales'!S35<84.5%,"Satisfactorio","Óptimo"))),"No rendida o no válida") -> Por Mejorar
A36: 21831147 | B36: 4 | C36: ARIELA COLOMBA JAÑA CAROCA | D36: JAÑA | E36: CAROCA | F36: ARIELA COLOMBA | H36: Rendida | K36: 3 | L36: 4 | M36: 2 | N36: 3 | O36: 1 | P36: 2 | Q36: 2 | R36: =SUM(K36:Q36) -> 17 | S36: =R36/32 -> 0.53125 | T36: =IF(H36="Rendida ",IF('Resultados Individuales'!S36<49.5%,"Por Mejorar",IF('Resultados Individuales'!S36<64.5%,"Base",IF('Resultados Individuales'!S36<84.5%,"Satisfactorio","Óptimo"))),"No rendida o no válida") -> Base
A37: 21860359 | B37: 9 | C37: TYLOR ALEXANDER PEÑA GÁLVEZ | D37: PEÑA | E37: GÁLVEZ | F37: TYLOR ALEXANDER | H37: Rendida | K37: 1 | L37: 1 | M37: 0 | N37: 1 | O37: 1 | P37: 1 | Q37: 2 | R37: =SUM(K37:Q37) -> 7 | S37: =R37/32 -> 0.21875 | T37: =IF(H37="Rendida ",IF('Resultados Individuales'!S37<49.5%,"Por Mejorar",IF('Resultados Individuales'!S37<64.5%,"Base",IF('Resultados Individuales'!S37<84.5%,"Satisfactorio","Óptimo"))),"No rendida o no válida") -> Por Mejorar
R38: =SUM(K38:Q38) -> 0 | S38: =R38/32 -> 0 | T38: =IF(H38="Rendida ",IF('Resultados Individuales'!S38<49.5%,"Por Mejorar",IF('Resultados Individuales'!S38<64.5%,"Base",IF('Resultados Individuales'!S38<84.5%,"Satisfactorio","Óptimo"))),"No rendida o no válida") -> No rendida o no válida
R39: =SUM(K39:Q39) -> 0 | S39: =R39/32 -> 0 | T39: =IF(H39="Rendida ",IF('Resultados Individuales'!S39<49.5%,"Por Mejorar",IF('Resultados Individuales'!S39<64.5%,"Base",IF('Resultados Individuales'!S39<84.5%,"Satisfactorio","Óptimo"))),"No rendida o no válida") -> No rendida o no válida
R40: =SUM(K40:Q40) -> 0 | S40: =R40/32 -> 0 | T40: =IF(H40="Rendida ",IF('Resultados Individuales'!S40<49.5%,"Por Mejorar",IF('Resultados Individuales'!S40<64.5%,"Base",IF('Resultados Individuales'!S40<84.5%,"Satisfactorio","Óptimo"))),"No rendida o no válida") -> No rendida o no válida
R41: =SUM(K41:Q41) -> 0 | S41: =R41/32 -> 0 | T41: =IF(H41="Rendida ",IF('Resultados Individuales'!S41<49.5%,"Por Mejorar",IF('Resultados Individuales'!S41<64.5%,"Base",IF('Resultados Individuales'!S41<84.5%,"Satisfactorio","Óptimo"))),"No rendida o no válida") -> No rendida o no válida
...

Sheet Resultados Grupales
D1: Actividad problema 1 | G1: Actividad Problema 2 | K1: Resultados Generales Cohorte
A2: N Estudiantes habilitados para rendir | B2: N Estudiantes que rindieron | C2: Porcentaje de cobertura EPI | D2: Señale tres aspectos que distinguen a las arqueologías post-procesuales de la arqueología procesual. Refiérase brevemente a cada uno | E2: ¿De qué manera el Funcionalismo impactó a la teoría y la práctica arqueológica? | F2: Señale tres corrientes teóricas que influyeron en el planteamiento de críticas a la arqueología procesual y al desarrollo de las arqueologías post-procesuales. | G2: 1a) ¿Qué pasos debiera desarrollar un equipo arqueológico en terreno para la identificación superficial y subsuperficial de los sitios? | H2: 1b) Una vez detectados diversos sitios, ¿cómo debiera tomarse la decisión sobre en qué áreas realizar excavaciones ampliadas? | I2: 1c) ¿Qué procedimientos deben realizarse obligatoriamente a fin de registrar la información contextual de la excavación? | J2: 2) Desde la excavación de uno de estos sitios fueron recuperados líticos, cerámica, conchas, huesos, carbón y madera. Mencione dos métodos para el fechado del contexto recuperado y la forma en la cual dicho método funciona. | K2: PUNTAJE TOTAL ESTUDIANTE | L2: PORCENTAJE DE LOGRO EPI 2025 | M2: CATEGORÍA RESULTADO GLOBAL ESTUDIANTE

Sheet Validación datos NO BORRAR
E3: Estado de Habilitación para rendir | F3: ESTATUS DE RENDICIÓN | G3: JUSTIFICATIVO DE NO RENDICIÓN | H3: Puntaje según categoría
E4: Avance curricular suficiente o adecuado para evaluar ciclo básico | F4: Rendida | G4: Justifica | H4: 0
E5: Avance curricular insuficiente para evaluar ciclo básico (no rinde EPI 2025) | F5: No rendida | G5: No justifica | H5: 1
E6: EPI pendiente periodo anterior | F6: Rendida no válida | G6: No aplica | H6: 2
E7: Interrupción voluntaria (no rinde EPI 2025) | F7: No aplica | H7: 3
E8: Expulsión | H8: 4
E9: Retracto

Sheet ACCIONES
A2: NOMBRE DE LA FACULTAD
A3: NOMBRE DEL PROGRAMA ACADÉMICO
A4: PLAN DE ESTUDIO AÑO
A6: Instrucciones: completar items en color azul. Se incorporan ejemplos que pueden se considerados por las unidades académicas para la elaboración de sus propuestas.
A8: ANÁLISIS Y TOMA DE DECISIONES BASADAS EN LA EVIDENCIA
A9: Se presentan, a continuación, las acciones planificadas considerando el análisis de los resultados de la aplicación EPI 2025. Estas acciones -consideradas para ser desarrolladas a corto, mediano y largo plazo- están orientadas a fortalecer el perfil intermedio intermedio del programa, teniendo a la vista las competencias con menores niveles de logro.
A10: N° | B10: TIPO DE ACCIÓN | C10: ACCIONES | K10: MEDIO DE VERIFICACIÓN
A11: I. | B11: CORTO PLAZO | C11: Ejs. (acciones temporales que se realizan o buscan tener un impacto en el semestre consecutivo a la rendición de EPI) - realizar tutorías personalizadas con estudiantes que obtuvieron bajos resultados. - aplicar focus groups con estudiantes para indagar en variables que incidieron en los resultados (percepción sobre claridad de instrucciones, nivel de dificultad de las preguntas y nivel de preparación). - llevar a cabo una revisión inmediata de contenidos y metodologías programaciones de las actividades curriculares del ciclo básico -implementar evaluación diagnóstica durante ciclo básico, para detectar -de manera temprana- posibles dificultades que podrían interferir en el alcance del perfil intermedio. -integrar en programaciones de actividades curriculares de 3er año, ajustes que favorezcan el desarrollo de las compentencias que evidenciaron un menor logro en EPI. - ofrecer sesiones de refuerzo académico o tutorías personalizadas a estudiantes que han demostrado dificultades en la EPI, enfocándose en competencias en las que se hayan registrado debilidades. | K11: Ejs. - listas de asistencia - pauta preguntas focus group - acta sesión del comité curricular del programa académico
A12: II. | B12: MEDIANO PLAZO | C12: Ejs. (acciones temporales que se realizan o buscan tener un impacto más allá de transcurrido un semestre de la rendición de EPI) - desarrollar jornadas de trabajo con el equipo docente y directivo del programa académico para definir ajustes en las programaciones de las actividades curriculares del ciclo de profundización, particularmente en lo referido a metodologías y evaluaciones. - incorporar, en programaciones del ciclo básico, actividades de aprendizaje y evaluaciones orientadas a favorecer las competencias más descendidas en la EPI. - analizar comparativamente las calificaciones obtenidas en el ciclo básico con los resultados de EPI, para evaluar nudos críticos en la implementación del plan de estudio que puedan ser abordados con anticipación. | K12: Ejs. - programaciones de las actividades curriculares XXXX; XXXX; XXXX
A13: III. | B13: LARGO PLAZO | C13: Ejs. (acciones que buscan una implementación estable o permanente en el tiempo) - elaborar una actividad curricular de formación complementaria (OFC) orientada a fortalecer competencias más descendidas - actualizar plan de estudio, ajustando programas de actividades curriculares, carga académica y ubicación de actividades curriculares en el ciclo básico. - generar instancias para la colaboración entre docentes para con el propósito de compartir mejores prácticas y desarrollar estrategias pedagógicas más coherentes y efectivas en el ciclo básico del plan de estudio | K13: Ejs. - programa OFC - programas de actividades curriculares del ciclo básico, actualizadas

Sheet Hoja1
A1: POR MEJORAR | C1: RINDE
A2: SUFICIENTE | C2: NO RINDE
A3: SATISFACTORIO
A4: ÓPTIMO
