Workbook

Sheet Rúbrica Resultados Globales
A2: A) | B2: Definiciones a nivel micro (rúbrica)
C4: Nivel de logro
C5: Óptimo | D5: Satisfactorio | E5: Base | F5: Por Mejorar | G5: No observado
C6: (4 puntos) | D6: (3 puntos) | E6: (2 puntos) | F6: (1 punto) | G6: (0 punto)
C7: El desempeño descrito se logra completamente | D7: El desempeño descrito se logra, sin embargo, presenta algunas imprecisiones. | E7: El desempeño descrito se logra de forma mínima | F7: El desempeño descrito se presenta de forma errónea y/o no se ajusta a lo solicitado | G7: El desempeño descrito no es observado dada la ausencia de acciones o productos
A9: B) | B9: Definiciones a nivel macro (EPI)
B10: El presente documento tiene por objetivo especificar los criterios que dan origen a las definiciones del indicador global de EPI. Entendemos que la EPI es una evaluación formativa, donde existe una diversidad de instrumentos y exigencias asociadas a ellos que responde a la especificidad de cada disciplina. Sin embargo, desde el nivel central el foco se sitúa fundamentalmente en detectar las necesidades de apoyo necesarias que requeriría el estudiantado para continuar su ciclo de profundización, y, en otro casos, para detectar los niveles de autonomía que presentan los/las estudiantes para transitar al ciclo de profundización. En este contexto, los términos utilizados la columna “Justificación” de la siguiente tabla, como; “buen nivel”, “apropiado”,” mínimo”, deben entenderse en el contexto específico y situado de cada evaluación.
C15: Categorías
C16: Óptimo | D16: Satisfactorio | E16: Base | F16: Por Mejorar
B17: Porcentajes | C17: 100%-85% | D17: 84% - 65% | E17: 64% - 50% | F17: 0% - 49%
B18: Definiciones | C18: Los resultados obtenidos por el/la estudiante en la Evaluación de Perfil Intermedio evidencian que ha logrado los aprendizajes clave del Ciclo Básico de formación que le permiten continuar con su trayectoria formativa en el Ciclo de Profundización y/ Especialización, con autonomía, avanzando en el desarrollo de los desempeños evidenciados. | D18: Los resultados obtenidos por el/la estudiante en la Evaluación de Perfil Intermedio evidencian que ha logrado los aprendizajes clave del Ciclo Básico de formación que le permiten continuar con su trayectoria formativa en el Ciclo de Profundización y/o Especialización, con autonomía. Sin embargo, se evidencian aspectos específicos y acotados en que es necesario fortalecer los desempeños. | E18: Los resultados obtenidos por el/la estudiante en la Evaluación de Perfil Intermedio evidencian que el logro de los aprendizajes clave del Ciclo Básico de formación se cumplen de manera mínimay requieren ser fortalecidos durante el Ciclo de Profundización y/o Especialización, para apoyar la continuidad de la trayectoria formativa. | F18: Los resultados obtenidos por el/la estudiante en la Evaluación de Perfil Intermedio evidencian que no se han logrado los aprendizajes clave del Ciclo Básico de formación , requiriendo de acciones de apoyo en el Ciclo de Profundización y/o Especialización que favorezcan el desarrollo de los desempeños evaluados y aseguren la continuidad de la trayectoria formativa. | H18: El/la estudiante en la Evaluación de Perfil Intermedio no presenta respuestas, lo que no permite evidenciar el logro de los aprendizajes clave del Ciclo Básico de formación.
C19: El/la estudiante avanza con autonomía al Ciclo de Profundización y/o Especialización. Cuenta con desempeños relevantes para la continuidad de su trayectoria formativa | E19: El/la estudiante avanza al Ciclo de Profundización y/o Especialización con apoyos adicionales para desarrollar los aprendizajes prioritarios que permiten dar continuidad a su trayectoria formativa
C20: Acciones de fortalecimiento de las trayectorias formativas
B21: Justificación | C21: Dado el carácter formativo de esta evaluación, se define este nivel a partir del 85% ya que a partir de este porcentaje se evidencia con claridad un buen nivel de conocimientos teórico-disciplinares de los contenidos, así como un muy buen manejo metodológico/práctico de estos, sin necesitar apoyos especificos. | D21: Dado el carácter formativo de esta evaluación, se define este nivel a partir del 65% y no del 70% en función del criterio de la autonomía para poder continuar hacia el ciclo de profundización, siendo el 65% un nivel de solidez suficiente para aquello, demostrando un conocimiento apropiado de los conocimientos teórico-disciplinares y un manejo apropiado metodológico/práctico de estos. Esto también obedece a la diversidad de EPIs existentes y a los distintos niveles de exigencia de los distintos instrumentos. | E21: Dado el carácter formativo de la evaluación, se define este nivel a partir del 50% ya que el/la estudiante demuestra un conocimiento/manejo básico de los contenidos/habilidades esenciales, sin embargo el nivel de profundidad de este manejo es superficial/parcial/insuficiente. logrando solo a mitad del puntaje. El nivel de profundidad de los aprendizajes logrados y la consecuente necesidad de apoyos predominan para definir los porcentajes de logro de este nivel. | F21: Dado el carácter formativo de la evaluación, se define este nivel como porcentajes de logro menores al 50%, ya que el/la estudiante no alcanza un mínimo de conocimiento ni manejo de contenidos y habilidades esperadas, evidenciando la necesidad de apoyos para poder transitar al ciclo de profundización.

Sheet Rúbrica situación evaluativa 

Sheet Resultados Individuales
A1: DATOS DE ESTUDIANTES DE LA COHORTE | J1: Actividad problema 1 No observado: 0 punto Por mejorar: 1 punto Base: 2 puntos Satisfactorio : 3 puntos Óptimo : 4 puntos | N1: Resultado General por estudiante
A3: RUT ESTUDIANTE | B3: DV | C3: PRIMER APELLIDO (Apellido paterno) | D3: SEGUNDO APELLIDO (Apellido materno) | E3: NOMBRES | F3: ESTADO DE HABILITACIÓN PARA RENDIR | G3: ESTATUS DE RENDICIÓN | H3: FECHA DE RENDICIÓN | I3: JUSTIFICACIÓN DE NO RENDICIÓN | J3: 1. Distinción entre fenómeno y problema social | K3: 2. Fundamentos para la construcción de sujetos y fenómenos sociales y de intervención social | L3: 3. Coherencia entre teorías críticas y estrategias metodológicas en la intervención social | M3: 4. Comunicación escrita y textos académicos | N3: PUNTAJE TOTAL ESTUDIANTE | O3: PORCENTAJE DE LOGRO | P3: CATEGORÍA RESULTADO GLOBAL ESTUDIANTE
A4: 12284807 | B4: 8 | C4: MAULEN | D4: HERRAS | E4: MIRNA ISABEL | F4: Avance curricular suficiente o adecuado para evaluar ciclo básico | G4: Rendida | H4: 45757 | J4: 4 | K4: 2 | L4: 0 | M4: 3 | N4: 9 | O4: =N4/16 -> 0.5625 | P4: =IF(G4="Rendida ",IF('Resultados Individuales'!O4<49.5%,"Por Mejorar",IF('Resultados Individuales'!O4<64.5%,"Base",IF('Resultados Individuales'!O4<84.5%,"Satisfactorio","Óptimo"))),"No rendida o no válida") -> No rendida o no válida
A5: 18534312 | B5: K | C5: ANGULO | D5: LAGOS | E5: MARIA LUISA | F5: Avance curricular suficiente o adecuado para evaluar ciclo básico | G5: Rendida | H5: 45757 | J5: 3 | K5: 1 | L5: 2 | M5: 3 | N5: 9 | O5: =N5/16 -> 0.5625 | P5: =IF(G5="Rendida ",IF('Resultados Individuales'!O5<49.5%,"Por Mejorar",IF('Resultados Individuales'!O5<64.5%,"Base",IF('Resultados Individuales'!O5<84.5%,"Satisfactorio","Óptimo"))),"No rendida o no válida") -> No rendida o no válida
A6: 20345509 | B6: 7 | C6: HERNÁNDEZ | D6: ROA | E6: CAMILA ANGÉLICA | F6: Avance curricular suficiente o adecuado para evaluar ciclo básico | G6: Rendida | H6: 45757 | J6: 3 | K6: 2 | L6: 3 | M6: 2 | N6: 10 | O6: =N6/16 -> 0.625 | P6: =IF(G6="Rendida ",IF('Resultados Individuales'!O6<49.5%,"Por Mejorar",IF('Resultados Individuales'!O6<64.5%,"Base",IF('Resultados Individuales'!O6<84.5%,"Satisfactorio","Óptimo"))),"No rendida o no válida") -> No rendida o no válida
A7: 20452370 | B7: 3 | C7: TIZNADO | D7: ROJAS | E7: JOSÉ IGNACIO | F7: Avance curricular suficiente o adecuado para evaluar ciclo básico | G7: Rendida | H7: 45757 | J7: 1 | K7: 1 | L7: 0 | M7: 2 | N7: 4 | O7: =N7/16 -> 0.25 | P7: =IF(G7="Rendida ",IF('Resultados Individuales'!O7<49.5%,"Por Mejorar",IF('Resultados Individuales'!O7<64.5%,"Base",IF('Resultados Individuales'!O7<84.5%,"Satisfactorio","Óptimo"))),"No rendida o no válida") -> No rendida o no válida
A8: 20456534 | B8: 1 | C8: FIGUEROA | D8: RÍOS | E8: SEBASTIÁN ANDRÉS | F8: Avance curricular suficiente o adecuado para evaluar ciclo básico | G8: Rendida | H8: 45757 | J8: 2 | K8: 2 | L8: 3 | M8: 3 | N8: 10 | O8: =N8/16 -> 0.625 | P8: =IF(G8="Rendida ",IF('Resultados Individuales'!O8<49.5%,"Por Mejorar",IF('Resultados Individuales'!O8<64.5%,"Base",IF('Resultados Individuales'!O8<84.5%,"Satisfactorio","Óptimo"))),"No rendida o no válida") -> No rendida o no válida
A9: 20549979 | B9: 2 | C9: ACUÑA | D9: JORQUERA | E9: ELIZABETH CAROLINA | F9: Avance curricular suficiente o adecuado para evaluar ciclo básico | G9: Rendida | H9: 45757 | J9: 1 | K9: 2 | L9: 3 | M9: 2 | N9: 8 | O9: =N9/16 -> 0.5 | P9: =IF(G9="Rendida ",IF('Resultados Individuales'!O9<49.5%,"Por Mejorar",IF('Resultados Individuales'!O9<64.5%,"Base",IF('Resultados Individuales'!O9<84.5%,"Satisfactorio","Óptimo"))),"No rendida o no válida") -> No rendida o no válida
A10: 20560107 | B10: 4 | C10: MORENO | D10: MARTÍNEZ | E10: RAYEN ALMENDRA | F10: Avance curricular suficiente o adecuado para evaluar ciclo básico | G10: Rendida | H10: 45757 | J10: 4 | K10: 3 | L10: 3 | M10: 3 | N10: 13 | O10: =N10/16 -> 0.8125 | P10: =IF(G10="Rendida ",IF('Resultados Individuales'!O10<49.5%,"Por Mejorar",IF('Resultados Individuales'!O10<64.5%,"Base",IF('Resultados Individuales'!O10<84.5%,"Satisfactorio","Óptimo"))),"No rendida o no válida") -> No rendida o no válida
A11: 20820005 | B11: 4 | C11: NEGRETE | D11: CARRIEL | E11: JAVIERA ALEJANDRA | F11: Avance curricular suficiente o adecuado para evaluar ciclo básico | G11: Rendida | H11: 45757 | J11: 4 | K11: 3 | L11: 0 | M11: 3 | N11: 10 | O11: =N11/16 -> 0.625 | P11: =IF(G11="Rendida ",IF('Resultados Individuales'!O11<49.5%,"Por Mejorar",IF('Resultados Individuales'!O11<64.5%,"Base",IF('Resultados Individuales'!O11<84.5%,"Satisfactorio","Óptimo"))),"No rendida o no válida") -> No rendida o no válida
A12: 20923472 | B12: 6 | C12: BRAVO | D12: LIPIN | E12: IGNACIA BELÉN | F12: Avance curricular suficiente o adecuado para evaluar ciclo básico | G12: Rendida | H12: 45757 | J12: 2 | K12: 1 | L12: 2 | M12: 2 | N12: 7 | O12: =N12/16 -> 0.4375 | P12: =IF(G12="Rendida ",IF('Resultados Individuales'!O12<49.5%,"Por Mejorar",IF('Resultados Individuales'!O12<64.5%,"Base",IF('Resultados Individuales'!O12<84.5%,"Satisfactorio","Óptimo"))),"No rendida o no válida") -> No rendida o no válida
A13: 20985907 | B13: 6 | C13: SOTO | D13: STEWART | E13: CAMILA MACARENA | F13: Avance curricular suficiente o adecuado para evaluar ciclo básico | G13: No aplica | H13: No aplica | I13: No aplica | N13: 0 | O13: =N13/16 -> 0 | P13: =IF(G13="Rendida ",IF('Resultados Individuales'!O13<49.5%,"Por Mejorar",IF('Resultados Individuales'!O13<64.5%,"Base",IF('Resultados Individuales'!O13<84.5%,"Satisfactorio","Óptimo"))),"No rendida o no válida") -> No rendida o no válida
A14: 21144070 | B14: 8 | C14: HERNÁNDEZ | D14: ARELLANO | E14: CAMILA ANTONIA | F14: Avance curricular suficiente o adecuado para evaluar ciclo básico | G14: Rendida | H14: 45757 | J14: 3 | K14: 3 | L14: 3 | M14: 3 | N14: 12 | O14: =N14/16 -> 0.75 | P14: =IF(G14="Rendida ",IF('Resultados Individuales'!O14<49.5%,"Por Mejorar",IF('Resultados Individuales'!O14<64.5%,"Base",IF('Resultados Individuales'!O14<84.5%,"Satisfactorio","Óptimo"))),"No rendida o no válida") -> No rendida o no válida
A15: 21233486 | B15: 3 | C15: CORALES | D15: CARBONELL | E15: AMPARO | F15: Avance curricular suficiente o adecuado para evaluar ciclo básico | G15: Rendida | H15: 45757 | J15: 3 | K15: 4 | L15: 3 | M15: 4 | N15: 14 | O15: =N15/16 -> 0.875 | P15: =IF(G15="Rendida ",IF('Resultados Individuales'!O15<49.5%,"Por Mejorar",IF('Resultados Individuales'!O15<64.5%,"Base",IF('Resultados Individuales'!O15<84.5%,"Satisfactorio","Óptimo"))),"No rendida o no válida") -> No rendida o no válida
A16: 21255945 | B16: 8 | C16: PAZ | D16: CARRILLO | E16: YANARA ANTONIA | F16: Avance curricular suficiente o adecuado para evaluar ciclo básico | G16: Rendida | H16: 45757 | J16: 2 | K16: 2 | L16: 3 | M16: 2 | N16: 9 | O16: =N16/16 -> 0.5625 | P16: =IF(G16="Rendida ",IF('Resultados Individuales'!O16<49.5%,"Por Mejorar",IF('Resultados Individuales'!O16<64.5%,"Base",IF('Resultados Individuales'!O16<84.5%,"Satisfactorio","Óptimo"))),"No rendida o no válida") -> No rendida o no válida
A17: 21279857 | B17: 6 | C17: SOTO | D17: ACUÑA | E17: TRINIDAD ALEJANDRA | F17: Avance curricular suficiente o adecuado para evaluar ciclo básico | G17: Rendida | H17: 45757 | J17: 2 | K17: 3 | L17: 4 | M17: 4 | N17: 13 | O17: =N17/16 -> 0.8125 | P17: =IF(G17="Rendida ",IF('Resultados Individuales'!O17<49.5%,"Por Mejorar",IF('Resultados Individuales'!O17<64.5%,"Base",IF('Resultados Individuales'!O17<84.5%,"Satisfactorio","Óptimo"))),"No rendida o no válida") -> No rendida o no válida
A18: 21280325 | B18: 1 | C18: MORALES | D18: CASTRO | E18: TRIANA YAIRE | F18: Avance curricular suficiente o adecuado para evaluar ciclo básico | G18: Rendida | H18: 45757 | J18: 4 | K18: 3 | L18: 0 | M18: 3 | N18: 10 | O18: =N18/16 -> 0.625 | P18: =IF(G18="Rendida ",IF('Resultados Individuales'!O18<49.5%,"Por Mejorar",IF('Resultados Individuales'!O18<64.5%,"Base",IF('Resultados Individuales'!O18<84.5%,"Satisfactorio","Óptimo"))),"No rendida o no válida") -> No rendida o no válida
A19: 21311269 | B19: 4 | C19: ÁLVAREZ | D19: GONZÁLEZ | E19: DANIELA DEL CARMEN | F19: Avance curricular suficiente o adecuado para evaluar ciclo básico | G19: Rendida | H19: 45757 | J19: 2 | K19: 1 | L19: 1 | M19: 2 | N19: 6 | O19: =N19/16 -> 0.375 | P19: =IF(G19="Rendida ",IF('Resultados Individuales'!O19<49.5%,"Por Mejorar",IF('Resultados Individuales'!O19<64.5%,"Base",IF('Resultados Individuales'!O19<84.5%,"Satisfactorio","Óptimo"))),"No rendida o no válida") -> No rendida o no válida
A20: 21329568 | B20: 3 | C20: MUÑOZ | D20: CASTILLO | E20: NOELIA FRANCISCA | F20: Avance curricular suficiente o adecuado para evaluar ciclo básico | G20: Rendida | H20: 45757 | J20: 2 | K20: 1 | L20: 0 | M20: 2 | N20: 5 | O20: =N20/16 -> 0.3125 | P20: =IF(G20="Rendida ",IF('Resultados Individuales'!O20<49.5%,"Por Mejorar",IF('Resultados Individuales'!O20<64.5%,"Base",IF('Resultados Individuales'!O20<84.5%,"Satisfactorio","Óptimo"))),"No rendida o no válida") -> No rendida o no válida
A21: 21336139 | B21: 2 | C21: PULGAR | D21: GONZÁLEZ | E21: ANTONIA ALEJANDRA | F21: Avance curricular suficiente o adecuado para evaluar ciclo básico | G21: Rendida | H21: 45757 | J21: 2 | K21: 3 | L21: 1 | M21: 2 | N21: 8 | O21: =N21/16 -> 0.5 | P21: =IF(G21="Rendida ",IF('Resultados Individuales'!O21<49.5%,"Por Mejorar",IF('Resultados Individuales'!O21<64.5%,"Base",IF('Resultados Individuales'!O21<84.5%,"Satisfactorio","Óptimo"))),"No rendida o no válida") -> No rendida o no válida
A22: 21356662 | B22: 8 | C22: MENDOZA | D22: BECERRA | E22: MANUEL RICARDO ALEXANDER | F22: Avance curricular suficiente o adecuado para evaluar ciclo básico | G22: Rendida | H22: 45757 | J22: 3 | K22: 3 | L22: 2 | M22: 2 | N22: 10 | O22: =N22/16 -> 0.625 | P22: =IF(G22="Rendida ",IF('Resultados Individuales'!O22<49.5%,"Por Mejorar",IF('Resultados Individuales'!O22<64.5%,"Base",IF('Resultados Individuales'!O22<84.5%,"Satisfactorio","Óptimo"))),"No rendida o no válida") -> No rendida o no válida
A23: 21360375 | B23: 2 | C23: MELLADO | D23: CONTRERAS | E23: CRISTOPHER BASTIÁN | F23: Avance curricular suficiente o adecuado para evaluar ciclo básico | G23: Rendida | H23: 45757 | J23: 1 | K23: 1 | L23: 0 | M23: 0 | N23: 2 | O23: =N23/16 -> 0.125 | P23: =IF(G23="Rendida ",IF('Resultados Individuales'!O23<49.5%,"Por Mejorar",IF('Resultados Individuales'!O23<64.5%,"Base",IF('Resultados Individuales'!O23<84.5%,"Satisfactorio","Óptimo"))),"No rendida o no válida") -> No rendida o no válida
A24: 21380540 | B24: 1 | C24: FUENTES | D24: SALINAS | E24: DOMINIQUE VICTORIA | F24: Avance curricular suficiente o adecuado para evaluar ciclo básico | G24: Rendida | H24: 45757 | J24: 1 | K24: 3 | L24: 0 | M24: 2 | N24: 6 | O24: =N24/16 -> 0.375 | P24: =IF(G24="Rendida ",IF('Resultados Individuales'!O24<49.5%,"Por Mejorar",IF('Resultados Individuales'!O24<64.5%,"Base",IF('Resultados Individuales'!O24<84.5%,"Satisfactorio","Óptimo"))),"No rendida o no válida") -> No rendida o no válida
A25: 21385142 | B25: K | C25: JORDÁN | D25: TRONCOSO | E25: ANTONIA DE LOS ÁNGELES | F25: Avance curricular suficiente o adecuado para evaluar ciclo básico | G25: No rendida | H25: No aplica | I25: Justifica tema de salud mental grave | N25: 0 | O25: =N25/16 -> 0 | P25: =IF(G25="Rendida ",IF('Resultados Individuales'!O25<49.5%,"Por Mejorar",IF('Resultados Individuales'!O25<64.5%,"Base",IF('Resultados Individuales'!O25<84.5%,"Satisfactorio","Óptimo"))),"No rendida o no válida") -> No rendida o no válida
A26: 21386122 | B26: 0 | C26: GUZMÁN | D26: REYES | E26: AMARO RAÚL | F26: Avance curricular suficiente o adecuado para evaluar ciclo básico | G26: Rendida | H26: 45757 | J26: 1 | K26: 1 | L26: 0 | M26: 2 | N26: 4 | O26: =N26/16 -> 0.25 | P26: =IF(G26="Rendida ",IF('Resultados Individuales'!O26<49.5%,"Por Mejorar",IF('Resultados Individuales'!O26<64.5%,"Base",IF('Resultados Individuales'!O26<84.5%,"Satisfactorio","Óptimo"))),"No rendida o no válida") -> No rendida o no válida
A27: 21420164 | B27: K | C27: LEYTON | D27: BENAVIDES | E27: BASTIÁN IGNACIO | F27: Avance curricular suficiente o adecuado para evaluar ciclo básico | G27: Rendida | H27: 45757 | J27: 1 | K27: 1 | L27: 0 | M27: 3 | N27: 5 | O27: =N27/16 -> 0.3125 | P27: =IF(G27="Rendida ",IF('Resultados Individuales'!O27<49.5%,"Por Mejorar",IF('Resultados Individuales'!O27<64.5%,"Base",IF('Resultados Individuales'!O27<84.5%,"Satisfactorio","Óptimo"))),"No rendida o no válida") -> No rendida o no válida
A28: 21428146 | B28: 5 | C28: CONTRERAS | D28: VIVAR | E28: IVANA ISIDORA IGNACIA | F28: Avance curricular suficiente o adecuado para evaluar ciclo básico | G28: Rendida | H28: 45757 | J28: 2 | K28: 2 | L28: 1 | M28: 2 | N28: 7 | O28: =N28/16 -> 0.4375 | P28: =IF(G28="Rendida ",IF('Resultados Individuales'!O28<49.5%,"Por Mejorar",IF('Resultados Individuales'!O28<64.5%,"Base",IF('Resultados Individuales'!O28<84.5%,"Satisfactorio","Óptimo"))),"No rendida o no válida") -> No rendida o no válida
A29: 21439208 | B29: 9 | C29: FERNÁNDEZ | D29: COX | E29: MARTÍN | F29: Avance curricular suficiente o adecuado para evaluar ciclo básico | G29: Rendida | H29: 45757 | J29: 1 | K29: 1 | L29: 1 | M29: 2 | N29: 5 | O29: =N29/16 -> 0.3125 | P29: =IF(G29="Rendida ",IF('Resultados Individuales'!O29<49.5%,"Por Mejorar",IF('Resultados Individuales'!O29<64.5%,"Base",IF('Resultados Individuales'!O29<84.5%,"Satisfactorio","Óptimo"))),"No rendida o no válida") -> No rendida o no válida
A30: 21468250 | B30: 8 | C30: DUSTAN | D30: BUSTOS | E30: MAITE VALENTINA | F30: Avance curricular suficiente o adecuado para evaluar ciclo básico | G30: Rendida | H30: 45757 | J30: 2 | K30: 2 | L30: 1 | M30: 2 | N30: 7 | O30: =N30/16 -> 0.4375 | P30: =IF(G30="Rendida ",IF('Resultados Individuales'!O30<49.5%,"Por Mejorar",IF('Resultados Individuales'!O30<64.5%,"Base",IF('Resultados Individuales'!O30<84.5%,"Satisfactorio","Óptimo"))),"No rendida o no válida") -> No rendida o no válida
A31: 21482862 | B31: 6 | C31: STONE | D31: ARANA | E31: FERNANDA ESPERANZA | F31: Avance curricular suficiente o adecuado para evaluar ciclo básico | G31: Rendida | H31: 45757 | J31: 1 | K31: 1 | L31: 1 | M31: 2 | N31: 5 | O31: =N31/16 -> 0.3125 | P31: =IF(G31="Rendida ",IF('Resultados Individuales'!O31<49.5%,"Por Mejorar",IF('Resultados Individuales'!O31<64.5%,"Base",IF('Resultados Individuales'!O31<84.5%,"Satisfactorio","Óptimo"))),"No rendida o no válida") -> No rendida o no válida
A32: 21488964 | B32: 1 | C32: GONZÁLEZ | D32: FUENTES | E32: CONSTANZA JOHANNA CATARI | F32: Avance curricular suficiente o adecuado para evaluar ciclo básico | G32: Rendida | H32: 45757 | J32: 1 | K32: 2 | L32: 1 | M32: 2 | N32: 6 | O32: =N32/16 -> 0.375 | P32: =IF(G32="Rendida ",IF('Resultados Individuales'!O32<49.5%,"Por Mejorar",IF('Resultados Individuales'!O32<64.5%,"Base",IF('Resultados Individuales'!O32<84.5%,"Satisfactorio","Óptimo"))),"No rendida o no válida") -> No rendida o no válida
A33: 21493317 | B33: 9 | C33: VARGAS | D33: ROMÁN | E33: TANYA NAOMY | F33: Avance curricular suficiente o adecuado para evaluar ciclo básico | G33: Rendida | H33: 45757 | J33: 3 | K33: 2 | L33: 0 | M33: 3 | N33: 8 | O33: =N33/16 -> 0.5 | P33: =IF(G33="Rendida ",IF('Resultados Individuales'!O33<49.5%,"Por Mejorar",IF('Resultados Individuales'!O33<64.5%,"Base",IF('Resultados Individuales'!O33<84.5%,"Satisfactorio","Óptimo"))),"No rendida o no válida") -> No rendida o no válida
A34: 21495886 | B34: 4 | C34: SALAZAR | D34: MUÑOZ | E34: DARIAN RENATA | F34: Avance curricular suficiente o adecuado para evaluar ciclo básico | G34: Rendida | H34: 45757 | J34: 2 | K34: 2 | L34: 2 | M34: 3 | N34: 9 | O34: =N34/16 -> 0.5625 | P34: =IF(G34="Rendida ",IF('Resultados Individuales'!O34<49.5%,"Por Mejorar",IF('Resultados Individuales'!O34<64.5%,"Base",IF('Resultados Individuales'!O34<84.5%,"Satisfactorio","Óptimo"))),"No rendida o no válida") -> No rendida o no válida
A35: 21500412 | B35: 0 | C35: PEREIRA | D35: CONTRERAS | E35: JASMÍN ALEJANDRA | F35: Avance curricular suficiente o adecuado para evaluar ciclo básico | G35: Rendida | H35: 45757 | J35: 2 | K35: 1 | L35: 2 | M35: 2 | N35: 7 | O35: =N35/16 -> 0.4375 | P35: =IF(G35="Rendida ",IF('Resultados Individuales'!O35<49.5%,"Por Mejorar",IF('Resultados Individuales'!O35<64.5%,"Base",IF('Resultados Individuales'!O35<84.5%,"Satisfactorio","Óptimo"))),"No rendida o no válida") -> No rendida o no válida
A36: 21504320 | B36: 7 | C36: ULLOA | D36: FUENTES | E36: CATALINA MARÍA LUISA | F36: Avance curricular suficiente o adecuado para evaluar ciclo básico | G36: Rendida | H36: 45757 | J36: 3 | K36: 2 | L36: 4 | M36: 4 | N36: 13 | O36: =N36/16 -> 0.8125 | P36: =IF(G36="Rendida ",IF('Resultados Individuales'!O36<49.5%,"Por Mejorar",IF('Resultados Individuales'!O36<64.5%,"Base",IF('Resultados Individuales'!O36<84.5%,"Satisfactorio","Óptimo"))),"No rendida o no válida") -> No rendida o no válida
A37: 21507049 | B37: 2 | C37: VERDUGO | D37: ROJAS | E37: VIOLETA SUYANA INKA | F37: Avance curricular suficiente o adecuado para evaluar ciclo básico | G37: Rendida | H37: 45775 | J37: 3 | K37: 3 | L37: 4 | M37: 4 | N37: 14 | O37: =N37/16 -> 0.875 | P37: =IF(G37="Rendida ",IF('Resultados Individuales'!O37<49.5%,"Por Mejorar",IF('Resultados Individuales'!O37<64.5%,"Base",IF('Resultados Individuales'!O37<84.5%,"Satisfactorio","Óptimo"))),"No rendida o no válida") -> No rendida o no válida
A38: 21521343 | B38: 9 | C38: CÁCERES | D38: CAMPOS | E38: AMANDA CAROLINA | F38: Avance curricular suficiente o adecuado para evaluar ciclo básico | G38: Rendida | H38: 45757 | J38: 1 | K38: 1 | L38: 0 | M38: 3 | N38: 5 | O38: =N38/16 -> 0.3125 | P38: =IF(G38="Rendida ",IF('Resultados Individuales'!O38<49.5%,"Por Mejorar",IF('Resultados Individuales'!O38<64.5%,"Base",IF('Resultados Individuales'!O38<84.5%,"Satisfactorio","Óptimo"))),"No rendida o no válida") -> No rendida o no válida
A39: 21526463 | B39: 7 | C39: TORRES | D39: GATICA | E39: KAMILA ANDREA | F39: Avance curricular suficiente o adecuado para evaluar ciclo básico | G39: Rendida | H39: 45757 | J39: 2 | K39: 1 | L39: 1 | M39: 2 | N39: 6 | O39: =N39/16 -> 0.375 | P39: =IF(G39="Rendida ",IF('Resultados Individuales'!O39<49.5%,"Por Mejorar",IF('Resultados Individuales'!O39<64.5%,"Base",IF('Resultados Individuales'!O39<84.5%,"Satisfactorio","Óptimo"))),"No rendida o no válida") -> No rendida o no válida
... A48: 21586243 | B48: 7 | C48: FIGUEROA | D48: SOTO | E48: ANTONIA VANESA | F48: Avance curricular suficiente o adecuado para evaluar ciclo básico | G48: Rendida | H48: 45757 | J48: 3 | K48: 2 | L48: 0 | M48: 2 | N48: 7 | O48: =N48/16 -> 0.4375 | P48: =IF(G48="Rendida ",IF('Resultados Individuales'!O48<49.5%,"Por Mejorar",IF('Resultados Individuales'!O48<64.5%,"Base",IF('Resultados Individuales'!O48<84.5%,"Satisfactorio","Óptimo"))),"No rendida o no válida") -> No rendida o no válida
A49: 21601426 | B49: K | C49: MÁRQUEZ | D49: MUÑOZ | E49: ANTONIA IGNACIA | F49: Avance curricular suficiente o adecuado para evaluar ciclo básico | G49: Rendida | H49: 45757 | J49: 2 | K49: 3 | L49: 2 | M49: 2 | N49: 9 | O49: =N49/16 -> 0.5625 | P49: =IF(G49="Rendida ",IF('Resultados Individuales'!O49<49.5%,"Por Mejorar",IF('Resultados Individuales'!O49<64.5%,"Base",IF('Resultados Individuales'!O49<84.5%,"Satisfactorio","Óptimo"))),"No rendida o no válida") -> No rendida o no válida
...

Sheet Resultados Grupales
D1: Actividad problema 1 Nivel de logro 0: 0 punto Nivel de logro 1: 1 punto Nivel de logro 2: 2 puntos Nivel del logro 3 : 3 puntos Nivel del logro 4 : 4 puntos | H1: Resultados Generales Cohorte
A2: N Estudiantes habilitados para rendir | B2: N Estudiantes que rindieron | C2: Porcentaje de cobertura EPI | D2: 1. Distinción entre fenómeno y problema social | E2: 2. Fundamentos para la construcción de sujetos y fenómenos sociales y de intervención social | F2: 3. Coherencia entre teorías críticas y estrategias metodológicas en la intervención social | I2: 4. Comunicación escrita y textos académicos | L2: PUNTAJE TOTAL | M2: PORCENTAJE DE LOGRO EPI 2025 | N2: CATEGORÍA RESULTADO GLOBAL
A3: 72 | B3: 71 | C3: 0.986 | D3: 2 | E3: 2 | F3: Indicardor 1 | G3: Indicador 2 | H3: Indicador 3 | I3: Indicardor 1 | J3: Indicador 2 | K3: Indicador 3 | L3: 32 | M3: 0.34
F4: 0 | G4: 0 | H4: 0 | I4: 1 | J4: 4 | K4: 2 | N4: Pendiente de consultar

Sheet Validación datos NO BORRAR
E3: Estado de Habilitación para rendir | F3: ESTATUS DE RENDICIÓN | G3: JUSTIFICATIVO DE NO RENDICIÓN | H3: Puntaje según categoría
E4: Avance curricular suficiente o adecuado para evaluar ciclo básico | F4: Rendida | G4: Justifica | H4: 1
E5: Avance curricular insuficiente para evaluar ciclo básico (no rinde EPI 2025) | F5: No rendida | G5: No justifica | H5: 2
E6: EPI pendiente periodo anterior | F6: Rendida no válida | G6: No aplica | H6: 3
E7: Interrupción voluntaria (no rinde EPI 2025) | F7: No aplica | H7: 4
E8: Expulsión | H8: 0
E9: Retracto

Sheet Hoja1
A1: POR MEJORAR | C1: RINDE
A2: SUFICIENTE | C2: NO RINDE
A3: SATISFACTORIO
A4: ÓPTIMO

Sheet ACCIONES
B2: Facultad de Ciencias Sociales
B3: Trabajo Social
B4: PLAN DE ESTUDIO 2023
B8: ANÁLISIS Y TOMA DE DECISIONES BASADAS EN LA EVIDENCIA
B9: Se presentan, a continuación, las acciones planificadas considerando el análisis de los resultados de la aplicación EPI 2025. Estas acciones -consideradas para ser desarrolladas a corto, mediano y largo plazo- están orientadas a fortalecer el perfil intermedio intermedio del programa, teniendo a la vista las competencias con menores niveles de logro.
B10: N° | C10: TIPO DE ACCIÓN | D10: ACCIONES | L10: MEDIO DE VERIFICACIÓN
B11: I. | C11: CORTO PLAZO | D11: -Realizar una instancia de reforzamiento que permita mitigar las confusiones que presentan las/os estudiantes respecto a conceptualizaciones fundamentales para el desarrollado de la carrera. - Implementar un taller específico mediante el cual se refuercen los elementos centrales del diseño de Intervenciones Sociales - Grupo de conversación enfocado en recoger los principales desafíos y nudos críticos del proceso evaluativo - Generar un espacio de socialización de los resultados de la EPI con docentes de la carrera -Generar un espacio grupal de socialización de los resultados de la EPI con las y los estudiantes que la rindieron | L11: .-Material audiovisual utilizado para el reformzamientos del diseño de Intervenciones Sociales - listas de asistencia - pauta preguntas focus gropu - Material audiovisual utilizado en las instancias de socialización
B12: II. | C12: MEDIANO PLAZO | D12: - Desarrollar jornadas de trabajo con el equipo docente de la carrera para le evaluación de la necesidad de generar cambios metodológicos en los cursos del Ciclo Básico de la carrera. | L12: - Acta de reunión
B13: III. | C13: LARGO PLAZO | D13: - Se realizó recientemente un cambio en el Plan de Estudios (2023), lo que se espera genere un impacto positivo en el desarrollo de las competencias y contenidos considerados para el Ciclo Básico. - Generar una instancia para la socialización de estrategias de innovación en la docencia universitaria | L13: - Documento Nuevo Plan de Estudios 2023 - Lista de asistencia Taller de Innovación en Docencia
