Workbook

Sheet Rúbrica Resultados Globales
A2: A) | B2: Definiciones a nivel micro (rúbrica)
C4: Nivel de logro
C5: Óptimo | D5: Satisfactorio | E5: Base | F5: Por Mejorar | G5: No observado
C6: (4 puntos) | D6: (3 puntos) | E6: (2 puntos) | F6: (1 punto) | G6: (0 punto)
C7: El desempeño descrito se logra completamente | D7: El desempeño descrito se logra, sin embargo, presenta algunas imprecisiones. | E7: El desempeño descrito se logra de forma mínima | F7: El desempeño descrito se presenta de forma errónea y/o no se ajusta a lo solicitado | G7: El desempeño descrito no es observado dada la ausencia de acciones o productos
A9: B) | B9: Definiciones a nivel macro (EPI)
B10: El presente documento tiene por objetivo especificar los criterios que dan origen a las definiciones del indicador global de EPI. Entendemos que la EPI es una evaluación formativa, donde existe una diversidad de instrumentos y exigencias asociadas a ellos que responde a la especificidad de cada disciplina. Sin embargo, desde el nivel central el foco se sitúa fundamentalmente en detectar las necesidades de apoyo necesarias que requeriría el estudiantado para continuar su ciclo de profundización, y, en otro casos, para detectar los niveles de autonomía que presentan los/las estudiantes para transitar al ciclo de profundización. En este contexto, los términos utilizados la columna “Justificación” de la siguiente tabla, como; “buen nivel”, “apropiado”,” mínimo”, deben entenderse en el contexto específico y situado de cada evaluación.
C15: Categorías
C16: Óptimo | D16: Satisfactorio | E16: Base | F16: Por Mejorar
B17: Porcentajes | C17: 100%-85% | D17: 84% - 65% | E17: 64% - 50% | F17: 0% - 49%
B18: Definiciones | C18: Los resultados obtenidos por el/la estudiante en la Evaluación de Perfil Intermedio evidencian que ha logrado los aprendizajes clave del Ciclo Básico de formación que le permiten continuar con su trayectoria formativa en el Ciclo de Profundización y/ Especialización, con autonomía, avanzando en el desarrollo de los desempeños evidenciados. | D18: Los resultados obtenidos por el/la estudiante en la Evaluación de Perfil Intermedio evidencian que ha logrado los aprendizajes clave del Ciclo Básico de formación que le permiten continuar con su trayectoria formativa en el Ciclo de Profundización y/o Especialización, con autonomía. Sin embargo, se evidencian aspectos específicos y acotados en que es necesario fortalecer los desempeños. | E18: Los resultados obtenidos por el/la estudiante en la Evaluación de Perfil Intermedio evidencian que el logro de los aprendizajes clave del Ciclo Básico de formación se cumplen de manera mínimay requieren ser fortalecidos durante el Ciclo de Profundización y/o Especialización, para apoyar la continuidad de la trayectoria formativa. | F18: Los resultados obtenidos por el/la estudiante en la Evaluación de Perfil Intermedio evidencian que no se han logrado los aprendizajes clave del Ciclo Básico de formación , requiriendo de acciones de apoyo en el Ciclo de Profundización y/o Especialización que favorezcan el desarrollo de los desempeños evaluados y aseguren la continuidad de la trayectoria formativa. | H18: El/la estudiante en la Evaluación de Perfil Intermedio no presenta respuestas, lo que no permite evidenciar el logro de los aprendizajes clave del Ciclo Básico de formación.
C19: El/la estudiante avanza con autonomía al Ciclo de Profundización y/o Especialización. Cuenta con desempeños relevantes para la continuidad de su trayectoria formativa | E19: El/la estudiante avanza al Ciclo de Profundización y/o Especialización con apoyos adicionales para desarrollar los aprendizajes prioritarios que permiten dar continuidad a su trayectoria formativa
C20: Acciones de fortalecimiento de las trayectorias formativas
B21: Justificación | C21: Dado el carácter formativo de esta evaluación, se define este nivel a partir del 85% ya que a partir de este porcentaje se evidencia con claridad un buen nivel de conocimientos teórico-disciplinares de los contenidos, así como un muy buen manejo metodológico/práctico de estos, sin necesitar apoyos especificos. | D21: Dado el carácter formativo de esta evaluación, se define este nivel a partir del 65% y no del 70% en función del criterio de la autonomía para poder continuar hacia el ciclo de profundización, siendo el 65% un nivel de solidez suficiente para aquello, demostrando un conocimiento apropiado de los conocimientos teórico-disciplinares y un manejo apropiado metodológico/práctico de estos. Esto también obedece a la diversidad de EPIs existentes y a los distintos niveles de exigencia de los distintos instrumentos. | E21: Dado el carácter formativo de la evaluación, se define este nivel a partir del 50% ya que el/la estudiante demuestra un conocimiento/manejo básico de los contenidos/habilidades esenciales, sin embargo el nivel de profundidad de este manejo es superficial/parcial/insuficiente. logrando solo a mitad del puntaje. El nivel de profundidad de los aprendizajes logrados y la consecuente necesidad de apoyos predominan para definir los porcentajes de logro de este nivel. | F21: Dado el carácter formativo de la evaluación, se define este nivel como porcentajes de logro menores al 50%, ya que el/la estudiante no alcanza un mínimo de conocimiento ni manejo de contenidos y habilidades esperadas, evidenciando la necesidad de apoyos para poder transitar al ciclo de profundización.

Sheet Rúbrica situación evaluativa 

Sheet Resultados Individuales
A1: DATOS DE ESTUDIANTES DE LA COHORTE | K1: Actividad problema 1 No observado-no responde: 0 puntos Nivel Bajo 1: 1 punto Nivel Medio bajo: 2 puntos Nivel Medio-alto: 3 puntos Nivel Satisfactorio : 4 puntos | P1: Resultado General por estudiante
A3: RUT ESTUDIANTE | B3: DV | D3: PRIMER APELLIDO (Apellido paterno) | E3: SEGUNDO APELLIDO (Apellido materno) | F3: NOMBRES | G3: ESTADO DE HABILITACIÓN PARA RENDIR | H3: ESTATUS DE RENDICIÓN | I3: FECHA DE RENDICIÓN | J3: JUSTIFICACIÓN DE NO RENDICIÓN | K3: Es capaz de reconocer un problema disciplinar (C.P. o RR.II.), empleando herramientas metodológicas. | L3: Es capaz de distinguir las estructuras teóricas básicas (C.P. o RR.II), empleando conceptos y categorías en una problemática disciplinar. | M3: Es capaz de elaborar un esquema de investigación. | N3: Es capaz de extraer las ideas fundamentales de un texto, ordenándolas en sentido lógico y utilizando las normas de citación correspondientes. | P3: PUNTAJE TOTAL ESTUDIANTE | Q3: PORCENTAJE DE LOGRO | R3: CATEGORÍA RESULTADO GLOBAL ESTUDIANTE | S3: Promedio
A4: 19850361 | B4: 4 | C4: KEVIN TOMAS DIAZ NUÑEZ | D4: DIAZ | E4: NUÑEZ | F4: KEVIN TOMAS | H4: Rendida | I4: 45775 | K4: 2 | L4: 1 | M4: 1 | N4: 1 | P4: =SUM(K4:N4) -> 5 | Q4: =(P4*1)/16 -> 0.3125 | R4: =IF(H4="Rendida ",IF('Resultados Individuales'!Q4<49.5%,"Por Mejorar",IF('Resultados Individuales'!Q4<64.5%,"Base",IF('Resultados Individuales'!Q4<84.5%,"Satisfactorio","Óptimo"))),"No rendida o no válida") -> Por Mejorar | S4: 4.6
A5: 20396277 | B5: 0 | C5: ALEXIS FELIPE SALVADOR CAMPAÑA BRAVO | D5: CAMPAÑA | E5: BRAVO | F5: ALEXIS FELIPE SALVADOR | H5: Rendida | I5: 45758 | K5: 2 | L5: 2 | M5: 1 | N5: 3 | P5: =SUM(K5:N5) -> 8 | Q5: =(P5*1)/16 -> 0.5 | R5: =IF(H5="Rendida ",IF('Resultados Individuales'!Q5<49.5%,"Por Mejorar",IF('Resultados Individuales'!Q5<64.5%,"Base",IF('Resultados Individuales'!Q5<84.5%,"Satisfactorio","Óptimo"))),"No rendida o no válida") -> Base | S5: 4.9
A6: 20604367 | B6: 9 | C6: PATRICIO CARLOS MARTÍNEZ GÓMEZ | D6: MARTÍNEZ | E6: GÓMEZ | F6: PATRICIO CARLOS | H6: Rendida | I6: 45758 | K6: 2 | L6: 1 | M6: 1 | N6: 2 | P6: =SUM(K6:N6) -> 6 | Q6: =(P6*1)/16 -> 0.375 | R6: =IF(H6="Rendida ",IF('Resultados Individuales'!Q6<49.5%,"Por Mejorar",IF('Resultados Individuales'!Q6<64.5%,"Base",IF('Resultados Individuales'!Q6<84.5%,"Satisfactorio","Óptimo"))),"No rendida o no válida") -> Por Mejorar | S6: 5.3
A7: 20817354 | B7: 5 | C7: JOSE IGNACIO ANMELLA GOMEZ | D7: ANMELLA | E7: GOMEZ | F7: JOSE IGNACIO | H7: Rendida | I7: 45758 | K7: 2 | L7: 1 | M7: 1 | N7: 1 | P7: =SUM(K7:N7) -> 5 | Q7: =(P7*1)/16 -> 0.3125 | R7: =IF(H7="Rendida ",IF('Resultados Individuales'!Q7<49.5%,"Por Mejorar",IF('Resultados Individuales'!Q7<64.5%,"Base",IF('Resultados Individuales'!Q7<84.5%,"Satisfactorio","Óptimo"))),"No rendida o no válida") -> Por Mejorar | S7: 4.7
A8: 20877000 | B8: 4 | C8: JOAQUÍN IGNACIO CARMONA RODRÍGUEZ | D8: CARMONA | E8: RODRÍGUEZ | F8: JOAQUÍN IGNACIO | H8: Rendida | I8: 45758 | K8: 2 | L8: 2 | M8: 2 | N8: 3 | P8: =SUM(K8:N8) -> 9 | Q8: =(P8*1)/16 -> 0.5625 | R8: =IF(H8="Rendida ",IF('Resultados Individuales'!Q8<49.5%,"Por Mejorar",IF('Resultados Individuales'!Q8<64.5%,"Base",IF('Resultados Individuales'!Q8<84.5%,"Satisfactorio","Óptimo"))),"No rendida o no válida") -> Base | S8: 4.6
A9: 20878583 | B9: 4 | C9: JAIME ERNESTO MUÑOZ ORTEGA | D9: MUÑOZ | E9: ORTEGA | F9: JAIME ERNESTO | H9: Rendida | I9: 45758 | K9: 2 | L9: 1 | M9: 1 | N9: 2 | P9: =SUM(K9:N9) -> 6 | Q9: =(P9*1)/16 -> 0.375 | R9: =IF(H9="Rendida ",IF('Resultados Individuales'!Q9<49.5%,"Por Mejorar",IF('Resultados Individuales'!Q9<64.5%,"Base",IF('Resultados Individuales'!Q9<84.5%,"Satisfactorio","Óptimo"))),"No rendida o no válida") -> Por Mejorar | S9: 5.8
A10: 20944492 | B10: 5 | C10: PAOLA VALENTINA ESCOBAR MUÑOZ | D10: ESCOBAR | E10: MUÑOZ | F10: PAOLA VALENTINA | H10: Rendida | I10: 45758 | K10: 2 | L10: 1 | M10: 2 | N10: 2 | P10: =SUM(K10:N10) -> 7 | Q10: =(P10*1)/16 -> 0.4375 | R10: =IF(H10="Rendida ",IF('Resultados Individuales'!Q10<49.5%,"Por Mejorar",IF('Resultados Individuales'!Q10<64.5%,"Base",IF('Resultados Individuales'!Q10<84.5%,"Satisfactorio","Óptimo"))),"No rendida o no válida") -> Por Mejorar | S10: 5.2
A11: 20953894 | B11: 6 | C11: VÍCTOR ARMANDO FERNÁNDEZ SALAS | D11: FERNÁNDEZ | E11: SALAS | F11: VÍCTOR ARMANDO | G11: Interrupción voluntaria (no rinde EPI 2025) | H11: No rendida | J11: Justifica | P11: =SUM(K11:N11) -> 0 | Q11: =(P11*1)/16 -> 0 | R11: =IF(H11="Rendida ",IF('Resultados Individuales'!Q11<49.5%,"Por Mejorar",IF('Resultados Individuales'!Q11<64.5%,"Base",IF('Resultados Individuales'!Q11<84.5%,"Satisfactorio","Óptimo"))),"No rendida o no válida") -> No rendida o no válida | S11: 4.9 | T11: Estudiante suspende 1 semestre 2025
A12: 21082575 | B12: 4 | C12: RENATA ISIDORA POBLETE GAJARDO | D12: POBLETE | E12: GAJARDO | F12: RENATA ISIDORA | H12: Rendida | I12: 45758 | K12: 2 | L12: 2 | M12: 2 | N12: 2 | P12: =SUM(K12:N12) -> 8 | Q12: =(P12*1)/16 -> 0.5 | R12: =IF(H12="Rendida ",IF('Resultados Individuales'!Q12<49.5%,"Por Mejorar",IF('Resultados Individuales'!Q12<64.5%,"Base",IF('Resultados Individuales'!Q12<84.5%,"Satisfactorio","Óptimo"))),"No rendida o no válida") -> Base | S12: 5.2
A13: 21153093 | B13: 6 | C13: FRANCISCA MURIEL MONTES LABBÉ | D13: MONTES | E13: LABBÉ | F13: FRANCISCA MURIEL | H13: Rendida | I13: 45758 | K13: 1 | L13: 2 | M13: 1 | N13: 2 | P13: =SUM(K13:N13) -> 6 | Q13: =(P13*1)/16 -> 0.375 | R13: =IF(H13="Rendida ",IF('Resultados Individuales'!Q13<49.5%,"Por Mejorar",IF('Resultados Individuales'!Q13<64.5%,"Base",IF('Resultados Individuales'!Q13<84.5%,"Satisfactorio","Óptimo"))),"No rendida o no válida") -> Por Mejorar | S13: 5.1
A14: 21227952 | B14: 8 | C14: VALERIA RÍOS CARTER | D14: RÍOS | E14: CARTER | F14: VALERIA | H14: Rendida | I14: 45758 | K14: 1 | L14: 1 | M14: 2 | N14: 1 | P14: =SUM(K14:N14) -> 5 | Q14: =(P14*1)/16 -> 0.3125 | R14: =IF(H14="Rendida ",IF('Resultados Individuales'!Q14<49.5%,"Por Mejorar",IF('Resultados Individuales'!Q14<64.5%,"Base",IF('Resultados Individuales'!Q14<84.5%,"Satisfactorio","Óptimo"))),"No rendida o no válida") -> Por Mejorar | S14: 4.9
A15: 21242502 | B15: 8 | C15: JAVIERA BELÉN ÁLVAREZ POZO | D15: ÁLVAREZ | E15: POZO | F15: JAVIERA BELÉN | H15: Rendida | I15: 45758 | K15: 2 | L15: 2 | M15: 2 | N15: 2 | P15: =SUM(K15:N15) -> 8 | Q15: =(P15*1)/16 -> 0.5 | R15: =IF(H15="Rendida ",IF('Resultados Individuales'!Q15<49.5%,"Por Mejorar",IF('Resultados Individuales'!Q15<64.5%,"Base",IF('Resultados Individuales'!Q15<84.5%,"Satisfactorio","Óptimo"))),"No rendida o no válida") -> Base | S15: 4.9
A16: 21251191 | B16: 9 | C16: SOFÍA ANTONIA ESPÍNDOLA COBS | D16: ESPÍNDOLA | E16: COBS | F16: SOFÍA ANTONIA | H16: Rendida | I16: 45758 | K16: 4 | L16: 3 | M16: 3 | N16: 1 | P16: =SUM(K16:N16) -> 11 | Q16: =(P16*1)/16 -> 0.6875 | R16: =IF(H16="Rendida ",IF('Resultados Individuales'!Q16<49.5%,"Por Mejorar",IF('Resultados Individuales'!Q16<64.5%,"Base",IF('Resultados Individuales'!Q16<84.5%,"Satisfactorio","Óptimo"))),"No rendida o no válida") -> Satisfactorio | S16: 5.1
A17: 21264354 | B17: 8 | C17: CAMILO ANTONIO ARAYA NÚÑEZ | D17: ARAYA | E17: NÚÑEZ | F17: CAMILO ANTONIO | H17: Rendida | I17: 45758 | K17: 1 | L17: 1 | M17: 2 | N17: 1 | P17: =SUM(K17:N17) -> 5 | Q17: =(P17*1)/16 -> 0.3125 | R17: =IF(H17="Rendida ",IF('Resultados Individuales'!Q17<49.5%,"Por Mejorar",IF('Resultados Individuales'!Q17<64.5%,"Base",IF('Resultados Individuales'!Q17<84.5%,"Satisfactorio","Óptimo"))),"No rendida o no válida") -> Por Mejorar | S17: 5.7
A18: 21265706 | B18: 9 | C18: LUCAS ALONSO RAVANAL CALDERÓN | D18: RAVANAL | E18: CALDERÓN | F18: LUCAS ALONSO | H18: Rendida | I18: 45758 | K18: 2 | L18: 3 | M18: 3 | N18: 3 | P18: =SUM(K18:N18) -> 11 | Q18: =(P18*1)/16 -> 0.6875 | R18: =IF(H18="Rendida ",IF('Resultados Individuales'!Q18<49.5%,"Por Mejorar",IF('Resultados Individuales'!Q18<64.5%,"Base",IF('Resultados Individuales'!Q18<84.5%,"Satisfactorio","Óptimo"))),"No rendida o no válida") -> Satisfactorio | S18: 5.6
A19: 21275562 | B19: 1 | C19: MARTINA ISIDORA MAULÉN NARVÁEZ | D19: MAULÉN | E19: NARVÁEZ | F19: MARTINA ISIDORA | H19: Rendida | I19: 45758 | K19: 3 | L19: 4 | M19: 4 | N19: 4 | P19: =SUM(K19:N19) -> 15 | Q19: =(P19*1)/16 -> 0.9375 | R19: =IF(H19="Rendida ",IF('Resultados Individuales'!Q19<49.5%,"Por Mejorar",IF('Resultados Individuales'!Q19<64.5%,"Base",IF('Resultados Individuales'!Q19<84.5%,"Satisfactorio","Óptimo"))),"No rendida o no válida") -> Óptimo | S19: 5.5
A20: 21289514 | B20: 8 | C20: CRISTIAN DANIEL VARGAS MARTÍNEZ | D20: VARGAS | E20: MARTÍNEZ | F20: CRISTIAN DANIEL | H20: Rendida | I20: 45758 | K20: 3 | L20: 2 | M20: 2 | N20: 3 | P20: =SUM(K20:N20) -> 10 | Q20: =(P20*1)/16 -> 0.625 | R20: =IF(H20="Rendida ",IF('Resultados Individuales'!Q20<49.5%,"Por Mejorar",IF('Resultados Individuales'!Q20<64.5%,"Base",IF('Resultados Individuales'!Q20<84.5%,"Satisfactorio","Óptimo"))),"No rendida o no válida") -> Base | S20: 5.8
A21: 21300587 | B21: 1 | C21: CATALINA PAZ ALARCÓN BROWN | D21: ALARCÓN | E21: BROWN | F21: CATALINA PAZ | H21: Rendida | I21: 45758 | K21: 3 | L21: 4 | M21: 3 | N21: 2 | P21: =SUM(K21:N21) -> 12 | Q21: =(P21*1)/16 -> 0.75 | R21: =IF(H21="Rendida ",IF('Resultados Individuales'!Q21<49.5%,"Por Mejorar",IF('Resultados Individuales'!Q21<64.5%,"Base",IF('Resultados Individuales'!Q21<84.5%,"Satisfactorio","Óptimo"))),"No rendida o no válida") -> Satisfactorio | S21: 5.6
A22: 21304929 | B22: 1 | C22: SOFÍA CATALINA HERNÁNDEZ RIQUELME | D22: HERNÁNDEZ | E22: RIQUELME | F22: SOFÍA CATALINA | H22: Rendida | I22: 45758 | K22: 2 | L22: 2 | M22: 2 | N22: 1 | P22: =SUM(K22:N22) -> 7 | Q22: =(P22*1)/16 -> 0.4375 | R22: =IF(H22="Rendida ",IF('Resultados Individuales'!Q22<49.5%,"Por Mejorar",IF('Resultados Individuales'!Q22<64.5%,"Base",IF('Resultados Individuales'!Q22<84.5%,"Satisfactorio","Óptimo"))),"No rendida o no válida") -> Por Mejorar | S22: 4.6
A23: 21328435 | B23: 5 | C23: ANDRÉS ANTONIO HERNÁNDEZ NÚÑEZ | D23: HERNÁNDEZ | E23: NÚÑEZ | F23: ANDRÉS ANTONIO | G23: Interrupción voluntaria (no rinde EPI 2025) | H23: No aplica | J23: No aplica | P23: =SUM(K23:N23) -> 0 | Q23: =(P23*1)/16 -> 0 | R23: =IF(H23="Rendida ",IF('Resultados Individuales'!Q23<49.5%,"Por Mejorar",IF('Resultados Individuales'!Q23<64.5%,"Base",IF('Resultados Individuales'!Q23<84.5%,"Satisfactorio","Óptimo"))),"No rendida o no válida") -> No rendida o no válida | T23: Estudiante desactivado por inactividad
A24: 21342357 | B24: 6 | C24: VICENTE ALFREDO VIDAL JIMÉNEZ | D24: VIDAL | E24: JIMÉNEZ | F24: VICENTE ALFREDO | H24: Rendida | I24: 45758 | K24: 2 | L24: 2 | M24: 1 | N24: 2 | P24: =SUM(K24:N24) -> 7 | Q24: =(P24*1)/16 -> 0.4375 | R24: =IF(H24="Rendida ",IF('Resultados Individuales'!Q24<49.5%,"Por Mejorar",IF('Resultados Individuales'!Q24<64.5%,"Base",IF('Resultados Individuales'!Q24<84.5%,"Satisfactorio","Óptimo"))),"No rendida o no válida") -> Por Mejorar | S24: 5.8
A25: 21350588 | B25: 2 | C25: CAMILA NOEMÍ ARIAS VILLAGRÁN | D25: ARIAS | E25: VILLAGRÁN | F25: CAMILA NOEMÍ | H25: Rendida | I25: 45758 | K25: 2 | L25: 2 | M25: 2 | N25: 1 | P25: =SUM(K25:N25) -> 7 | Q25: =(P25*1)/16 -> 0.4375 | R25: =IF(H25="Rendida ",IF('Resultados Individuales'!Q25<49.5%,"Por Mejorar",IF('Resultados Individuales'!Q25<64.5%,"Base",IF('Resultados Individuales'!Q25<84.5%,"Satisfactorio","Óptimo"))),"No rendida o no válida") -> Por Mejorar | S25: 5.1
A26: 21360728 | B26: 6 | C26: MARÍA DOMINGA ALBORNOZ TORRES | D26: ALBORNOZ | E26: TORRES | F26: MARÍA DOMINGA | H26: Rendida | I26: 45758 | K26: 2 | L26: 3 | M26: 2 | N26: 2 | P26: =SUM(K26:N26) -> 9 | Q26: =(P26*1)/16 -> 0.5625 | R26: =IF(H26="Rendida ",IF('Resultados Individuales'!Q26<49.5%,"Por Mejorar",IF('Resultados Individuales'!Q26<64.5%,"Base",IF('Resultados Individuales'!Q26<84.5%,"Satisfactorio","Óptimo"))),"No rendida o no válida") -> Base | S26: 5
A27: 21429663 | B27: 2 | C27: ALAN ADÁN KRAMP LAZO | D27: KRAMP | E27: LAZO | F27: ALAN ADÁN | H27: Rendida | I27: 45758 | K27: 2 | L27: 3 | M27: 2 | N27: 1 | P27: =SUM(K27:N27) -> 8 | Q27: =(P27*1)/16 -> 0.5 | R27: =IF(H27="Rendida ",IF('Resultados Individuales'!Q27<49.5%,"Por Mejorar",IF('Resultados Individuales'!Q27<64.5%,"Base",IF('Resultados Individuales'!Q27<84.5%,"Satisfactorio","Óptimo"))),"No rendida o no válida") -> Base | S27: 4.9
A28: 21436237 | B28: 6 | C28: JAMES BENJAMÍN VELASCO SALINAS | D28: VELASCO | E28: SALINAS | F28: JAMES BENJAMÍN | H28: Rendida | I28: 45758 | K28: 2 | L28: 2 | M28: 2 | N28: 3 | P28: =SUM(K28:N28) -> 9 | Q28: =(P28*1)/16 -> 0.5625 | R28: =IF(H28="Rendida ",IF('Resultados Individuales'!Q28<49.5%,"Por Mejorar",IF('Resultados Individuales'!Q28<64.5%,"Base",IF('Resultados Individuales'!Q28<84.5%,"Satisfactorio","Óptimo"))),"No rendida o no válida") -> Base | S28: 5.5
A29: 21450191 | B29: 0 | C29: ANTONIA FERNANDA GALLEGUILLOS CORREA | D29: GALLEGUILLOS | E29: CORREA | F29: ANTONIA FERNANDA | H29: Rendida | I29: 45758 | K29: 3 | L29: 4 | M29: 3 | N29: 3 | P29: =SUM(K29:N29) -> 13 | Q29: =(P29*1)/16 -> 0.8125 | R29: =IF(H29="Rendida ",IF('Resultados Individuales'!Q29<49.5%,"Por Mejorar",IF('Resultados Individuales'!Q29<64.5%,"Base",IF('Resultados Individuales'!Q29<84.5%,"Satisfactorio","Óptimo"))),"No rendida o no válida") -> Satisfactorio | S29: 4.5
A30: 21475698 | B30: 6 | C30: DOMINIQUE ARELI SALAS PÉREZ | D30: SALAS | E30: PÉREZ | F30: DOMINIQUE ARELI | H30: Rendida | I30: 45758 | K30: 3 | L30: 2 | M30: 2 | N30: 1 | P30: =SUM(K30:N30) -> 8 | Q30: =(P30*1)/16 -> 0.5 | R30: =IF(H30="Rendida ",IF('Resultados Individuales'!Q30<49.5%,"Por Mejorar",IF('Resultados Individuales'!Q30<64.5%,"Base",IF('Resultados Individuales'!Q30<84.5%,"Satisfactorio","Óptimo"))),"No rendida o no válida") -> Base | S30: 5
A31: 21476009 | B31: 6 | C31: EMMA SANEM BUSTAMANTE LOBOS | D31: BUSTAMANTE | E31: LOBOS | F31: EMMA SANEM | H31: Rendida | I31: 45758 | K31: 2 | L31: 1 | M31: 1 | N31: 1 | P31: =SUM(K31:N31) -> 5 | Q31: =(P31*1)/16 -> 0.3125 | R31: =IF(H31="Rendida ",IF('Resultados Individuales'!Q31<49.5%,"Por Mejorar",IF('Resultados Individuales'!Q31<64.5%,"Base",IF('Resultados Individuales'!Q31<84.5%,"Satisfactorio","Óptimo"))),"No rendida o no válida") -> Por Mejorar | S31: 3.4
A32: 21479731 | B32: 3 | C32: ANAÍS ISABU DÍAZ MALUENDA | D32: DÍAZ | E32: MALUENDA | F32: ANAÍS ISABU | H32: Rendida | I32: 45758 | K32: 1 | L32: 2 | M32: 2 | N32: 2 | P32: =SUM(K32:N32) -> 7 | Q32: =(P32*1)/16 -> 0.4375 | R32: =IF(H32="Rendida ",IF('Resultados Individuales'!Q32<49.5%,"Por Mejorar",IF('Resultados Individuales'!Q32<64.5%,"Base",IF('Resultados Individuales'!Q32<84.5%,"Satisfactorio","Óptimo"))),"No rendida o no válida") -> Por Mejorar | S32: 4.6
A33: 21483662 | B33: 9 | C33: AMARANTA PENELOPE VILLARROEL LANDETA | D33: VILLARROEL | E33: LANDETA | F33: AMARANTA PENELOPE | H33: Rendida | I33: 45758 | K33: 1 | L33: 1 | M33: 1 | N33: 1 | P33: =SUM(K33:N33) -> 4 | Q33: =(P33*1)/16 -> 0.25 | R33: =IF(H33="Rendida ",IF('Resultados Individuales'!Q33<49.5%,"Por Mejorar",IF('Resultados Individuales'!Q33<64.5%,"Base",IF('Resultados Individuales'!Q33<84.5%,"Satisfactorio","Óptimo"))),"No rendida o no válida") -> Por Mejorar | S33: 5.2
A34: 21498187 | B34: 4 | C34: MAXIMILIANO HERNÁN MORALES GONZÁLEZ | D34: MORALES | E34: GONZÁLEZ | F34: MAXIMILIANO HERNÁN | G34: Interrupción voluntaria (no rinde EPI 2025) | H34: No aplica | J34: No aplica | P34: =SUM(K34:N34) -> 0 | Q34: =(P34*1)/16 -> 0 | R34: =IF(H34="Rendida ",IF('Resultados Individuales'!Q34<49.5%,"Por Mejorar",IF('Resultados Individuales'!Q34<64.5%,"Base",IF('Resultados Individuales'!Q34<84.5%,"Satisfactorio","Óptimo"))),"No rendida o no válida") -> No rendida o no válida | T34: Estudiante desactivado por inactividad
A35: 21514916 | B35: 1 | C35: SCHELSEA LEMONI JESSY ANAHI TORO FÁBREGA | D35: TORO | E35: FÁBREGA | F35: SCHELSEA LEMONI JESSY ANAHI | G35: Interrupción voluntaria (no rinde EPI 2025) | H35: No aplica | J35: No aplica | P35: =SUM(K35:N35) -> 0 | Q35: =(P35*1)/16 -> 0 | R35: =IF(H35="Rendida ",IF('Resultados Individuales'!Q35<49.5%,"Por Mejorar",IF('Resultados Individuales'!Q35<64.5%,"Base",IF('Resultados Individuales'!Q35<84.5%,"Satisfactorio","Óptimo"))),"No rendida o no válida") -> No rendida o no válida | T35: Estudiante desactivado por inactividad
A36: 21527115 | B36: 3 | C36: THEO ADRIANO CAZAÑAS NEIRA | D36: CAZAÑAS | E36: NEIRA | F36: THEO ADRIANO | H36: Rendida | I36: 45758 | K36: 4 | L36: 2 | M36: 3 | N36: 1 | P36: =SUM(K36:N36) -> 10 | Q36: =(P36*1)/16 -> 0.625 | R36: =IF(H36="Rendida ",IF('Resultados Individuales'!Q36<49.5%,"Por Mejorar",IF('Resultados Individuales'!Q36<64.5%,"Base",IF('Resultados Individuales'!Q36<84.5%,"Satisfactorio","Óptimo"))),"No rendida o no válida") -> Base | S36: 5.6
A37: 21529159 | B37: 6 | C37: VALENTINA EVELYN VALDÉS VIDAL | D37: VALDÉS | E37: VIDAL | F37: VALENTINA EVELYN | H37: Rendida | I37: 45758 | K37: 2 | L37: 2 | M37: 2 | N37: 1 | P37: =SUM(K37:N37) -> 7 | Q37: =(P37*1)/16 -> 0.4375 | R37: =IF(H37="Rendida ",IF('Resultados Individuales'!Q37<49.5%,"Por Mejorar",IF('Resultados Individuales'!Q37<64.5%,"Base",IF('Resultados Individuales'!Q37<84.5%,"Satisfactorio","Óptimo"))),"No rendida o no válida") -> Por Mejorar | S37: 5
A38: 21550070 | B38: 5 | C38: CAMILO JESUS REYES PÉREZ | D38: REYES | E38: PÉREZ | F38: CAMILO JESUS | H38: Rendida | I38: 45758 | K38: 1 | L38: 1 | M38: 1 | N38: 1 | P38: =SUM(K38:N38) -> 4 | Q38: =(P38*1)/16 -> 0.25 | R38: =IF(H38="Rendida ",IF('Resultados Individuales'!Q38<49.5%,"Por Mejorar",IF('Resultados Individuales'!Q38<64.5%,"Base",IF('Resultados Individuales'!Q38<84.5%,"Satisfactorio","Óptimo"))),"No rendida o no válida") -> Por Mejorar | S38: 4.4
A39: 21576667 | B39: 5 | C39: ANTONIA ANAIS SOLIS CHELME | D39: SOLIS | E39: CHELME | F39: ANTONIA ANAIS | H39: Rendida | I39: 45758 | K39: 3 | L39: 4 | M39: 3 | N39: 4 | P39: =SUM(K39:N39) -> 14 | Q39: =(P39*1)/16 -> 0.875 | R39: =IF(H39="Rendida ",IF('Resultados Individuales'!Q39<49.5%,"Por Mejorar",IF('Resultados Individuales'!Q39<64.5%,"Base",IF('Resultados Individuales'!Q39<84.5%,"Satisfactorio","Óptimo"))),"No rendida o no válida") -> Óptimo | S39: 4.9
A40: 21588818 | B40: 5 | C40: BIANCA IGNACIA GÓMEZ RAMÍREZ | D40: GÓMEZ | E40: RAMÍREZ | F40: BIANCA IGNACIA | H40: Rendida | I40: 45758 | K40: 2 | L40: 4 | M40: 2 | N40: 2 | P40: =SUM(K40:N40) -> 10 | Q40: =(P40*1)/16 -> 0.625 | R40: =IF(H40="Rendida ",IF('Resultados Individuales'!Q40<49.5%,"Por Mejorar",IF('Resultados Individuales'!Q40<64.5%,"Base",IF('Resultados Individuales'!Q40<84.5%,"Satisfactorio","Óptimo"))),"No rendida o no válida") -> Base | S40: 5.6
A41: 21598337 | B41: 4 | C41: SOFÍA BELÉN VERGARA GONZÁLEZ | D41: VERGARA | E41: GONZÁLEZ | F41: SOFÍA BELÉN | H41: Rendida | I41: 45758 | K41: 1 | L41: 1 | M41: 1 | N41: 1 | P41: =SUM(K41:N41) -> 4 | Q41: =(P41*1)/16 -> 0.25 | R41: =IF(H41="Rendida ",IF('Resultados Individuales'!Q41<49.5%,"Por Mejorar",IF('Resultados Individuales'!Q41<64.5%,"Base",IF('Resultados Individuales'!Q41<84.5%,"Satisfactorio","Óptimo"))),"No rendida o no válida") -> Por Mejorar | S41: 4.2
...

Sheet Resultados Grupales
D1: Actividad problema 1 | I1: Resultados Generales Cohorte
A2: N Estudiantes habilitados para rendir | B2: N Estudiantes que rindieron | C2: Porcentaje de cobertura EPI | D2: Es capaz de reconocer un problema disciplinar (C.P. o RR.II.), empleando herramientas metodológicas. | E2: Es capaz de distinguir las estructuras teóricas básicas (C.P. o RR.II), empleando conceptos y categorías en una problemática disciplinar. | F2: Es capaz de elaborar un esquema de investigación. | G2: Es capaz de extraer las ideas fundamentales de un texto, ordenándolas en sentido lógico y utilizando las normas de citación correspondientes. | I2: PUNTAJE TOTAL | J2: PORCENTAJE DE LOGRO EPI 2025 | K2: CATEGORÍA RESULTADO GLOBAL
A3: 51 | B3: 47 | C3: 0.92

Sheet Validación datos NO BORRAR
E3: Estado de Habilitación para rendir | F3: ESTATUS DE RENDICIÓN | G3: JUSTIFICATIVO DE NO RENDICIÓN | H3: Puntaje según categoría
E4: Avance curricular suficiente o adecuado para evaluar ciclo básico | F4: Rendida | G4: Justifica | H4: 0
E5: Avance curricular insuficiente para evaluar ciclo básico (no rinde EPI 2025) | F5: No rendida | G5: No justifica | H5: 1
E6: EPI pendiente periodo anterior | F6: Rendida no válida | G6: No aplica | H6: 2
E7: Interrupción voluntaria (no rinde EPI 2025) | F7: No aplica | H7: 3
E8: Expulsión | H8: 4
E9: Retracto

Sheet ACCIONES
B2: NOMBRE DE LA FACULTAD
B3: NOMBRE DEL PROGRAMA ACADÉMICO
B4: PLAN DE ESTUDIO AÑO
B6: Instrucciones: completar items en color azul. Se incorporan ejemplos que pueden se considerados por las unidades académicas para la elaboración de sus propuestas.
B8: ANÁLISIS Y TOMA DE DECISIONES BASADAS EN LA EVIDENCIA
B9: Se presentan, a continuación, las acciones planificadas considerando el análisis de los resultados de la aplicación EPI 2025. Estas acciones -consideradas para ser desarrolladas a corto, mediano y largo plazo- están orientadas a fortalecer el perfil intermedio intermedio del programa, teniendo a la vista las competencias con menores niveles de logro.
B10: N° | C10: TIPO DE ACCIÓN | D10: ACCIONES | L10: MEDIO DE VERIFICACIÓN
B11: I. | C11: CORTO PLAZO | D11: 1. Realización de focus group con estudiantesque rindieron evaluación para analizar factores incidentes en resultados obtenidos (percepción sobre instructivo, nivel de dificultad de dimensiones y preguntas, insumos, y condiciones de evaluación). 2. Incorporación en cursos de linea formativas (RRII, Instituciones y Metodologia) actividades formativas que vinculadas a reforzar competencias de perfil intermedio | L11: 1. Pauta focus group (realización agosto) 2. Programaciones (inclusión de actividades alineadas con PI)
B12: II. | C12: MEDIANO PLAZO | D12: 1. Jornada con equipo curricular para contrastar resultados de Epi en relación con resultados académicos obtenidos cursos ciclos básico. Levantamiento nudos críticos y plan de accion. 2. Ajustes de metodologías y evaluaciones en programaciones cursos de ciclo profundización (con Plan 2015 vigente) | L12: 1. Acta comité curricular (enero 26) 2. Programaciones 1S 2026 cursos lineas formativas
B13: III. | C13: LARGO PLAZO | D13: Modificación perfil intermedio dado cambio Plan de estudio 2024 | L13: Documentos asociados a cambios perfil intermedio

Sheet Hoja1
A1: POR MEJORAR | C1: RINDE
A2: SUFICIENTE | C2: NO RINDE
A3: SATISFACTORIO
A4: ÓPTIMO
