Workbook

Sheet Rúbrica Resultados Globales
A2: A) | B2: Definiciones a nivel micro (rúbrica)
C4: Nivel de logro
C5: Óptimo | D5: Satisfactorio | E5: Base | F5: Por Mejorar | G5: No observado
C6: (4 puntos) | D6: (3 puntos) | E6: (2 puntos) | F6: (1 punto) | G6: (0 punto)
C7: El desempeño descrito se logra completamente | D7: El desempeño descrito se logra, sin embargo, presenta algunas imprecisiones. | E7: El desempeño descrito se logra de forma mínima | F7: El desempeño descrito se presenta de forma errónea y/o no se ajusta a lo solicitado | G7: El desempeño descrito no es observado dada la ausencia de acciones o productos
A9: B) | B9: Definiciones a nivel macro (EPI)
B10: El presente documento tiene por objetivo especificar los criterios que dan origen a las definiciones del indicador global de EPI. Entendemos que la EPI es una evaluación formativa, donde existe una diversidad de instrumentos y exigencias asociadas a ellos que responde a la especificidad de cada disciplina. Sin embargo, desde el nivel central el foco se sitúa fundamentalmente en detectar las necesidades de apoyo necesarias que requeriría el estudiantado para continuar su ciclo de profundización, y, en otro casos, para detectar los niveles de autonomía que presentan los/las estudiantes para transitar al ciclo de profundización. En este contexto, los términos utilizados la columna “Justificación” de la siguiente tabla, como; “buen nivel”, “apropiado”,” mínimo”, deben entenderse en el contexto específico y situado de cada evaluación.
C15: Categorías
C16: Óptimo | D16: Satisfactorio | E16: Base | F16: Por Mejorar
B17: Porcentajes | C17: 100%-85% | D17: 84% - 65% | E17: 64% - 50% | F17: 0% - 49%
B18: Definiciones | C18: Los resultados obtenidos por el/la estudiante en la Evaluación de Perfil Intermedio evidencian que ha logrado los aprendizajes clave del Ciclo Básico de formación que le permiten continuar con su trayectoria formativa en el Ciclo de Profundización y/ Especialización, con autonomía, avanzando en el desarrollo de los desempeños evidenciados. | D18: Los resultados obtenidos por el/la estudiante en la Evaluación de Perfil Intermedio evidencian que ha logrado los aprendizajes clave del Ciclo Básico de formación que le permiten continuar con su trayectoria formativa en el Ciclo de Profundización y/o Especialización, con autonomía. Sin embargo, se evidencian aspectos específicos y acotados en que es necesario fortalecer los desempeños. | E18: Los resultados obtenidos por el/la estudiante en la Evaluación de Perfil Intermedio evidencian que el logro de los aprendizajes clave del Ciclo Básico de formación se cumplen de manera mínimay requieren ser fortalecidos durante el Ciclo de Profundización y/o Especialización, para apoyar la continuidad de la trayectoria formativa. | F18: Los resultados obtenidos por el/la estudiante en la Evaluación de Perfil Intermedio evidencian que no se han logrado los aprendizajes clave del Ciclo Básico de formación , requiriendo de acciones de apoyo en el Ciclo de Profundización y/o Especialización que favorezcan el desarrollo de los desempeños evaluados y aseguren la continuidad de la trayectoria formativa. | H18: El/la estudiante en la Evaluación de Perfil Intermedio no presenta respuestas, lo que no permite evidenciar el logro de los aprendizajes clave del Ciclo Básico de formación.
C19: El/la estudiante avanza con autonomía al Ciclo de Profundización y/o Especialización. Cuenta con desempeños relevantes para la continuidad de su trayectoria formativa | E19: El/la estudiante avanza al Ciclo de Profundización y/o Especialización con apoyos adicionales para desarrollar los aprendizajes prioritarios que permiten dar continuidad a su trayectoria formativa
C20: Acciones de fortalecimiento de las trayectorias formativas
B21: Justificación | C21: Dado el carácter formativo de esta evaluación, se define este nivel a partir del 85% ya que a partir de este porcentaje se evidencia con claridad un buen nivel de conocimientos teórico-disciplinares de los contenidos, así como un muy buen manejo metodológico/práctico de estos, sin necesitar apoyos especificos. | D21: Dado el carácter formativo de esta evaluación, se define este nivel a partir del 65% y no del 70% en función del criterio de la autonomía para poder continuar hacia el ciclo de profundización, siendo el 65% un nivel de solidez suficiente para aquello, demostrando un conocimiento apropiado de los conocimientos teórico-disciplinares y un manejo apropiado metodológico/práctico de estos. Esto también obedece a la diversidad de EPIs existentes y a los distintos niveles de exigencia de los distintos instrumentos. | E21: Dado el carácter formativo de la evaluación, se define este nivel a partir del 50% ya que el/la estudiante demuestra un conocimiento/manejo básico de los contenidos/habilidades esenciales, sin embargo el nivel de profundidad de este manejo es superficial/parcial/insuficiente. logrando solo a mitad del puntaje. El nivel de profundidad de los aprendizajes logrados y la consecuente necesidad de apoyos predominan para definir los porcentajes de logro de este nivel. | F21: Dado el carácter formativo de la evaluación, se define este nivel como porcentajes de logro menores al 50%, ya que el/la estudiante no alcanza un mínimo de conocimiento ni manejo de contenidos y habilidades esperadas, evidenciando la necesidad de apoyos para poder transitar al ciclo de profundización.

Sheet Rúbrica situación evaluativa 
V136: *

Sheet Resultados Individuales
A1: DATOS DE ESTUDIANTES DE LA COHORTE | K1: Actividad problema 1 Nivel de logro 1: 1 punto Nivel de logro 2 : 2 puntos Nivel del logro 3 : 3 puntos Nivel de logro 4 : 4 puntos | O1: Actividad Problema 2 Nivel de logro 1: 1 punto Nivel de logro 2 : 2 puntos Nivel del logro 3 : 3 puntos Nivel de logro 4 : 4 puntos | S1: Resultado General por estudiante
V2: COMENTARIOS GENERALES POR ESTUDIANTE
A3: RUT ESTUDIANTE | B3: DV | D3: PRIMER APELLIDO (Apellido paterno) | E3: SEGUNDO APELLIDO (Apellido materno) | F3: NOMBRES | G3: ESTADO DE HABILITACIÓN PARA RENDIR | H3: ESTATUS DE RENDICIÓN | I3: FECHA DE RENDICIÓN | J3: JUSTIFICACIÓN DE NO RENDICIÓN | K3: Toma de posición respecto de la idoneidad de la acción de precario. | L3: Posicionamiento crítico en torno a elementos éticos y de justicia social incluidos en el caso. | M3: Identificación de razonamientos jurídicos y sus posibles correlaciones. (Razonamiento jurisdiccional y razonamiento académico) | N3: Uso del lenguaje jurídico apropiado con el caso y postura en el rol de abogado. | O3: Análisis enfoque del de género en el proyecto de ley | P3: Reflexión sobre desigualdades estructurales en el contexto procesal de familia | Q3: Perspectiva interseccional en el análisis | R3: Uso del lenguaje jurídico apropiado con el caso y postura en el rol de abogado/a | S3: PUNTAJE TOTAL ESTUDIANTE | T3: PORCENTAJE DE LOGRO | U3: CATEGORÍA RESULTADO GLOBAL ESTUDIANTE
A4: 8915103 | B4: 1 | C4: ALEJANDRO ROBERTO ROJAS SANTANDER | D4: ROJAS | E4: SANTANDER | F4: ALEJANDRO ROBERTO | G4: Avance curricular suficiente o adecuado para evaluar ciclo básico | H4: No rendida | I4: no aplica | S4: =SUM(K4:R4) -> 0 | T4: =S4/40 -> 0 | U4: =IF(H4="Rendida ",IF('Resultados Individuales'!T4<49.5%,"Por Mejorar",IF('Resultados Individuales'!T4<64.5%,"Base",IF('Resultados Individuales'!T4<84.5%,"Satisfactorio","Óptimo"))),"No rendida o no válida") -> No rendida o no válida
A5: 11828211 | B5: 6 | C5: MICHELE LOUISSETTE HIRIART LAULIE | D5: HIRIART | E5: LAULIE | F5: MICHELE LOUISSETTE | G5: Avance curricular suficiente o adecuado para evaluar ciclo básico | H5: Rendida | I5: 45758 | K5: 3 | L5: 4 | M5: 4 | N5: 4 | O5: 3 | P5: 3 | Q5: 2 | R5: 4 | S5: =SUM(K5:R5) -> 27 | T5: =S5/40 -> 0.675 | U5: =IF(H5="Rendida ",IF('Resultados Individuales'!T5<49.5%,"Por Mejorar",IF('Resultados Individuales'!T5<64.5%,"Base",IF('Resultados Individuales'!T5<84.5%,"Satisfactorio","Óptimo"))),"No rendida o no válida") -> Satisfactorio | V5: El desempeño evidenciado en ambas actividades refleja un nivel de análisis jurídico sobresaliente, caracterizado por el uso preciso y riguroso del lenguaje técnico, la identificación clara de instituciones y categorías relevantes, así como por la capacidad de integrar razonamientos normativos con dimensiones éticas y sociales. En la primera actividad, se observa un análisis crítico excepcional que aborda con profundidad la tensión entre equidad y seguridad jurídica, vinculando con maestría el pensamiento de Finnis con el razonamiento judicial, lo que demuestra madurez conceptual y un dominio sólido del derecho contemporáneo. En la segunda actividad, se visibiliza un manejo claro de las innovaciones procesales y del enfoque de derechos de niñez y género, destacando medidas concretas como la participación efectiva de NNA y la incorporación de representaciones jurídicas especializadas, junto con una acertada reflexión sobre el rol del proceso judicial en la protección de derechos desde una mirada interseccional. Para alcanzar un nivel óptimo en todas las dimensiones, se sugiere como proyección futura reforzar la referencia explícita a normas específicas —citando artículos del proyecto de ley analizado— e integrar el marco internacional aplicable, como la CEDAW o la Convención sobre los Derechos del Niño. Asimismo, sería valioso profundizar en el análisis interseccional, considerando cómo variables como clase social y pertenencia étnica inciden en el acceso a la justicia. Esta consolidación permitiría elevar aún más la calidad ya destacada del trabajo
A6: 15166536 | B6: 5 | C6: CAMILA YITSEN ALVAREZ ARUCUTIPA | D6: ALVAREZ | E6: ARUCUTIPA | F6: CAMILA YITSEN | G6: Avance curricular suficiente o adecuado para evaluar ciclo básico | H6: Rendida | I6: 45758 | K6: 1 | L6: 2 | M6: 3 | N6: 3 | O6: 3 | P6: 3 | Q6: 3 | R6: 3 | S6: =SUM(K6:R6) -> 21 | T6: =S6/40 -> 0.525 | U6: =IF(H6="Rendida ",IF('Resultados Individuales'!T6<49.5%,"Por Mejorar",IF('Resultados Individuales'!T6<64.5%,"Base",IF('Resultados Individuales'!T6<84.5%,"Satisfactorio","Óptimo"))),"No rendida o no válida") -> Base | V6: El desempeño en las dos actividades refleja contrastes claros en el logro de competencias del perfil intermedio de Derecho. En la primera actividad, si bien se desarrollan las tres preguntas y se hace referencia expresa al art. 2195 del Código Civil, así como a la teoría de Finnis y al valor del matrimonio como institución, se observa una confusión conceptual grave: la consigna exigía argumentar la postura opuesta a la del tribunal (defender la procedencia del precario), pero la respuesta se alinea con el razonamiento judicial, afectando la coherencia de todo el análisis. Esta omisión impide un desarrollo técnico sólido de los elementos del precario y resta profundidad al análisis ético, que se mantiene en un nivel superficial sin incorporar categorías centrales como seguridad jurídica, interpretación extensiva o incorrecta aplicación del derecho. Se requiere también mayor precisión en la relación entre jurisprudencia y derecho positivo, así como un desarrollo más completo de los dos elementos constitutivos del matrimonio según Finnis. En contraste, en la segunda actividad se aprecia un manejo mucho más maduro de las herramientas jurídicas y del análisis crítico. Destacan la identificación precisa de los mecanismos de participación de NNA —audiencias específicas, obligación de fundamentación judicial y vínculo con autonomía progresiva— y un análisis competente del enfoque de género que reconoce medidas como la protección reforzada en casos de violencia intrafamiliar, la corresponsabilidad en la tuición y la capacitación judicial. Asimismo, se contextualizan acertadamente motivaciones legislativas relevantes (crisis del ex-SENAME, estallido social 2019, proceso constituyente), y la relación con el debido proceso se fundamenta de manera ejemplar mediante la Convención Americana de Derechos Humanos y la jurisprudencia de la Corte IDH. Aun con estas fortalezas, para alcanzar un nivel óptimo se sugiere profundizar en la relevancia normativa específica, vincular más explícitamente las medidas con estándares internacionales concretos (CEDAW, Convención sobre los Derechos del Niño) y ampliar el tratamiento de la interseccionalidad, analizando cómo variables como género, edad, clase y etnia se entrecruzan en el acceso a la justicia.
A7: 16071809 | B7: 9 | C7: VANESSA ELENA CARRASCO MUÑOZ | D7: CARRASCO | E7: MUÑOZ | F7: VANESSA ELENA | G7: Avance curricular suficiente o adecuado para evaluar ciclo básico | H7: Rendida | I7: 45758 | K7: 3 | L7: 4 | M7: 4 | N7: 4 | O7: 2 | P7: 2 | Q7: 2 | R7: 3 | S7: =SUM(K7:R7) -> 24 | T7: =S7/40 -> 0.6 | U7: =IF(H7="Rendida ",IF('Resultados Individuales'!T7<49.5%,"Por Mejorar",IF('Resultados Individuales'!T7<64.5%,"Base",IF('Resultados Individuales'!T7<84.5%,"Satisfactorio","Óptimo"))),"No rendida o no válida") -> Base | V7: El desempeño en ambas actividades refleja un manejo sólido del razonamiento jurídico y del uso de un lenguaje técnico especializado, con especial fortaleza en el desarrollo conceptual y crítico. En la primera actividad, el análisis del precario es coherente y bien estructurado, demostrando comprensión de la figura y de la ausencia de nexo jurídico como fundamento central de la acción. Destaca un posicionamiento ético original y profundo, que problematiza con rigor las tensiones entre justicia social y seguridad jurídica, utilizando categorías avanzadas como interpretación extensiva, analogía e incorrecta aplicación del derecho. Asimismo, la correlación con la filosofía de Finnis se desarrolla con solvencia académica, estableciendo límites críticos a las obligaciones derivadas del matrimonio y proponiendo una ponderación entre instituciones jurídicas. El lenguaje técnico utilizado refleja madurez formativa y proyección profesional. Para fortalecer aún más este desempeño, se sugiere citar directamente el art. 2195 del Código Civil y sistematizar de manera más clara los tres requisitos del precario, junto con mejorar ciertos detalles formales de construcción sintáctica. En la segunda actividad, se evidencia un buen manejo del tema, destacando la identificación precisa de los mecanismos de participación de niños, niñas y adolescentes —derecho a ser oídos, audiencias adaptadas y obligación de fundamentación judicial— y su correcta vinculación con la autonomía progresiva. También es pertinente la valoración de la coordinación intersectorial como herramienta clave para la garantía de derechos. Sin embargo, el análisis del enfoque de género requiere mayor profundidad, dado que no se distinguen medidas concretas orientadas a mujeres, niñas o adolescentes ni se articulan normas internacionales relevantes. La interseccionalidad aparece mencionada, pero sin integrar un examen crítico de variables múltiples que incidan en el acceso a la justicia. Como proyección de mejora, se recomienda incorporar referencias a instrumentos internacionales sobre igualdad y no discriminación (CEDAW, Convención de Belém do Pará), así como profundizar el análisis en torno a fenómenos sociales nacionales recientes (crisis del SENAME, estallido social de 2019, proceso constituyente) y desarrollar una mirada interseccional más completa, incluyendo género, clase y etnia.
A8: 17879125 | B8: 7 | C8: FELIPE IGNACIO PARRA OROPESA | D8: PARRA | E8: OROPESA | F8: FELIPE IGNACIO | G8: Interrupción voluntaria (no rinde EPI 2025) | S8: =SUM(K8:R8) -> 0 | T8: =S8/40 -> 0 | U8: =IF(H8="Rendida ",IF('Resultados Individuales'!T8<49.5%,"Por Mejorar",IF('Resultados Individuales'!T8<64.5%,"Base",IF('Resultados Individuales'!T8<84.5%,"Satisfactorio","Óptimo"))),"No rendida o no válida") -> No rendida o no válida
A9: 18502526 | B9: 8 | C9: JORGE RODRIGO GALLEGUILLOS MOTA | D9: GALLEGUILLOS | E9: MOTA | F9: JORGE RODRIGO | G9: Avance curricular suficiente o adecuado para evaluar ciclo básico | H9: No rendida | I9: no aplica | S9: =SUM(K9:R9) -> 0 | T9: =S9/40 -> 0 | U9: =IF(H9="Rendida ",IF('Resultados Individuales'!T9<49.5%,"Por Mejorar",IF('Resultados Individuales'!T9<64.5%,"Base",IF('Resultados Individuales'!T9<84.5%,"Satisfactorio","Óptimo"))),"No rendida o no válida") -> No rendida o no válida
A10: 18956008 | B10: 7 | C10: NICOLÁS ALEJANDRO CATALÁN ARTIGAS | D10: CATALÁN | E10: ARTIGAS | F10: NICOLÁS ALEJANDRO | G10: Avance curricular suficiente o adecuado para evaluar ciclo básico | H10: Rendida | I10: 45758 | K10: 4 | L10: 4 | M10: 4 | N10: 4 | O10: 3 | P10: 4 | Q10: 4 | R10: 3 | S10: =SUM(K10:R10) -> 30 | T10: =S10/40 -> 0.75 | U10: =IF(H10="Rendida ",IF('Resultados Individuales'!T10<49.5%,"Por Mejorar",IF('Resultados Individuales'!T10<64.5%,"Base",IF('Resultados Individuales'!T10<84.5%,"Satisfactorio","Óptimo"))),"No rendida o no válida") -> Satisfactorio | V10: El desempeño alcanzado en ambas actividades refleja un nivel sobresaliente de análisis jurídico, técnico y ético, propio de un perfil intermedio consolidado con proyección hacia niveles avanzados. En la primera actividad, se observa un desarrollo sistemático y riguroso de la institución del precario, abordando con precisión los tres requisitos copulativos del art. 2195 del Código Civil y destacando con fundamentación sólida la inexistencia de nexo jurídico entre las partes. El posicionamiento ético trasciende lo meramente formal al incorporar múltiples dimensiones —justicia social, perspectiva de género e interés superior del menor— ofreciendo una comprensión holística de la problemática. La referencia a la teoría de John Finnis se articula de modo académico y pertinente, integrando los elementos constitutivos del matrimonio (fides y procreación) y vinculándolos con el considerando quinto de la sentencia, lo que revela madurez en el razonamiento teórico y práctico. El lenguaje jurídico empleado es técnico, preciso y profesional. En la segunda actividad, se constata un manejo conceptual igualmente sólido sobre el proyecto de ley, destacando la identificación clara de innovaciones procesales y el análisis profundo del enfoque de género, con énfasis en la corresponsabilidad parental, medidas de protección en contextos de violencia intrafamiliar y la creación de unidades técnicas especializadas para fortalecer la protección integral. Su reflexión crítica sobre desigualdades estructurales es consistente y se complementa con una adecuada integración de la perspectiva interseccional, considerando género, edad y situación socioeconómica. El uso del lenguaje jurídico es preciso, articulando correctamente estándares de debido proceso y principios rectores como el interés superior del niño. Para avanzar hacia un nivel de excelencia, se sugiere enriquecer el análisis con citas y referencias directas a instrumentos internacionales sobre derechos humanos (por ejemplo, Convención sobre los Derechos del Niño, CEDAW y Convención de Belém do Pará), y profundizar en la fundamentación normativa de las medidas de género a la luz del derecho comparado y las obligaciones internacionales del Estado
A11: 19126017 | B11: 1 | C11: ANGELA ESTEFANÍA JEREZ SILVA | D11: JEREZ | E11: SILVA | F11: ANGELA ESTEFANÍA | G11: Avance curricular suficiente o adecuado para evaluar ciclo básico | H11: No aplica | I11: no aplica | J11: No aplica | S11: =SUM(K11:R11) -> 0 | T11: =S11/40 -> 0 | U11: =IF(H11="Rendida ",IF('Resultados Individuales'!T11<49.5%,"Por Mejorar",IF('Resultados Individuales'!T11<64.5%,"Base",IF('Resultados Individuales'!T11<84.5%,"Satisfactorio","Óptimo"))),"No rendida o no válida") -> No rendida o no válida
A12: 19429710 | B12: 6 | C12: GABRIEL FERNANDO VALLEJOS MANRIQUEZ | D12: VALLEJOS | E12: MANRIQUEZ | F12: GABRIEL FERNANDO | G12: Avance curricular suficiente o adecuado para evaluar ciclo básico | H12: Rendida | I12: 45758 | K12: 2 | L12: 2 | M12: 3 | N12: 2 | O12: 2 | P12: 2 | Q12: 1 | R12: 2 | S12: =SUM(K12:R12) -> 16 | T12: =S12/40 -> 0.4 | U12: =IF(H12="Rendida ",IF('Resultados Individuales'!T12<49.5%,"Por Mejorar",IF('Resultados Individuales'!T12<64.5%,"Base",IF('Resultados Individuales'!T12<84.5%,"Satisfactorio","Óptimo"))),"No rendida o no válida") -> Por Mejorar | V12: El desempeño en ambas actividades muestra logros parciales en la aplicación del razonamiento jurídico y en la expresión argumentativa, aunque con diferencias marcadas entre los dos trabajos. En la primera actividad, se reconoce una comprensión general de los requisitos del precario y del valor institucional del matrimonio dentro del razonamiento judicial, pero la respuesta evidencia debilidades importantes en la construcción argumentativa y en la claridad conceptual, confundiendo elementos como herencia y posesión. El análisis ético y social es superficial y no logra profundizar en problemas claves como la justicia social o el uso de la analogía. El lenguaje jurídico empleado es básico e impreciso, acompañado de una redacción desordenada con errores de construcción que afectan la fluidez. Como proyección de mejora, resulta fundamental consolidar los aspectos técnicos de la institución del precario, trabajar un análisis crítico más robusto de las consecuencias jurídicas y sociales, y reforzar la expresión escrita formal y la argumentación sistemática. En la segunda actividad, se observa un mejor manejo de los contenidos, destacando la descripción de los mecanismos de participación de NNA —derecho a ser oídos, audiencias adaptadas y obligación de fundamentación judicial— así como su vinculación con la autonomía progresiva y las medidas de capacitación judicial. Del mismo modo, se identifica el avance hacia la corresponsabilidad parental y la protección reforzada ante violencia intrafamiliar. Sin embargo, el análisis resulta limitado en lo relativo al enfoque de género al no incorporar normas específicas, y la perspectiva interseccional solo se menciona de manera general a través de la referencia a niñas en contextos de vulnerabilidad, sin un desarrollo crítico más amplio. El lenguaje jurídico es funcional, pero el trabajo ganaría solidez con citas expresas a la Ley 21.430, la Convención sobre los Derechos del Niño, así como a disposiciones concretas del Código Civil y de Procedimiento Civil.
A13: 19522830 | B13: 2 | C13: PABLO VICENTE PARRY ARROYO | D13: PARRY | E13: ARROYO | F13: PABLO VICENTE | G13: Avance curricular suficiente o adecuado para evaluar ciclo básico | H13: Rendida | I13: 45758 | K13: 3 | L13: 4 | M13: 4 | N13: 4 | O13: 2 | P13: 3 | Q13: 3 | R13: 3 | S13: =SUM(K13:R13) -> 26 | T13: =S13/40 -> 0.65 | U13: =IF(H13="Rendida ",IF('Resultados Individuales'!T13<49.5%,"Por Mejorar",IF('Resultados Individuales'!T13<64.5%,"Base",IF('Resultados Individuales'!T13<84.5%,"Satisfactorio","Óptimo"))),"No rendida o no válida") -> Satisfactorio | V13: El desempeño en ambas actividades refleja un nivel jurídico avanzado, con proyección hacia estándares superiores al perfil intermedio esperado. En la primera actividad, se evidencia un posicionamiento ético crítico excepcional, que incorpora con precisión todos los conceptos técnicos solicitados —seguridad jurídica, incorrecta aplicación del derecho, orden público y protección constitucional—. La correlación conceptual es sobresaliente, identificando y vinculando las motivaciones de Finnis como contenidos implícitos del razonamiento judicial. Se desarrolla brillantemente la idea del matrimonio como bien humano intrínsecamente inteligible, conectando este valor con la decisión del tribunal de resguardar no solo los derechos legales, sino también las emociones y la salud mental de los cónyuges. El lenguaje jurídico es técnico y preciso, la estructura metodológica impecable y la redacción de excelencia, lo que proyecta un alto dominio conceptual y profesional. La única oportunidad de mejora se encuentra en profundizar aún más en el análisis de idoneidad del precario, desarrollando exhaustivamente los tres requisitos copulativos del art. 2195 CC en conexión explícita con los elementos del matrimonio según Finnis. En la segunda actividad, se articula de manera clara y rigurosa la relación entre los mecanismos de participación de los NNA (derecho a ser oídos, audiencias adaptadas y motivación judicial) con los principios rectores de autonomía progresiva e interés superior del niño. Asimismo, se destaca la obligación de coordinación intersectorial como herramienta esencial de protección. El análisis de género reconoce medidas concretas como la protección reforzada en contextos de violencia intrafamiliar, aunque carece de referencias normativas más específicas que lo robustezcan. La reflexión sobre desigualdades estructurales y la perspectiva interseccional es pertinente, integrando variables de edad, género y vulnerabilidad socioeconómica, y proyectando un rol activo de la representación y capacitación especializada. El lenguaje jurídico es profesional y fundamentado en la Ley N° 21.430 y en la Convención sobre los Derechos del Niño, lo que refuerza la solidez argumentativa.
A14: 19636454 | B14: 4 | C14: BRYAM ROY PARADA DURÁN | D14: PARADA | E14: DURÁN | F14: BRYAM ROY | G14: Interrupción voluntaria (no rinde EPI 2025) | S14: =SUM(K14:R14) -> 0 | T14: =S14/40 -> 0 | U14: =IF(H14="Rendida ",IF('Resultados Individuales'!T14<49.5%,"Por Mejorar",IF('Resultados Individuales'!T14<64.5%,"Base",IF('Resultados Individuales'!T14<84.5%,"Satisfactorio","Óptimo"))),"No rendida o no válida") -> No rendida o no válida
A15: 19645915 | B15: 4 | C15: LISANDRO ARTURO BUSTAMANTE DONOSO | D15: BUSTAMANTE | E15: DONOSO | F15: LISANDRO ARTURO | G15: Avance curricular suficiente o adecuado para evaluar ciclo básico | H15: No rendida | I15: no aplica | S15: =SUM(K15:R15) -> 0 | T15: =S15/40 -> 0 | U15: =IF(H15="Rendida ",IF('Resultados Individuales'!T15<49.5%,"Por Mejorar",IF('Resultados Individuales'!T15<64.5%,"Base",IF('Resultados Individuales'!T15<84.5%,"Satisfactorio","Óptimo"))),"No rendida o no válida") -> No rendida o no válida
A16: 19647397 | B16: 1 | C16: BELEN SOLANGE ARCE VALENZUELA | D16: ARCE | E16: VALENZUELA | F16: BELEN SOLANGE | G16: Avance curricular suficiente o adecuado para evaluar ciclo básico | H16: Rendida | I16: 45758 | K16: 3 | L16: 2 | M16: 2 | N16: 2 | O16: 1 | P16: 1 | Q16: 1 | R16: 2 | S16: =SUM(K16:R16) -> 14 | T16: =S16/40 -> 0.35 | U16: =IF(H16="Rendida ",IF('Resultados Individuales'!T16<49.5%,"Por Mejorar",IF('Resultados Individuales'!T16<64.5%,"Base",IF('Resultados Individuales'!T16<84.5%,"Satisfactorio","Óptimo"))),"No rendida o no válida") -> Por Mejorar | V16: El desempeño en las dos actividades evidencia un logro limitado de las competencias esperadas para el perfil intermedio de la carrera de Derecho, con importantes diferencias de nivel entre ambas. En la primera actividad, el estudiante demuestra una comprensión inicial de la institución del precario, pero incurre en confusiones conceptuales relevantes, en particular al no distinguir correctamente entre el contrato de compraventa y la relación jurídica entre la nueva dueña y la demandada. Su posicionamiento ético es pertinente, aunque superficial, y no incorpora categorías jurídicas avanzadas ni desarrolla con solidez el análisis crítico que se solicitaba. La correlación con la teoría de Finnis es básica y carece de profundidad académica. Como proyección de mejora, se sugiere profundizar los elementos copulativos del art. 2195 CC, enriquecer el análisis ético con nociones como justicia social y seguridad jurídica, y trabajar expresamente la relación con Finnis a un nivel doctrinario más consistente. Además, debe perfeccionar la presentación escrita formal para proyectar un estilo más profesional y riguroso. En la segunda actividad, las deficiencias son más graves, afectando dimensiones centrales de la evaluación. En la pregunta sobre enfoque de género, se confunden completamente conceptos, sustituyendo el análisis de género por una descripción de criterios vinculados al interés superior del niño, lo que impide cualquier reflexión significativa sobre desigualdades estructurales o interseccionalidad. Esto conlleva la omisión de aspectos críticos solicitados: no se identifican medidas específicas aplicables a mujeres, niñas y adolescentes, no se analiza cómo el proceso judicial puede reproducir o transformar desigualdades, y no se incorpora un enfoque interseccional. A ello se suman problemas severos de expresión escrita académica —frases extensas, confusas y errores ortográficos— que comprometen la claridad y calidad comunicativa. En la pregunta sobre debido proceso, no se desarrolla ningún estándar concreto, lo cual afecta gravemente el cumplimiento de la consigna. Si bien se observa la identificación de algunos elementos positivos, como la autonomía progresiva, la articulación interinstitucional y una referencia a cifras del SENAME 2016, estos son insuficientes para compensar las falencias conceptuales principales.
A17: 19829527 | B17: 2 | C17: DIEGO IGNACIO NAVARRO GUTIERREZ | D17: NAVARRO | E17: GUTIERREZ | F17: DIEGO IGNACIO | G17: Avance curricular suficiente o adecuado para evaluar ciclo básico | H17: Rendida | I17: 12.08.2025 | K17: 3 | L17: 4 | M17: 2 | N17: 3 | O17: 2 | P17: 2 | Q17: 3 | R17: 4 | S17: =SUM(K17:R17) -> 23 | T17: =S17/40 -> 0.575 | U17: =IF(H17="Rendida ",IF('Resultados Individuales'!T17<49.5%,"Por Mejorar",IF('Resultados Individuales'!T17<64.5%,"Base",IF('Resultados Individuales'!T17<84.5%,"Satisfactorio","Óptimo"))),"No rendida o no válida") -> Base | V17: El desempeño observado en las actividades muestra una base de conocimiento que permite avanzar, pero aún con importantes aspectos por mejorar para responder de manera adecuada a las competencias propias del perfil intermedio en Derecho.
A18: 19853952 | B18: K | C18: HÉCTOR MAXIMILIANO MORENO SALAZAR | D18: MORENO | E18: SALAZAR | F18: HÉCTOR MAXIMILIANO | S18: =SUM(K18:R18) -> 0 | T18: =S18/40 -> 0 | U18: =IF(H18="Rendida ",IF('Resultados Individuales'!T18<49.5%,"Por Mejorar",IF('Resultados Individuales'!T18<64.5%,"Base",IF('Resultados Individuales'!T18<84.5%,"Satisfactorio","Óptimo"))),"No rendida o no válida") -> No rendida o no válida | V18: En la primera actividad, se aprecia un esfuerzo por abordar la institución del precario, pero el análisis resulta incompleto y poco preciso. La argumentación carece de una línea lógica clara y no logra sostener conclusiones sólidas. Es necesario trabajar en la correcta identificación de los elementos normativos y en la estructuración del razonamiento jurídico, de modo que las ideas se presenten con mayor coherencia y claridad. Además, los problemas de redacción y ortografía afectan la presentación formal del trabajo y deben ser revisados cuidadosamente.
A19: 19903160 | B19: 0 | C19: POULETTE CONSTANZA FUENTEALBA GONZALEZ | D19: FUENTEALBA | E19: GONZALEZ | F19: POULETTE CONSTANZA | G19: Avance curricular suficiente o adecuado para evaluar ciclo básico | H19: No rendida | I19: no aplica | S19: =SUM(K19:R19) -> 0 | T19: =S19/40 -> 0 | U19: =IF(H19="Rendida ",IF('Resultados Individuales'!T19<49.5%,"Por Mejorar",IF('Resultados Individuales'!T19<64.5%,"Base",IF('Resultados Individuales'!T19<84.5%,"Satisfactorio","Óptimo"))),"No rendida o no válida") -> No rendida o no válida | V19: En la segunda actividad, se reconocen avances en la identificación de principios relevantes, como el derecho a ser oído de los NNA y la obligación de fundamentación judicial. Sin embargo, el análisis tiende a ser descriptivo y no logra alcanzar un nivel crítico ni de profundización. La perspectiva de género se incorpora de manera superficial y el uso de la terminología jurídica presenta imprecisiones que limitan la calidad del escrito. También se echa en falta una mayor referencia a medidas normativas concretas y a la forma en que estas buscan abordar desigualdades estructurales.
A20: 19954513 | B20: 2 | C20: EMILIA ELIZABETH JORQUERA CUEVAS | D20: JORQUERA | E20: CUEVAS | F20: EMILIA ELIZABETH | G20: Avance curricular suficiente o adecuado para evaluar ciclo básico | H20: No rendida | I20: no aplica | S20: =SUM(K20:R20) -> 0 | T20: =S20/40 -> 0 | U20: =IF(H20="Rendida ",IF('Resultados Individuales'!T20<49.5%,"Por Mejorar",IF('Resultados Individuales'!T20<64.5%,"Base",IF('Resultados Individuales'!T20<84.5%,"Satisfactorio","Óptimo"))),"No rendida o no válida") -> No rendida o no válida | V20: En términos generales, se recomienda fortalecer la argumentación jurídica, mejorar la precisión conceptual y trabajar en la claridad de la expresión escrita. Avanzar en estos aspectos permitirá que el desempeño sea más consistente y cercano a lo esperado en esta etapa de la formación.
A21: 20244309 | B21: 5 | C21: CONSTANZA JAVIERA MUÑOZ ADASME | D21: MUÑOZ | E21: ADASME | F21: CONSTANZA JAVIERA | G21: Avance curricular suficiente o adecuado para evaluar ciclo básico | H21: No rendida | I21: no aplica | S21: =SUM(K21:R21) -> 0 | T21: =S21/40 -> 0 | U21: =IF(H21="Rendida ",IF('Resultados Individuales'!T21<49.5%,"Por Mejorar",IF('Resultados Individuales'!T21<64.5%,"Base",IF('Resultados Individuales'!T21<84.5%,"Satisfactorio","Óptimo"))),"No rendida o no válida") -> No rendida o no válida
A22: 20391016 | B22: 9 | C22: DIEGO IGNACIO CORADA JULIO | D22: CORADA | E22: JULIO | F22: DIEGO IGNACIO | G22: Avance curricular suficiente o adecuado para evaluar ciclo básico | H22: Rendida | I22: 45758 | K22: 4 | L22: 3 | M22: 3 | N22: 4 | O22: 2 | P22: 3 | Q22: 2 | R22: 3 | S22: =SUM(K22:R22) -> 24 | T22: =S22/40 -> 0.6 | U22: =IF(H22="Rendida ",IF('Resultados Individuales'!T22<49.5%,"Por Mejorar",IF('Resultados Individuales'!T22<64.5%,"Base",IF('Resultados Individuales'!T22<84.5%,"Satisfactorio","Óptimo"))),"No rendida o no válida") -> Base | V22: El desempeño en ambas actividades refleja un manejo sólido de las competencias del perfil intermedio de Derecho, con un estilo argumentativo técnico y organizado, aunque aún con oportunidades de profundización normativa y de análisis crítico. En la primera actividad, se destaca un análisis sistemático y riguroso de la institución del precario: el estudiante desarrolla con claridad los tres requisitos del art. 2195 del Código Civil, incorporando una fundamentación técnica sobresaliente y un análisis fáctico detallado. Su posicionamiento ético es equilibrado, ya que contrasta los aspectos positivos y negativos de la sentencia, integrando adecuadamente nociones como la seguridad jurídica, aunque podría enriquecerse mediante el uso de categorías más específicas solicitadas en la pauta. La correlación con la teoría de Finnis es correcta al reconocer la centralidad del matrimonio como bien humano básico, pero requiere un mayor desarrollo académico de los elementos constitutivos (fides y procreación). El lenguaje jurídico es técnico, preciso y proyecta adecuada competencia profesional. La calidad formal es consistente, con errores de redacción menores que no afectan la claridad global del trabajo. En la segunda actividad, el estudiante identifica con precisión los principales mecanismos de participación de los NNA —audiencias adaptadas, obligación de fundamentar y la figura del curador ad litem—, vinculándolos de forma adecuada con la autonomía progresiva. La reflexión sobre desigualdades estructurales es correcta, destacando la reforma de los códigos civil y procesal y la incorporación explícita del interés superior del niño, junto con un lenguaje apropiado que integra tanto nociones procesales como constitucionales. No obstante, el análisis del enfoque de género carece de mayor profundidad normativa e interseccional: las referencias se limitan a menciones generales sobre corresponsabilidad parental sin desarrollarse en conexión con marcos internacionales ni con ejemplos específicos de medidas reforzadas.
A23: 20510143 | B23: 8 | C23: DIEGO BENJAMÍN ROJAS FLORES | D23: ROJAS | E23: FLORES | F23: DIEGO BENJAMÍN | G23: Avance curricular suficiente o adecuado para evaluar ciclo básico | H23: No aplica | I23: 45758 | J23: No aplica | S23: =SUM(K23:R23) -> 0 | T23: =S23/40 -> 0 | U23: =IF(H23="Rendida ",IF('Resultados Individuales'!T23<49.5%,"Por Mejorar",IF('Resultados Individuales'!T23<64.5%,"Base",IF('Resultados Individuales'!T23<84.5%,"Satisfactorio","Óptimo"))),"No rendida o no válida") -> No rendida o no válida
A24: 20550155 | B24: K | C24: JOSEFA MICHELLE JIMENEZ AROS | D24: JIMENEZ | E24: AROS | F24: JOSEFA MICHELLE | G24: Avance curricular suficiente o adecuado para evaluar ciclo básico | H24: Rendida | I24: 45758 | K24: 3 | L24: 3 | M24: 3 | N24: 3 | O24: 3 | P24: 4 | Q24: 3 | R24: 4 | S24: =SUM(K24:R24) -> 26 | T24: =S24/40 -> 0.65 | U24: =IF(H24="Rendida ",IF('Resultados Individuales'!T24<49.5%,"Por Mejorar",IF('Resultados Individuales'!T24<64.5%,"Base",IF('Resultados Individuales'!T24<84.5%,"Satisfactorio","Óptimo"))),"No rendida o no válida") -> Satisfactorio | V24: El desempeño en ambas actividades refleja un nivel competente y bien encaminado hacia la consolidación del perfil intermedio en Derecho, con un manejo adecuado del análisis normativo y ético, así como del lenguaje jurídico, aunque aún con oportunidades de profundización conceptual y técnica. En la primera actividad, el estudiante adopta posturas claras y consistentes frente a todas las preguntas, demostrando comprensión sólida de los elementos del precario al citar expresamente el art. 2195 del Código Civil. Se aprecia, además, un enfoque integral que incorpora consideraciones de género, derechos del niño y referencias normativas internacionales, como el Pacto de San José. Su análisis ético es apropiado, reconociendo aspectos de justicia social y estableciendo conexiones correctas entre la filosofía de Finnis y el razonamiento del tribunal en torno a los fines esenciales del matrimonio. El uso del lenguaje jurídico es adecuado y la calidad formal aceptable. Las áreas de mejora se concentran en profundizar el desarrollo técnico del análisis jurídico, incorporando explícitamente conceptos como interpretación extensiva, analogía y seguridad jurídica, así como en perfeccionar el uso de ciertas expresiones técnicas para proyectar un estilo más riguroso y sofisticado. En la segunda actividad, se observa un desempeño particularmente sólido en la dimensión social y contextual, destacando el análisis profundo de fenómenos relevantes (como la crisis del SENAME) y su conexión con la necesidad de reforma en materia de niñez y adolescencia. Se identifican medidas concretas con enfoque de género y se vinculan con tratados internacionales, lo que evidencia un manejo consciente de los estándares de derechos humanos. Asimismo, la reflexión interseccional es consistente, aunque podría ampliarse mediante la incorporación de más categorías sociales —como etnia o discapacidad— para alcanzar una mirada más completa. El uso del lenguaje jurídico es riguroso y proyecta un enfoque profesional claro.
A25: 20602647 | B25: 2 | C25: NATALIA ALEJANDRA ARAYA GARCÍA | D25: ARAYA | E25: GARCÍA | F25: NATALIA ALEJANDRA | S25: =SUM(K25:R25) -> 0 | T25: =S25/40 -> 0 | U25: =IF(H25="Rendida ",IF('Resultados Individuales'!T25<49.5%,"Por Mejorar",IF('Resultados Individuales'!T25<64.5%,"Base",IF('Resultados Individuales'!T25<84.5%,"Satisfactorio","Óptimo"))),"No rendida o no válida") -> No rendida o no válida
A26: 20678732 | B26: 5 | C26: RENATA LOBOS VILLANUEVA | D26: LOBOS | E26: VILLANUEVA | F26: RENATA | G26: Avance curricular suficiente o adecuado para evaluar ciclo básico | H26: No rendida | I26: no aplica | S26: =SUM(K26:R26) -> 0 | T26: =S26/40 -> 0 | U26: =IF(H26="Rendida ",IF('Resultados Individuales'!T26<49.5%,"Por Mejorar",IF('Resultados Individuales'!T26<64.5%,"Base",IF('Resultados Individuales'!T26<84.5%,"Satisfactorio","Óptimo"))),"No rendida o no válida") -> No rendida o no válida
A27: 20746309 | B27: 4 | C27: FELIPE IGNACIO NILO GUERRA | D27: NILO | E27: GUERRA | F27: FELIPE IGNACIO | G27: Avance curricular suficiente o adecuado para evaluar ciclo básico | H27: Rendida | I27: 45758 | K27: 3 | L27: 3 | M27: 3 | N27: 3 | O27: 1 | P27: 1 | Q27: 2 | R27: 3 | S27: =SUM(K27:R27) -> 19 | T27: =S27/40 -> 0.475 | U27: =IF(H27="Rendida ",IF('Resultados Individuales'!T27<49.5%,"Por Mejorar",IF('Resultados Individuales'!T27<64.5%,"Base",IF('Resultados Individuales'!T27<84.5%,"Satisfactorio","Óptimo"))),"No rendida o no válida") -> Por Mejorar | V27: El trabajo evidencia un desempeño heterogéneo entre las dos actividades, mostrando logros relevantes en el análisis del precario en la primera actividad, pero deficiencias críticas en la segunda, lo que refleja un nivel irregular frente a las competencias esperadas para el perfil intermedio de Derecho. En la primera actividad, el estudiante adopta posiciones claras y fundamentadas en todas las respuestas, identificando correctamente los tres requisitos copulativos del precario y argumentando de manera pertinente que entre demandante y demandada no existe vínculo jurídico, configurándose así el tercer requisito. El posicionamiento ético es coherente, valorando la protección familiar desde la dimensión constitucional (art. 1° inc. 2° de la Constitución) y reconociendo la importancia de la protección de Jeannette como usuaria del bien familiar. Se identifican apropiadamente las conexiones entre Finnis y el tribunal en torno al matrimonio como bien humano básico, relacionándolo de manera correcta con la protección constitucional. El lenguaje jurídico es básico pero adecuado, utilizando terminología pertinente y manteniendo una estructura clara con buena presentación formal. No obstante, las áreas de mejora se concentran en la falta de cita expresa del art. 2195 CC, la ausencia de desarrollo técnico más profundo de los conceptos, y en no haber incorporado nociones avanzadas solicitadas como interpretación extensiva, analogía y seguridad jurídica en el análisis ético-crítico, lo que limita el nivel de sofisticación conceptual del trabajo. En la segunda actividad, en cambio, se evidencian serias deficiencias en la comprensión del enfoque de género solicitado. La principal debilidad radica en la confusión conceptual entre el enfoque intersectorial (coordinación de organismos) y el enfoque de género (análisis de desigualdades estructurales que afectan a mujeres, niñas y adolescentes). Esta confusión impide un desarrollo adecuado de la reflexión, dejando sin abordar las desigualdades estructurales, sin incorporar perspectiva interseccional y con un análisis extremadamente limitado. Aunque el lenguaje jurídico empleado es básico pero apropiado, la brevedad y superficialidad de la respuesta reflejan una preparación insuficiente para el nivel de análisis crítico requerido en este tramo de la carrera.
A28: 20773727 | B28: 5 | C28: ALEJANDRA VICTORIA SANCHEZ JORQUERA | D28: SANCHEZ | E28: JORQUERA | F28: ALEJANDRA VICTORIA | G28: Avance curricular suficiente o adecuado para evaluar ciclo básico | H28: Rendida | I28: 45758 | K28: 3 | L28: 3 | M28: 3 | N28: 2 | O28: 1 | P28: 2 | Q28: 1 | R28: 3 | S28: =SUM(K28:R28) -> 18 | T28: =S28/40 -> 0.45 | U28: =IF(H28="Rendida ",IF('Resultados Individuales'!T28<49.5%,"Por Mejorar",IF('Resultados Individuales'!T28<64.5%,"Base",IF('Resultados Individuales'!T28<84.5%,"Satisfactorio","Óptimo"))),"No rendida o no válida") -> Por Mejorar | V28: El desempeño en las dos actividades presenta avances en la identificación de las instituciones jurídicas trabajadas, pero también limitaciones relevantes que dificultan un resultado sólido y consistente con el perfil intermedio de Derecho. En la primera actividad, el estudiante logra identificar correctamente los elementos básicos del precario, haciendo referencia apropiada al art. 2195 del Código Civil, y establece una conexión pertinente entre la filosofía de Finnis y el razonamiento del tribunal sobre los fundamentos del matrimonio. Además, su posicionamiento ético reconoce la complejidad del caso, diferenciando actuaciones de buena y mala fe. Sin embargo, se observan problemas conceptuales relevantes: la respuesta confunde la configuración con la procedencia del precario, llegando a argumentaciones contradictorias al reconocer derechos derivados del matrimonio pero al mismo tiempo concluir que procedería el precario. El análisis ético se mantiene en un nivel superficial, pues no incorpora los conceptos técnicos solicitados (como seguridad jurídica, analogía o interpretación extensiva). A esto se suman deficiencias en la precisión del lenguaje jurídico, con errores terminológicos, así como fallas en ortografía y redacción que restan formalidad y afectan la proyección profesional del texto. En la segunda actividad, el estudiante describe de manera adecuada los principales mecanismos de participación de los NNA (derecho a ser oído, audiencias adaptadas, fundamentación judicial y coordinación intersectorial), vinculándolos correctamente con principios como el interés superior del niño y la autonomía progresiva. No obstante, la respuesta omite por completo el análisis del enfoque de género y de la perspectiva interseccional, lo que limita el desarrollo crítico esperado. El tratamiento uniforme hacia los NNA invisibiliza desigualdades estructurales que afectan de manera diferenciada a niñas, adolescentes y mujeres. Asimismo, si bien el lenguaje jurídico es adecuado, la fundamentación se presenta incompleta al no recurrir a normas específicas ni a tratados internacionales. La incorporación de referencias expresas a la Ley 21.430, a la Convención sobre los Derechos del Niño y a artículos pertinentes del Código Civil y del Código de Procedimiento Civil habría robustecido de manera sustantiva la argumentación.
A29: 20778801 | B29: 5 | C29: FERNANDO ANDRÉS VERGARA BAEZA | D29: VERGARA | E29: BAEZA | F29: FERNANDO ANDRÉS | G29: Avance curricular suficiente o adecuado para evaluar ciclo básico | H29: Rendida | I29: 45758 | K29: 4 | L29: 4 | M29: 4 | N29: 4 | O29: 3 | P29: 3 | Q29: 2 | R29: 4 | S29: =SUM(K29:R29) -> 28 | T29: =S29/40 -> 0.7 | U29: =IF(H29="Rendida ",IF('Resultados Individuales'!T29<49.5%,"Por Mejorar",IF('Resultados Individuales'!T29<64.5%,"Base",IF('Resultados Individuales'!T29<84.5%,"Satisfactorio","Óptimo"))),"No rendida o no válida") -> Satisfactorio | V29: El trabajo presentado evidencia un nivel de excelencia en el manejo de las competencias del perfil intermedio de Derecho, con una sólida integración entre argumentación jurídica, análisis ético y reflexión social. En la primera actividad, el estudiante evalúa de manera sistemática todos los elementos del art. 2195 del Código Civil, construyendo una argumentación estructurada y pertinente sobre la procedencia del precario, en atención a la extinción del vínculo jurídico tras la compraventa del inmueble. Se aprecia una adecuada integración de nociones éticas, de justicia social y de garantías jurídicas, logrando una valoración equilibrada de la interpretación del tribunal. Destaca la profundidad con que se establece la conexión entre la filosofía de Finnis y el razonamiento judicial, lo que potencia el carácter académico de la reflexión. El uso del lenguaje jurídico es riguroso, preciso y profesional, y la expresión escrita resulta impecable, evidenciando claridad, coherencia y un estilo formal adecuado. Todo ello refleja un desempeño sobresaliente en el desarrollo de competencias analítico-jurídicas y de proyección profesional. En la segunda actividad, el estudiante describe con precisión los mecanismos de participación de NNA —audiencias adaptadas y obligación de fundamentar la consideración de su opinión—, articulándolos correctamente con los principios de autonomía progresiva e interés superior del niño. El análisis de género es pertinente, al destacar la protección reforzada en contextos de violencia intrafamiliar, junto con la importancia de la capacitación de operadores jurídicos y la coordinación intersectorial para abordar desigualdades. La reflexión sobre desigualdades estructurales es consistente, poniendo énfasis en el valor transformador de la motivación judicial y la efectiva ponderación de la voz de niños y adolescentes. Asimismo, aunque la perspectiva interseccional integra de manera correcta variables como edad y género, se recomienda ampliar este análisis incorporando otras categorías sociales, como clase, etnia o discapacidad, para robustecer la reflexión crítica. El lenguaje jurídico es riguroso, técnicamente fundamentado y apoyado en la Ley N° 21.430 y en estándares del debido proceso, lo que evidencia un claro nivel profesional.
A30: 20801460 | B30: 9 | C30: BENJAMÍN ENRIQUE JORQUERA LAGUNAS | D30: JORQUERA | E30: LAGUNAS | F30: BENJAMÍN ENRIQUE | G30: Avance curricular insuficiente para evaluar ciclo básico (no rinde EPI 2025) | H30: No aplica | I30: no aplica | S30: =SUM(K30:R30) -> 0 | T30: =S30/40 -> 0 | U30: =IF(H30="Rendida ",IF('Resultados Individuales'!T30<49.5%,"Por Mejorar",IF('Resultados Individuales'!T30<64.5%,"Base",IF('Resultados Individuales'!T30<84.5%,"Satisfactorio","Óptimo"))),"No rendida o no válida") -> No rendida o no válida
A31: 20824342 | B31: K | C31: JAVIERA BELÉN SÁNCHEZ PINILLA | D31: SÁNCHEZ | E31: PINILLA | F31: JAVIERA BELÉN | G31: Avance curricular suficiente o adecuado para evaluar ciclo básico | H31: No rendida | I31: no aplica | S31: =SUM(K31:R31) -> 0 | T31: =S31/40 -> 0 | U31: =IF(H31="Rendida ",IF('Resultados Individuales'!T31<49.5%,"Por Mejorar",IF('Resultados Individuales'!T31<64.5%,"Base",IF('Resultados Individuales'!T31<84.5%,"Satisfactorio","Óptimo"))),"No rendida o no válida") -> No rendida o no válida
A32: 20837817 | B32: 1 | C32: JAVIERA CAMILA AGUAYO OJEDA | D32: AGUAYO | E32: OJEDA | F32: JAVIERA CAMILA | G32: Avance curricular suficiente o adecuado para evaluar ciclo básico | H32: No rendida | I32: no aplica | S32: =SUM(K32:R32) -> 0 | T32: =S32/40 -> 0 | U32: =IF(H32="Rendida ",IF('Resultados Individuales'!T32<49.5%,"Por Mejorar",IF('Resultados Individuales'!T32<64.5%,"Base",IF('Resultados Individuales'!T32<84.5%,"Satisfactorio","Óptimo"))),"No rendida o no válida") -> No rendida o no válida
A33: 20844575 | B33: 8 | C33: MATÍAS IGNACIO FUENTES ÁVILA | D33: FUENTES | E33: ÁVILA | F33: MATÍAS IGNACIO | G33: Avance curricular suficiente o adecuado para evaluar ciclo básico | H33: Rendida | I33: 45882 | K33: 2 | L33: 2 | M33: 3 | N33: 2 | O33: 2 | P33: 3 | Q33: 2 | R33: 3 | S33: =SUM(K33:R33) -> 19 | T33: =S33/40 -> 0.475 | U33: =IF(H33="Rendida ",IF('Resultados Individuales'!T33<49.5%,"Por Mejorar",IF('Resultados Individuales'!T33<64.5%,"Base",IF('Resultados Individuales'!T33<84.5%,"Satisfactorio","Óptimo"))),"No rendida o no válida") -> Por Mejorar | V33: El desempeño evidenciado en las actividades refleja un progreso parcial, pero aún insuficiente para responder plenamente a las competencias del perfil intermedio en Derecho. Si bien se reconocen esfuerzos por abordar los contenidos, el trabajo requiere una mejora significativa en distintos planos.
A34: 20845895 | B34: 7 | C34: THIARE ISABEL LARA TRANGO | D34: LARA | E34: TRANGO | F34: THIARE ISABEL | G34: Avance curricular suficiente o adecuado para evaluar ciclo básico | H34: Rendida | I34: 45758 | K34: 3 | L34: 3 | M34: 4 | N34: 3 | O34: 1 | P34: 2 | Q34: 1 | R34: 3 | S34: =SUM(K34:R34) -> 20 | T34: =S34/40 -> 0.5 | U34: =IF(H34="Rendida ",IF('Resultados Individuales'!T34<49.5%,"Por Mejorar",IF('Resultados Individuales'!T34<64.5%,"Base",IF('Resultados Individuales'!T34<84.5%,"Satisfactorio","Óptimo"))),"No rendida o no válida") -> Base | V34: En la primera actividad, el análisis presentado carece de profundidad y se limita a enunciar aspectos generales sin llegar a un desarrollo técnico suficiente. La utilización de fuentes normativas resulta escasa y poco precisa, lo que afecta la solidez de la argumentación. Además, la falta de ejemplos o referencias jurisprudenciales debilita la capacidad de aplicar el conocimiento a situaciones concretas. A esto se suma la necesidad de trabajar en la organización del texto, ya que la exposición de ideas se percibe fragmentada y dificulta la comprensión.
A35: 20881046 | B35: 4 | C35: CHRISTOPHER CARLOS MANUEL OLIVERA JESÚS | D35: OLIVERA | E35: JESÚS | F35: CHRISTOPHER CARLOS MANUEL | G35: Avance curricular suficiente o adecuado para evaluar ciclo básico | H35: Rendida | I35: 45758 | K35: 4 | L35: 4 | M35: 4 | N35: 4 | O35: 4 | P35: 4 | Q35: 4 | R35: 4 | S35: =SUM(K35:R35) -> 32 | T35: =S35/40 -> 0.8 | U35: =IF(H35="Rendida ",IF('Resultados Individuales'!T35<49.5%,"Por Mejorar",IF('Resultados Individuales'!T35<64.5%,"Base",IF('Resultados Individuales'!T35<84.5%,"Satisfactorio","Óptimo"))),"No rendida o no válida") -> Satisfactorio | V35: En la segunda actividad, si bien se observa la intención de vincular el proyecto con principios jurídicos relevantes, el tratamiento de estos temas es superficial y no alcanza a proyectarse hacia un análisis crítico. El estudiante debe avanzar en el uso más riguroso de la terminología jurídica y en la diferenciación conceptual entre nociones cercanas, evitando confusiones que afectan el rigor académico. Igualmente, se recomienda profundizar en la perspectiva de género y en cómo las medidas normativas buscan corregir desigualdades estructurales, aspecto que en este caso aparece solo de manera enunciativa.
A36: 20946748 | B36: 8 | C36: FERNANDA JAVIERA ESCOBAR CONTRERAS | D36: ESCOBAR | E36: CONTRERAS | F36: FERNANDA JAVIERA | G36: Avance curricular suficiente o adecuado para evaluar ciclo básico | H36: No rendida | I36: no aplica | S36: =SUM(K36:R36) -> 0 | T36: =S36/40 -> 0 | U36: =IF(H36="Rendida ",IF('Resultados Individuales'!T36<49.5%,"Por Mejorar",IF('Resultados Individuales'!T36<64.5%,"Base",IF('Resultados Individuales'!T36<84.5%,"Satisfactorio","Óptimo"))),"No rendida o no válida") -> No rendida o no válida | V36: De manera general, se sugiere trabajar en la precisión del lenguaje, en el fortalecimiento de la argumentación mediante fundamentos normativos y doctrinarios, y en la capacidad de articular un análisis crítico y aplicado, que supere el nivel descriptivo y responda a las exigencias propias del estudio del Derecho
A37: 20965094 | B37: 0 | C37: JOSÉ DOMINGO BLANCO CASABONA | D37: BLANCO | E37: CASABONA | F37: JOSÉ DOMINGO | G37: Avance curricular suficiente o adecuado para evaluar ciclo básico | H37: Rendida | I37: 45758 | K37: 3 | L37: 3 | M37: 4 | N37: 3 | O37: 2 | P37: 2 | Q37: 2 | R37: 2 | S37: =SUM(K37:R37) -> 21 | T37: =S37/40 -> 0.525 | U37: =IF(H37="Rendida ",IF('Resultados Individuales'!T37<49.5%,"Por Mejorar",IF('Resultados Individuales'!T37<64.5%,"Base",IF('Resultados Individuales'!T37<84.5%,"Satisfactorio","Óptimo"))),"No rendida o no válida") -> Base | V37: El desempeño del estudiante en ambas actividades evidencia buen manejo conceptual y la capacidad de formular argumentos jurídicos pertinentes, aunque con diferencias de solidez entre la primera y la segunda actividad. En la primera actividad, se aprecia un dominio correcto de la institución del precario, desarrollando de manera sistemática los tres requisitos del art. 2195 CC y articulando coherentemente la argumentación respecto de su procedencia. El análisis ético es pertinente, con reflexiones interesantes acerca de la evolución del matrimonio como institución social, aunque podría enriquecerse con categorías jurídicas más específicas como seguridad jurídica o correcta aplicación del derecho. Destaca positivamente la correlación con Finnis, la cual se presenta con profundidad académica, al desarrollar los elementos constitutivos del matrimonio (fides y procreación) y proyectarlos en el considerando judicial. El uso del lenguaje jurídico es adecuado y emplea terminología técnica suficiente. No obstante, se recomienda perfeccionar la cita normativa (mención expresa del art. 2195 CC), mantener un registro formal más uniforme y atender a pequeños errores tipográficos que afectan la pulcritud formal del texto. En la segunda actividad, el análisis muestra avances en la identificación de elementos centrales del proyecto de ley, como el derecho a ser oído y la participación activa de los NNA, estableciendo vínculos con fenómenos sociales relevantes como los abusos en el sistema de protección infantil y el impacto del estallido social. También se reconoce un enfoque creativo al relacionar las “circunstancias particulares” con la necesidad de un análisis de género, lo que refleja capacidad crítica. Sin embargo, se evidencian limitaciones importantes: las respuestas son breves, el lenguaje utilizado se acerca a lo coloquial en lugar de mantener precisión técnica, se omite el desarrollo de nociones claves como la autonomía progresiva, y la perspectiva interseccional se aborda superficialmente. Esto reduce la solidez del trabajo a nivel normativo y crítico. Para mejorar, se sugiere fortalecer el uso del lenguaje jurídico especializado, ampliar el desarrollo analítico hasta cubrir la extensión exigida, integrar de manera más sistemática marcos teóricos como la interseccionalidad, e incorporar explicaciones apoyadas en la Ley N° 21.430, la Convención sobre los Derechos del Niño y marcos normativos conexos.
A38: 20972461 | B38: 8 | C38: PAULA FABIANA VILLEGAS RIQUELME | D38: VILLEGAS | E38: RIQUELME | F38: PAULA FABIANA | G38: Avance curricular suficiente o adecuado para evaluar ciclo básico | H38: Rendida | I38: 45758 | K38: 4 | L38: 3 | M38: 3 | N38: 4 | O38: 2 | P38: 2 | Q38: 2 | R38: 3 | S38: =SUM(K38:R38) -> 23 | T38: =S38/40 -> 0.575 | U38: =IF(H38="Rendida ",IF('Resultados Individuales'!T38<49.5%,"Por Mejorar",IF('Resultados Individuales'!T38<64.5%,"Base",IF('Resultados Individuales'!T38<84.5%,"Satisfactorio","Óptimo"))),"No rendida o no válida") -> Base | V38: El desempeño en ambas actividades refleja un avance consistente en el manejo de análisis jurídico y en la construcción de argumentos, destacando mayor solidez en la primera actividad que en la segunda. En la primera actividad, la estudiante demuestra un análisis jurídico sólido y bien estructurado, caracterizado por la precisión técnica y la claridad argumentativa. La evaluación de los elementos del precario se desarrolla de forma sistemática y convincente, particularmente al identificar la insuficiencia de supuestos no probados como fundamento para rechazar la acción. Se observa un dominio claro del lenguaje jurídico técnico y la capacidad de integrar consideraciones tanto procesales como sustantivas. Asimismo, la crítica a la decisión del tribunal se encuentra bien fundamentada, al incorporar instituciones relevantes como la del bien familiar. La relación establecida entre Finnis y el considerando judicial es correcta y pertinente, aunque podría haber alcanzado mayor desarrollo desde la perspectiva filosófica. En lo formal, la expresión escrita destaca por su claridad, orden y precisión, proyectando las competencias esperadas para el perfil intermedio con un desempeño claramente sobresaliente. En la segunda actividad, la estudiante identifica adecuadamente los mecanismos de participación de los NNA —derecho a ser oído en audiencias adaptadas y obligación de fundamentar su opinión— vinculándolos tanto al interés superior como a la autonomía progresiva. No obstante, el análisis de género resulta superficial, al no especificar medidas normativas concretas ni aludir a estándares internacionales relevantes. De igual manera, la reflexión sobre desigualdades estructurales y la perspectiva interseccional se presentan limitadas, reducidas a referencias de articulación interinstitucional, sin un análisis profundo sobre la interacción de variables sociales como género, clase, etnia o situación socioeconómica. El uso del lenguaje jurídico es correcto y pertinente, aunque el rigor del argumento se vería reforzado con citas expresas a artículos de la Ley 21.430, la Convención sobre los Derechos del Niño o el Código de Procedimiento Civil.
