Workbook

Sheet Rúbrica Resultados Globales
A2: A) | B2: Definiciones a nivel micro (rúbrica)
C4: Nivel de logro
C5: Óptimo | D5: Satisfactorio | E5: Base | F5: Por Mejorar | G5: No observado
C6: (4 puntos) | D6: (3 puntos) | E6: (2 puntos) | F6: (1 punto) | G6: (0 punto)
C7: El desempeño descrito se logra completamente | D7: El desempeño descrito se logra, sin embargo, presenta algunas imprecisiones. | E7: El desempeño descrito se logra de forma mínima | F7: El desempeño descrito se presenta de forma errónea y/o no se ajusta a lo solicitado | G7: El desempeño descrito no es observado dada la ausencia de acciones o productos
A9: B) | B9: Definiciones a nivel macro (EPI)
B10: El presente documento tiene por objetivo especificar los criterios que dan origen a las definiciones del indicador global de EPI. Entendemos que la EPI es una evaluación formativa, donde existe una diversidad de instrumentos y exigencias asociadas a ellos que responde a la especificidad de cada disciplina. Sin embargo, desde el nivel central el foco se sitúa fundamentalmente en detectar las necesidades de apoyo necesarias que requeriría el estudiantado para continuar su ciclo de profundización, y, en otro casos, para detectar los niveles de autonomía que presentan los/las estudiantes para transitar al ciclo de profundización. En este contexto, los términos utilizados la columna “Justificación” de la siguiente tabla, como; “buen nivel”, “apropiado”,” mínimo”, deben entenderse en el contexto específico y situado de cada evaluación.
C15: Categorías
C16: Óptimo | D16: Satisfactorio | E16: Base | F16: Por Mejorar
B17: Porcentajes | C17: 100%-85% | D17: 84% - 65% | E17: 64% - 50% | F17: 0% - 49%
B18: Definiciones | C18: Los resultados obtenidos por el/la estudiante en la Evaluación de Perfil Intermedio evidencian que ha logrado los aprendizajes clave del Ciclo Básico de formación que le permiten continuar con su trayectoria formativa en el Ciclo de Profundización y/ Especialización, con autonomía, avanzando en el desarrollo de los desempeños evidenciados. | D18: Los resultados obtenidos por el/la estudiante en la Evaluación de Perfil Intermedio evidencian que ha logrado los aprendizajes clave del Ciclo Básico de formación que le permiten continuar con su trayectoria formativa en el Ciclo de Profundización y/o Especialización, con autonomía. Sin embargo, se evidencian aspectos específicos y acotados en que es necesario fortalecer los desempeños. | E18: Los resultados obtenidos por el/la estudiante en la Evaluación de Perfil Intermedio evidencian que el logro de los aprendizajes clave del Ciclo Básico de formación se cumplen de manera mínimay requieren ser fortalecidos durante el Ciclo de Profundización y/o Especialización, para apoyar la continuidad de la trayectoria formativa. | F18: Los resultados obtenidos por el/la estudiante en la Evaluación de Perfil Intermedio evidencian que no se han logrado los aprendizajes clave del Ciclo Básico de formación , requiriendo de acciones de apoyo en el Ciclo de Profundización y/o Especialización que favorezcan el desarrollo de los desempeños evaluados y aseguren la continuidad de la trayectoria formativa. | H18: El/la estudiante en la Evaluación de Perfil Intermedio no presenta respuestas, lo que no permite evidenciar el logro de los aprendizajes clave del Ciclo Básico de formación.
C19: El/la estudiante avanza con autonomía al Ciclo de Profundización y/o Especialización. Cuenta con desempeños relevantes para la continuidad de su trayectoria formativa | E19: El/la estudiante avanza al Ciclo de Profundización y/o Especialización con apoyos adicionales para desarrollar los aprendizajes prioritarios que permiten dar continuidad a su trayectoria formativa
C20: Acciones de fortalecimiento de las trayectorias formativas
B21: Justificación | C21: Dado el carácter formativo de esta evaluación, se define este nivel a partir del 85% ya que a partir de este porcentaje se evidencia con claridad un buen nivel de conocimientos teórico-disciplinares de los contenidos, así como un muy buen manejo metodológico/práctico de estos, sin necesitar apoyos especificos. | D21: Dado el carácter formativo de esta evaluación, se define este nivel a partir del 65% y no del 70% en función del criterio de la autonomía para poder continuar hacia el ciclo de profundización, siendo el 65% un nivel de solidez suficiente para aquello, demostrando un conocimiento apropiado de los conocimientos teórico-disciplinares y un manejo apropiado metodológico/práctico de estos. Esto también obedece a la diversidad de EPIs existentes y a los distintos niveles de exigencia de los distintos instrumentos. | E21: Dado el carácter formativo de la evaluación, se define este nivel a partir del 50% ya que el/la estudiante demuestra un conocimiento/manejo básico de los contenidos/habilidades esenciales, sin embargo el nivel de profundidad de este manejo es superficial/parcial/insuficiente. logrando solo a mitad del puntaje. El nivel de profundidad de los aprendizajes logrados y la consecuente necesidad de apoyos predominan para definir los porcentajes de logro de este nivel. | F21: Dado el carácter formativo de la evaluación, se define este nivel como porcentajes de logro menores al 50%, ya que el/la estudiante no alcanza un mínimo de conocimiento ni manejo de contenidos y habilidades esperadas, evidenciando la necesidad de apoyos para poder transitar al ciclo de profundización.

Sheet Rúbrica situación evaluativa 

Sheet Resultados Individuales
A1: DATOS DE ESTUDIANTES DE LA COHORTE | K1: Actividad problema 1 No observado: 0 puntos Insatisfactorio: 1 punto Bajo: 2 puntos Medio : 3 puntos Satisfactorio: 4 puntos | Q1: Resultado General por estudiante
A3: RUT ESTUDIANTE | B3: DV | C3: NOMBRE COMPLETO | D3: PRIMER APELLIDO (Apellido paterno) | E3: SEGUNDO APELLIDO (Apellido materno) | F3: NOMBRES | G3: ESTADO DE HABILITACIÓN PARA RENDIR | H3: ESTATUS DE RENDICIÓN | I3: FECHA DE RENDICIÓN | J3: JUSTIFICACIÓN DE NO RENDICIÓN | K3: Enfoques teórico-conceptuales de la antropología y su relación con una experiencia de trabajo etnográfico específico. | L3: Elementos fundamentales de la historia y el pensamiento latinoamericano para comprender un problema de investigación específico. | M3: Fundamentos y estrategias de las metodologías cualitativas y la etnografía para formular proyectos de investigación antropológica. | N3: Herramientas introductorias del trabajo etnográfico, incorporando el diseño, implementación y reporte escrito (análisis). | O3: Especificidades disciplinares de la antropología y su relación con otras disciplinas de las ciencias humanas. | P3: Aspectos formales asociados al ensayo | Q3: PUNTAJE TOTAL ESTUDIANTE | R3: PORCENTAJE DE LOGRO | S3: CATEGORÍA RESULTADO GLOBAL ESTUDIANTE
A4: 18829107 | B4: 4 | C4: CATALINA REBECA IBÁÑEZ REYES | D4: IBÁÑEZ | E4: REYES | F4: CATALINA REBECA | G4: Interrupción voluntaria (no rinde EPI 2025) | H4: No aplica | J4: No aplica | Q4: =SUM(K4:P4) -> 0 | R4: =Q4/24 -> 0 | S4: =IF(H4="Rendida ",IF('Resultados Individuales'!R4<49.5%,"Por Mejorar",IF('Resultados Individuales'!R4<64.5%,"Base",IF('Resultados Individuales'!R4<84.5%,"Satisfactorio","Óptimo"))),"No rendida o no válida") -> No rendida o no válida
A5: 19959162 | B5: 2 | C5: IGNACIO DONOSO CONTRERAS | D5: DONOSO | E5: CONTRERAS | F5: IGNACIO | G5: Interrupción voluntaria (no rinde EPI 2025) | H5: No aplica | J5: No aplica | Q5: =SUM(K5:P5) -> 0 | R5: =Q5/24 -> 0 | S5: =IF(H5="Rendida ",IF('Resultados Individuales'!R5<49.5%,"Por Mejorar",IF('Resultados Individuales'!R5<64.5%,"Base",IF('Resultados Individuales'!R5<84.5%,"Satisfactorio","Óptimo"))),"No rendida o no válida") -> No rendida o no válida
A6: 20290224 | B6: 3 | C6: VÍCTOR ALEXANDER ÁVALOS TAMAYO | D6: ÁVALOS | E6: TAMAYO | F6: VÍCTOR ALEXANDER | G6: Avance curricular suficiente o adecuado para evaluar ciclo básico | H6: Rendida | I6: 45749 | J6: No aplica | K6: 3 | L6: 3 | M6: 2 | N6: 3 | O6: 3 | P6: 2 | Q6: =SUM(K6:P6) -> 16 | R6: =Q6/24 -> 0.66666667 | S6: =IF(H6="Rendida ",IF('Resultados Individuales'!R6<49.5%,"Por Mejorar",IF('Resultados Individuales'!R6<64.5%,"Base",IF('Resultados Individuales'!R6<84.5%,"Satisfactorio","Óptimo"))),"No rendida o no válida") -> Satisfactorio
A7: 20317927 | B7: 8 | C7: JUAN SEBASTIAN KIESSLING KIESSLING | D7: KIESSLING | E7: KIESSLING | F7: JUAN SEBASTIAN | G7: Avance curricular suficiente o adecuado para evaluar ciclo básico | H7: Rendida | I7: 45749 | J7: No aplica | K7: 3 | L7: 3 | M7: 4 | N7: 4 | O7: 3 | P7: 3 | Q7: =SUM(K7:P7) -> 20 | R7: =Q7/24 -> 0.83333333 | S7: =IF(H7="Rendida ",IF('Resultados Individuales'!R7<49.5%,"Por Mejorar",IF('Resultados Individuales'!R7<64.5%,"Base",IF('Resultados Individuales'!R7<84.5%,"Satisfactorio","Óptimo"))),"No rendida o no válida") -> Satisfactorio
A8: 20347661 | B8: 2 | C8: JONATHAN GABRIEL MANCILLA MARTÍNEZ | D8: MANCILLA | E8: MARTÍNEZ | F8: JONATHAN GABRIEL | G8: Avance curricular suficiente o adecuado para evaluar ciclo básico | H8: Rendida | I8: 45749 | J8: No aplica | K8: 4 | L8: 4 | M8: 4 | N8: 4 | O8: 3 | P8: 4 | Q8: =SUM(K8:P8) -> 23 | R8: =Q8/24 -> 0.95833333 | S8: =IF(H8="Rendida ",IF('Resultados Individuales'!R8<49.5%,"Por Mejorar",IF('Resultados Individuales'!R8<64.5%,"Base",IF('Resultados Individuales'!R8<84.5%,"Satisfactorio","Óptimo"))),"No rendida o no válida") -> Óptimo
A9: 20455300 | B9: 9 | C9: LLACOLÉN PENÉLOPE HUINEO CABEZA | D9: HUINEO | E9: CABEZA | F9: LLACOLÉN PENÉLOPE | G9: Avance curricular suficiente o adecuado para evaluar ciclo básico | H9: Rendida | J9: No aplica | K9: 3 | L9: 3 | M9: 4 | N9: 4 | O9: 3 | P9: 2 | Q9: =SUM(K9:P9) -> 19 | R9: =Q9/24 -> 0.79166667 | S9: =IF(H9="Rendida ",IF('Resultados Individuales'!R9<49.5%,"Por Mejorar",IF('Resultados Individuales'!R9<64.5%,"Base",IF('Resultados Individuales'!R9<84.5%,"Satisfactorio","Óptimo"))),"No rendida o no válida") -> Satisfactorio
A10: 20848480 | B10: K | C10: GONZALO ANDRÉS MUÑOZ OLIVA | D10: MUÑOZ | E10: OLIVA | F10: GONZALO ANDRÉS | G10: Avance curricular suficiente o adecuado para evaluar ciclo básico | H10: Rendida | I10: 45761 | J10: No aplica | K10: 4 | L10: 3 | M10: 4 | N10: 4 | O10: 3 | P10: 4 | Q10: =SUM(K10:P10) -> 22 | R10: =Q10/24 -> 0.91666667 | S10: =IF(H10="Rendida ",IF('Resultados Individuales'!R10<49.5%,"Por Mejorar",IF('Resultados Individuales'!R10<64.5%,"Base",IF('Resultados Individuales'!R10<84.5%,"Satisfactorio","Óptimo"))),"No rendida o no válida") -> Óptimo
A11: 21007897 | B11: 5 | C11: ANTONIA MARÍA BUSTAMANTE MUÑOZ | D11: BUSTAMANTE | E11: MUÑOZ | F11: ANTONIA MARÍA | G11: Avance curricular suficiente o adecuado para evaluar ciclo básico | H11: Rendida | I11: 45749 | J11: No aplica | K11: 3 | L11: 1 | M11: 1 | N11: 1 | O11: 1 | P11: 3 | Q11: =SUM(K11:P11) -> 10 | R11: =Q11/24 -> 0.41666667 | S11: =IF(H11="Rendida ",IF('Resultados Individuales'!R11<49.5%,"Por Mejorar",IF('Resultados Individuales'!R11<64.5%,"Base",IF('Resultados Individuales'!R11<84.5%,"Satisfactorio","Óptimo"))),"No rendida o no válida") -> Por Mejorar
A12: 21027080 | B12: 9 | C12: EMIR ANDRÉS LABBÉ BARRIGA | D12: LABBÉ | E12: BARRIGA | F12: EMIR ANDRÉS | G12: Interrupción voluntaria (no rinde EPI 2025) | H12: No aplica | J12: No aplica | Q12: =SUM(K12:P12) -> 0 | R12: =Q12/24 -> 0 | S12: =IF(H12="Rendida ",IF('Resultados Individuales'!R12<49.5%,"Por Mejorar",IF('Resultados Individuales'!R12<64.5%,"Base",IF('Resultados Individuales'!R12<84.5%,"Satisfactorio","Óptimo"))),"No rendida o no válida") -> No rendida o no válida
A13: 21035501 | B13: 4 | C13: JAVIERA MARCELA DURÁN ESCUTI | D13: DURÁN | E13: ESCUTI | F13: JAVIERA MARCELA | G13: Avance curricular suficiente o adecuado para evaluar ciclo básico | H13: Rendida | I13: 45749 | J13: No aplica | K13: 3 | L13: 3 | M13: 4 | N13: 3 | O13: 4 | P13: 3 | Q13: =SUM(K13:P13) -> 20 | R13: =Q13/24 -> 0.83333333 | S13: =IF(H13="Rendida ",IF('Resultados Individuales'!R13<49.5%,"Por Mejorar",IF('Resultados Individuales'!R13<64.5%,"Base",IF('Resultados Individuales'!R13<84.5%,"Satisfactorio","Óptimo"))),"No rendida o no válida") -> Satisfactorio
A14: 21082092 | B14: 2 | C14: ANTONIA SOFÍA LEIVA VALDERRAMA | D14: LEIVA | E14: VALDERRAMA | F14: ANTONIA SOFÍA | G14: Avance curricular suficiente o adecuado para evaluar ciclo básico | H14: Rendida | I14: 45749 | J14: No aplica | K14: 4 | L14: 4 | M14: 4 | N14: 4 | O14: 3 | P14: 4 | Q14: =SUM(K14:P14) -> 23 | R14: =Q14/24 -> 0.95833333 | S14: =IF(H14="Rendida ",IF('Resultados Individuales'!R14<49.5%,"Por Mejorar",IF('Resultados Individuales'!R14<64.5%,"Base",IF('Resultados Individuales'!R14<84.5%,"Satisfactorio","Óptimo"))),"No rendida o no válida") -> Óptimo
A15: 21155880 | B15: 6 | C15: AMILCAR MARTÍN CANALA-ECHEVARRIA BELTRÁN | D15: CANALA-ECHEVARRIA | E15: BELTRÁN | F15: AMILCAR MARTÍN | G15: Avance curricular suficiente o adecuado para evaluar ciclo básico | H15: Rendida | I15: 45749 | J15: No aplica | K15: 4 | L15: 4 | M15: 4 | N15: 3 | O15: 3 | P15: 4 | Q15: =SUM(K15:P15) -> 22 | R15: =Q15/24 -> 0.91666667 | S15: =IF(H15="Rendida ",IF('Resultados Individuales'!R15<49.5%,"Por Mejorar",IF('Resultados Individuales'!R15<64.5%,"Base",IF('Resultados Individuales'!R15<84.5%,"Satisfactorio","Óptimo"))),"No rendida o no válida") -> Óptimo
A16: 21157655 | B16: 3 | C16: FRANCISCA ANTONIA PALMA ACEVEDO | D16: PALMA | E16: ACEVEDO | F16: FRANCISCA ANTONIA | G16: Avance curricular suficiente o adecuado para evaluar ciclo básico | H16: Rendida | I16: 45749 | J16: No aplica | K16: 2 | L16: 2 | M16: 4 | N16: 3 | O16: 4 | P16: 2 | Q16: =SUM(K16:P16) -> 17 | R16: =Q16/24 -> 0.70833333 | S16: =IF(H16="Rendida ",IF('Resultados Individuales'!R16<49.5%,"Por Mejorar",IF('Resultados Individuales'!R16<64.5%,"Base",IF('Resultados Individuales'!R16<84.5%,"Satisfactorio","Óptimo"))),"No rendida o no válida") -> Satisfactorio
A17: 21174863 | B17: K | C17: RICARDO IGNACIO SALAZAR BRAVO | D17: SALAZAR | E17: BRAVO | F17: RICARDO IGNACIO | G17: Avance curricular suficiente o adecuado para evaluar ciclo básico | H17: Rendida | I17: 45749 | J17: No aplica | K17: 4 | L17: 4 | M17: 4 | N17: 4 | O17: 3 | P17: 4 | Q17: =SUM(K17:P17) -> 23 | R17: =Q17/24 -> 0.95833333 | S17: =IF(H17="Rendida ",IF('Resultados Individuales'!R17<49.5%,"Por Mejorar",IF('Resultados Individuales'!R17<64.5%,"Base",IF('Resultados Individuales'!R17<84.5%,"Satisfactorio","Óptimo"))),"No rendida o no válida") -> Óptimo
A18: 21328171 | B18: 2 | C18: LUZ IGNACIA CATEJO GONZÁLEZ | D18: CATEJO | E18: GONZÁLEZ | F18: LUZ IGNACIA | G18: Avance curricular suficiente o adecuado para evaluar ciclo básico | H18: Rendida | I18: 45749 | J18: No aplica | K18: 2 | L18: 2 | M18: 1 | N18: 2 | O18: 1 | P18: 2 | Q18: =SUM(K18:P18) -> 10 | R18: =Q18/24 -> 0.41666667 | S18: =IF(H18="Rendida ",IF('Resultados Individuales'!R18<49.5%,"Por Mejorar",IF('Resultados Individuales'!R18<64.5%,"Base",IF('Resultados Individuales'!R18<84.5%,"Satisfactorio","Óptimo"))),"No rendida o no válida") -> Por Mejorar
A19: 21333607 | B19: K | C19: RAPHAEL IGNACIO CAMPOS MAYANÉS | D19: CAMPOS | E19: MAYANÉS | F19: RAPHAEL IGNACIO | G19: Avance curricular suficiente o adecuado para evaluar ciclo básico | H19: Rendida | I19: 45749 | J19: No aplica | K19: 4 | L19: 1 | M19: 2 | N19: 1 | O19: 2 | P19: 3 | Q19: =SUM(K19:P19) -> 13 | R19: =Q19/24 -> 0.54166667 | S19: =IF(H19="Rendida ",IF('Resultados Individuales'!R19<49.5%,"Por Mejorar",IF('Resultados Individuales'!R19<64.5%,"Base",IF('Resultados Individuales'!R19<84.5%,"Satisfactorio","Óptimo"))),"No rendida o no válida") -> Base
A20: 21342424 | B20: 6 | C20: CATALINA CONSTANZA CASTRO MUÑOZ | D20: CASTRO | E20: MUÑOZ | F20: CATALINA CONSTANZA | G20: Avance curricular suficiente o adecuado para evaluar ciclo básico | H20: Rendida | I20: 45749 | J20: No aplica | K20: 2 | L20: 2 | M20: 3 | N20: 3 | O20: 3 | P20: 3 | Q20: =SUM(K20:P20) -> 16 | R20: =Q20/24 -> 0.66666667 | S20: =IF(H20="Rendida ",IF('Resultados Individuales'!R20<49.5%,"Por Mejorar",IF('Resultados Individuales'!R20<64.5%,"Base",IF('Resultados Individuales'!R20<84.5%,"Satisfactorio","Óptimo"))),"No rendida o no válida") -> Satisfactorio
A21: 21394208 | B21: 5 | C21: VALERIA ALEJANDRA VERDUGO MONARDES | D21: VERDUGO | E21: MONARDES | F21: VALERIA ALEJANDRA | G21: Avance curricular suficiente o adecuado para evaluar ciclo básico | H21: Rendida | I21: 45749 | J21: No aplica | K21: 1 | L21: 1 | M21: 3 | N21: 2 | O21: 3 | P21: 2 | Q21: =SUM(K21:P21) -> 12 | R21: =Q21/24 -> 0.5 | S21: =IF(H21="Rendida ",IF('Resultados Individuales'!R21<49.5%,"Por Mejorar",IF('Resultados Individuales'!R21<64.5%,"Base",IF('Resultados Individuales'!R21<84.5%,"Satisfactorio","Óptimo"))),"No rendida o no válida") -> Base
A22: 21459816 | B22: 7 | C22: BENJAMÍN ANTONIO VALLE CASTILLO | D22: VALLE | E22: CASTILLO | F22: BENJAMÍN ANTONIO | G22: Avance curricular suficiente o adecuado para evaluar ciclo básico | H22: Rendida | I22: 45749 | J22: No aplica | K22: 3 | L22: 2 | M22: 4 | N22: 3 | O22: 3 | P22: 2 | Q22: =SUM(K22:P22) -> 17 | R22: =Q22/24 -> 0.70833333 | S22: =IF(H22="Rendida ",IF('Resultados Individuales'!R22<49.5%,"Por Mejorar",IF('Resultados Individuales'!R22<64.5%,"Base",IF('Resultados Individuales'!R22<84.5%,"Satisfactorio","Óptimo"))),"No rendida o no válida") -> Satisfactorio
A23: 21460161 | B23: 3 | C23: CAMILA CONSTANZA NAVARRO NÚÑEZ | D23: NAVARRO | E23: NÚÑEZ | F23: CAMILA CONSTANZA | G23: Avance curricular suficiente o adecuado para evaluar ciclo básico | H23: Rendida | I23: 45749 | J23: No aplica | K23: 3 | L23: 3 | M23: 4 | N23: 4 | O23: 3 | P23: 2 | Q23: =SUM(K23:P23) -> 19 | R23: =Q23/24 -> 0.79166667 | S23: =IF(H23="Rendida ",IF('Resultados Individuales'!R23<49.5%,"Por Mejorar",IF('Resultados Individuales'!R23<64.5%,"Base",IF('Resultados Individuales'!R23<84.5%,"Satisfactorio","Óptimo"))),"No rendida o no válida") -> Satisfactorio
A24: 21464640 | B24: 4 | C24: CARLA JAVIERA GONZÁLEZ VALENZUELA | D24: GONZÁLEZ | E24: VALENZUELA | F24: CARLA JAVIERA | G24: Avance curricular suficiente o adecuado para evaluar ciclo básico | H24: Rendida | I24: 45749 | J24: No aplica | K24: 4 | L24: 4 | M24: 4 | N24: 4 | O24: 2 | P24: 2 | Q24: =SUM(K24:P24) -> 20 | R24: =Q24/24 -> 0.83333333 | S24: =IF(H24="Rendida ",IF('Resultados Individuales'!R24<49.5%,"Por Mejorar",IF('Resultados Individuales'!R24<64.5%,"Base",IF('Resultados Individuales'!R24<84.5%,"Satisfactorio","Óptimo"))),"No rendida o no válida") -> Satisfactorio
A25: 21467583 | B25: 8 | C25: DANIELA MABEL FARÍAS NAVARRO | D25: FARÍAS | E25: NAVARRO | F25: DANIELA MABEL | G25: Avance curricular suficiente o adecuado para evaluar ciclo básico | H25: Rendida | I25: 45749 | J25: No aplica | K25: 2 | L25: 2 | M25: 2 | N25: 2 | O25: 3 | P25: 2 | Q25: =SUM(K25:P25) -> 13 | R25: =Q25/24 -> 0.54166667 | S25: =IF(H25="Rendida ",IF('Resultados Individuales'!R25<49.5%,"Por Mejorar",IF('Resultados Individuales'!R25<64.5%,"Base",IF('Resultados Individuales'!R25<84.5%,"Satisfactorio","Óptimo"))),"No rendida o no válida") -> Base
A26: 21473280 | B26: 7 | C26: JOSEFINA IGNACIA NUÑEZ VARELA | D26: NUÑEZ | E26: VARELA | F26: JOSEFINA IGNACIA | G26: Avance curricular suficiente o adecuado para evaluar ciclo básico | H26: Rendida | I26: 45749 | J26: No aplica | K26: 2 | L26: 4 | M26: 4 | N26: 3 | O26: 4 | P26: 3 | Q26: =SUM(K26:P26) -> 20 | R26: =Q26/24 -> 0.83333333 | S26: =IF(H26="Rendida ",IF('Resultados Individuales'!R26<49.5%,"Por Mejorar",IF('Resultados Individuales'!R26<64.5%,"Base",IF('Resultados Individuales'!R26<84.5%,"Satisfactorio","Óptimo"))),"No rendida o no válida") -> Satisfactorio
A27: 21510123 | B27: 1 | C27: FRANCISCA JESÚS ARAYA RIVERA | D27: ARAYA | E27: RIVERA | F27: FRANCISCA JESÚS | G27: Avance curricular suficiente o adecuado para evaluar ciclo básico | H27: Rendida | I27: 45761 | J27: No aplica | K27: 4 | L27: 3 | M27: 4 | N27: 3 | O27: 3 | P27: 4 | Q27: =SUM(K27:P27) -> 21 | R27: =Q27/24 -> 0.875 | S27: =IF(H27="Rendida ",IF('Resultados Individuales'!R27<49.5%,"Por Mejorar",IF('Resultados Individuales'!R27<64.5%,"Base",IF('Resultados Individuales'!R27<84.5%,"Satisfactorio","Óptimo"))),"No rendida o no válida") -> Óptimo
A28: 21513572 | B28: 1 | C28: CRISTINA ESPERANZA SARRO POLONI | D28: SARRO | E28: POLONI | F28: CRISTINA ESPERANZA | G28: Interrupción voluntaria (no rinde EPI 2025) | H28: No aplica | J28: No aplica | Q28: =SUM(K28:P28) -> 0 | R28: =Q28/24 -> 0 | S28: =IF(H28="Rendida ",IF('Resultados Individuales'!R28<49.5%,"Por Mejorar",IF('Resultados Individuales'!R28<64.5%,"Base",IF('Resultados Individuales'!R28<84.5%,"Satisfactorio","Óptimo"))),"No rendida o no válida") -> No rendida o no válida
A29: 21624240 | B29: 8 | C29: ANDRÉS FELIPE EDUARDO MARCHANT GORICHÓN | D29: MARCHANT | E29: GORICHÓN | F29: ANDRÉS FELIPE EDUARDO | G29: Avance curricular insuficiente para evaluar ciclo básico (no rinde EPI 2025) | H29: No aplica | J29: No aplica | Q29: =SUM(K29:P29) -> 0 | R29: =Q29/24 -> 0 | S29: =IF(H29="Rendida ",IF('Resultados Individuales'!R29<49.5%,"Por Mejorar",IF('Resultados Individuales'!R29<64.5%,"Base",IF('Resultados Individuales'!R29<84.5%,"Satisfactorio","Óptimo"))),"No rendida o no válida") -> No rendida o no válida
A30: 21636389 | B30: 2 | C30: EMILIA FRANCISCA MANRÍQUEZ URREA | D30: MANRÍQUEZ | E30: URREA | F30: EMILIA FRANCISCA | G30: Avance curricular insuficiente para evaluar ciclo básico (no rinde EPI 2025) | H30: No aplica | J30: No aplica | R30: =Q30/24 -> 0 | S30: =IF(H30="Rendida ",IF('Resultados Individuales'!R30<49.5%,"Por Mejorar",IF('Resultados Individuales'!R30<64.5%,"Base",IF('Resultados Individuales'!R30<84.5%,"Satisfactorio","Óptimo"))),"No rendida o no válida") -> No rendida o no válida
A31: 21636468 | B31: 6 | C31: DIEGO ALONSO GALAZ SOLAR | D31: GALAZ | E31: SOLAR | F31: DIEGO ALONSO | G31: Avance curricular insuficiente para evaluar ciclo básico (no rinde EPI 2025) | H31: No aplica | J31: No aplica | Q31: =SUM(K31:P31) -> 0 | R31: =Q31/24 -> 0 | S31: =IF(H31="Rendida ",IF('Resultados Individuales'!R31<49.5%,"Por Mejorar",IF('Resultados Individuales'!R31<64.5%,"Base",IF('Resultados Individuales'!R31<84.5%,"Satisfactorio","Óptimo"))),"No rendida o no válida") -> No rendida o no válida
A32: 21710759 | B32: 8 | C32: MARTINA IGNACIA MUÑOZ MARCHANT | D32: MUÑOZ | E32: MARCHANT | F32: MARTINA IGNACIA | G32: Avance curricular suficiente o adecuado para evaluar ciclo básico | H32: Rendida | I32: 45749 | J32: No aplica | K32: 4 | L32: 4 | M32: 4 | N32: 4 | O32: 3 | P32: 4 | Q32: =SUM(K32:P32) -> 23 | R32: =Q32/24 -> 0.95833333 | S32: =IF(H32="Rendida ",IF('Resultados Individuales'!R32<49.5%,"Por Mejorar",IF('Resultados Individuales'!R32<64.5%,"Base",IF('Resultados Individuales'!R32<84.5%,"Satisfactorio","Óptimo"))),"No rendida o no válida") -> Óptimo
A33: 21730722 | B33: 8 | C33: CONSTANZA MONSERRATT GAMBOA GAJARDO | D33: GAMBOA | E33: GAJARDO | F33: CONSTANZA MONSERRATT | G33: Avance curricular suficiente o adecuado para evaluar ciclo básico | H33: Rendida | I33: 45749 | J33: No aplica | K33: 2 | L33: 2 | M33: 3 | N33: 2 | O33: 2 | P33: 3 | Q33: =SUM(K33:P33) -> 14 | R33: =Q33/24 -> 0.58333333 | S33: =IF(H33="Rendida ",IF('Resultados Individuales'!R33<49.5%,"Por Mejorar",IF('Resultados Individuales'!R33<64.5%,"Base",IF('Resultados Individuales'!R33<84.5%,"Satisfactorio","Óptimo"))),"No rendida o no válida") -> Base
A34: 21797965 | B34: K | C34: ISIDORA ANTONIA LA RIVERA VARAS | D34: LA RIVERA | E34: VARAS | F34: ISIDORA ANTONIA | G34: Avance curricular suficiente o adecuado para evaluar ciclo básico | H34: Rendida | I34: 45749 | J34: No aplica | K34: 4 | L34: 3 | M34: 4 | N34: 4 | O34: 4 | P34: 3 | Q34: =SUM(K34:P34) -> 22 | R34: =Q34/24 -> 0.91666667 | S34: =IF(H34="Rendida ",IF('Resultados Individuales'!R34<49.5%,"Por Mejorar",IF('Resultados Individuales'!R34<64.5%,"Base",IF('Resultados Individuales'!R34<84.5%,"Satisfactorio","Óptimo"))),"No rendida o no válida") -> Óptimo
A35: 20818740 | B35: 6 | C35: ANTONIA SOFÍA SOBARZO TRONCOSO | D35: SOBARZO | E35: TRONCOSO | F35: ANTONIA SOFÍA | G35: Avance curricular suficiente o adecuado para evaluar ciclo básico | H35: Rendida | I35: 45749 | J35: No aplica | K35: 2 | L35: 2 | M35: 2 | N35: 3 | O35: 2 | P35: 2 | Q35: =SUM(K35:P35) -> 13 | R35: =Q35/24 -> 0.54166667 | S35: =IF(H35="Rendida ",IF('Resultados Individuales'!R35<49.5%,"Por Mejorar",IF('Resultados Individuales'!R35<64.5%,"Base",IF('Resultados Individuales'!R35<84.5%,"Satisfactorio","Óptimo"))),"No rendida o no válida") -> Base
Q36: =SUM(K36:P36) -> 0 | R36: =Q36/24 -> 0 | S36: =IF(H36="Rendida ",IF('Resultados Individuales'!R36<49.5%,"Por Mejorar",IF('Resultados Individuales'!R36<64.5%,"Base",IF('Resultados Individuales'!R36<84.5%,"Satisfactorio","Óptimo"))),"No rendida o no válida") -> No rendida o no válida
Q37: =SUM(K37:P37) -> 0 | R37: =Q37/24 -> 0 | S37: =IF(H37="Rendida ",IF('Resultados Individuales'!R37<49.5%,"Por Mejorar",IF('Resultados Individuales'!R37<64.5%,"Base",IF('Resultados Individuales'!R37<84.5%,"Satisfactorio","Óptimo"))),"No rendida o no válida") -> No rendida o no válida
Q38: =SUM(K38:P38) -> 0 | R38: =Q38/24 -> 0 | S38: =IF(H38="Rendida ",IF('Resultados Individuales'!R38<49.5%,"Por Mejorar",IF('Resultados Individuales'!R38<64.5%,"Base",IF('Resultados Individuales'!R38<84.5%,"Satisfactorio","Óptimo"))),"No rendida o no válida") -> No rendida o no válida
Q39: =SUM(K39:P39) -> 0 | R39: =Q39/24 -> 0 | S39: =IF(H39="Rendida ",IF('Resultados Individuales'!R39<49.5%,"Por Mejorar",IF('Resultados Individuales'!R39<64.5%,"Base",IF('Resultados Individuales'!R39<84.5%,"Satisfactorio","Óptimo"))),"No rendida o no válida") -> No rendida o no válida
Q40: =SUM(K40:P40) -> 0 | R40: =Q40/24 -> 0 | S40: =IF(H40="Rendida ",IF('Resultados Individuales'!R40<49.5%,"Por Mejorar",IF('Resultados Individuales'!R40<64.5%,"Base",IF('Resultados Individuales'!R40<84.5%,"Satisfactorio","Óptimo"))),"No rendida o no válida") -> No rendida o no válida
Q41: =SUM(K41:P41) -> 0 | R41: =Q41/24 -> 0 | S41: =IF(H41="Rendida ",IF('Resultados Individuales'!R41<49.5%,"Por Mejorar",IF('Resultados Individuales'!R41<64.5%,"Base",IF('Resultados Individuales'!R41<84.5%,"Satisfactorio","Óptimo"))),"No rendida o no válida") -> No rendida o no válida
...

Sheet Resultados Grupales
D1: Actividad problema 1 | J1: Resultados Generales Cohorte
A2: N Estudiantes habilitados para rendir | B2: N Estudiantes que rindieron | C2: Porcentaje de cobertura EPI | D2: Enfoques teórico-conceptuales de la antropología y su relación con una experiencia de trabajo etnográfico específico. | E2: Elementos fundamentales de la historia y el pensamiento latinoamericano para comprender un problema de investigación específico. | F2: Fundamentos y estrategias de las metodologías cualitativas y la etnografía para formular proyectos de investigación antropológica. | G2: Herramientas introductorias del trabajo etnográfico, incorporando el diseño, implementación y reporte escrito (análisis). | H2: Especificidades disciplinares de la antropología y su relación con otras disciplinas de las ciencias humanas. | I2: Aspectos formales asociados al ensayo | J2: PUNTAJE TOTAL ESTUDIANTE | K2: PORCENTAJE DE LOGRO EPI 2025 | L2: CATEGORÍA RESULTADO GLOBAL ESTUDIANTE
A3: 25 | B3: 25 | C3: 1 | D3: 3 | E3: 3 | F3: 3 | G3: 3 | H3: 3 | I3: 3 | J3: 18 | K3: 0.75 | L3: Satisfactorio

Sheet Validación datos NO BORRAR
E3: Estado de Habilitación para rendir | F3: ESTATUS DE RENDICIÓN | G3: JUSTIFICATIVO DE NO RENDICIÓN | H3: Puntaje según categoría
E4: Avance curricular suficiente o adecuado para evaluar ciclo básico | F4: Rendida | G4: Justifica | H4: 0
E5: Avance curricular insuficiente para evaluar ciclo básico (no rinde EPI 2025) | F5: No rendida | G5: No justifica | H5: 1
E6: EPI pendiente periodo anterior | F6: Rendida no válida | G6: No aplica | H6: 2
E7: Interrupción voluntaria (no rinde EPI 2025) | F7: No aplica | H7: 3
E8: Expulsión | H8: 4
E9: Retracto

Sheet Hoja1
A1: POR MEJORAR | C1: RINDE
A2: SUFICIENTE | C2: NO RINDE
A3: SATISFACTORIO
A4: ÓPTIMO

Sheet ACCIONES
B2: Facultad de Ciencias Sociales
B3: Antropología
B4: PLAN DE ESTUDIO 2011 (actualización 2015)
B6: Instrucciones: completar items en color azul. Se incorporan ejemplos que pueden se considerados por las unidades académicas para la elaboración de sus propuestas.
B8: ANÁLISIS Y TOMA DE DECISIONES BASADAS EN LA EVIDENCIA
B9: Se presentan, a continuación, las acciones planificadas considerando el análisis de los resultados de la aplicación EPI 2025. Estas acciones -consideradas para ser desarrolladas a corto, mediano y largo plazo- están orientadas a fortalecer el perfil intermedio intermedio del programa, teniendo a la vista las competencias con menores niveles de logro.
B10: N° | C10: TIPO DE ACCIÓN | D10: ACCIONES | L10: MEDIO DE VERIFICACIÓN
B11: I. | C11: CORTO PLAZO | D11: -Integrar en programaciones de actividades curriculares de 3er año, ajustes que favorezcan el desarrollo de las compentencias que evidenciaron un menor logro en EPI. | L11: Programaciones ajustadas
B12: II. | C12: MEDIANO PLAZO | D12: - Analizar comparativamente las calificaciones obtenidas en el ciclo básico con los resultados de EPI, para evaluar nudos críticos en la implementación del plan de estudio que puedan ser abordados con anticipación.L12 | L12: Acta de reuniones en que se analice comparativamente EPI (2026)
B13: III. | C13: LARGO PLAZO | D13: - Elaborar una actividad curricular de formación complementaria (OFC) orientada a fortalecer competencias más descendidas | L13: - propuesta de programa OFC (2026)
